Workbook
Name ____PR12: #REF!
Name ___PR12: #REF!
Name __PR12: #REF!
Name _005029252007Act: #REF!
Name _084029252007Act: #REF!
Name _97RBC: #REF!
Name _box1: #REF!
Name _box2: #REF!
Name _fas144: '[9]GP & FX Rate'!$A$46:$I$57
Name _PR12: #REF!
Name \a: #REF!
Name \b: #N/A
Name \d: #N/A
Name \q: #REF!
Name \x: #N/A
Name \z: #REF!
Name ABS: [10]ABS!$M$14:$W$40
Name Account: #REF!
Name ACCOUNT_LIST: [11]ACCOUNTS!$A$4:$A$47
Name ACDATA: #REF!
Name actdata: '[12]Actual Data'!$B$3:$AB$122
Name ACTSUB: [13]MONTH!$B$4
Name Actual2006: '[14]TOTAL ENTITY'!#REF!
Name Actual2007: '[14]TOTAL ENTITY'!#REF!
Name Actuality_IS_1: '[15]Cover & Parameters'!$D$15
Name Actuality_IS_2: '[15]Cover & Parameters'!$E$15
Name addedInfo: [16]Notes!$C$4
Name AGENT: [17]Definition!$F$21
Name APROFDATA: #REF!
Name AREPORT: #REF!
Name asdasff: [18]!TORIHIKI_GET_B
Name asdasff: [18]!TORIHIKI_GET_B
Name asdasff: [18]!TORIHIKI_GET_B
Name BFLAUnit: #REF!
Name BFNTUnit: #REF!
Name BFRCUnit: #REF!
Name brand: OFFSET([20]list!$W$8,0,0,COUNTA([20]list!$W:$W)-4,1)
Name Bridegstone_Americas_Holding__Inc.: #REF!
Name BSALE_A: #REF!,#REF!,#REF!,#REF!,#REF!
Name BSALE_B: #REF!,#REF!,#REF!,#REF!,#REF!
Name BSAUnitNames: '[21]BSA Units & Pgbds'!$B$6:$B$13
Name BSBDUnit: #REF!
Name BSCOL: #REF!,#REF!,#REF!,#REF!,#REF!,#REF!,#REF!,#REF!,#REF!,#REF!,#REF!,#REF!
Name BSDATA: #REF!
Name BSDOT1: #REF!,#REF!,#REF!,#REF!,#REF!,#REF!,#REF!,#REF!,#REF!,#REF!,#REF!,#REF!,#REF!,#REF!,#REF!,#REF!
Name BSDOT2: #REF!,#REF!,#REF!,#REF!,#REF!,#REF!,#REF!
Name buddata: '[22]Budget Data'!$B$3:$V$101
Name budget: [23]Basic!$C$12
Name Budget_Category: [24]Guideline!$B$9
Name BUDSUB: [13]MONTH!$B$5
Name buildUp: #REF!
Name CAL_ADATA: [17]CAL_A!$C$5:$S$84
Name CAL_BDATA: #REF!
Name CDNO: #REF!
Name Channel: [25]REF!$H$3:$I$5
Name CHK_ERR: #REF!
Name CHK_WAR: #REF!
Name clientes: [26]Clientes!$A$4:$D$103
Name ClosingVersion_1: '[15]Cover & Parameters'!$D$17
Name ClosingVersion_2: '[15]Cover & Parameters'!$E$17

Sheet Main
AH1: 1H Plan | AI1: RF | AJ1: RF(8+4) | AQ1: JUN FCST | AS1: JUN ACT | AU1: JUN ACT+Remain
AI2: 174916 | AJ2: 182480 | AQ2: JUN OB | AR2: 41311 | AS2: OB | AT2: 41311 | AU2: OB | AV2: 41311 | BD2: Total
AH3: 1H(ACT+FCST) | AI3: =AM8 -> 174375 | AJ3: =AM8 -> 174375 | AQ3: JUN RF(8+4) | AR3: 42119 | AS3: RF(8+4) | AT3: 42119 | AU3: RF(8+4) | AV3: 42119 | BD3: 도매 | BE3: =BD8/AA8 -> 0.50341276
AH4: Differ | AI4: =AI3-AI2 -> -541 | AJ4: =AJ3-AJ2 -> -8105 | AQ4: JUN FCST | AR4: =AI7 -> 37507.78 | AS4: ACT | AT4: =AJ8 -> 33394 | AU4: ACT+Remain | AV4: =AJ8+AK8 -> 40516.78 | BD4: 소매 | BE4: =BE8/AA8 -> 0.49404441
E5: 2020 | H5: 2021 | K5: 2022 | N5: 2023 | Q5: 2024 | T5: 2025 | W5: 최근 5년 DATA | AL5: *최대한 자세히 입력 | AQ5: Ratio(vs RF(8+4)) | AR5: =AR4/AR3 -> 0.89051924 | AS5: Ratio(vs RF(8+4)) | AT5: =AT4/AT3 -> 0.79284883 | AU5: Ratio(vs RF(8+4)) | AV5: =AV4/AV3 -> 0.96195969
B6: PIC | C6: 대리점 | D6: Portion | E6: 1H | F6: 2H | G6: Total | H6: 1H | I6: 2H | J6: Total | K6: 1H | L6: 2H | M6: Total | N6: 1H | O6: 2H | P6: Total | Q6: 1H | R6: 2H | S6: Total | T6: 1H | U6: 2H | V6: Total | W6: Y21 | X6: Y22 | Y6: Y23 | Z6: Y24 | AA6: Y25 | AB6: % (Y25기준) | AC6: Jan Act | AD6: Feb Act | AE6: Mar Act | AF6: Apr Act | AG6: May Act | AH6: JUN Portion(RF) | AI6: Jun FCST | AJ6: Jun Act(26) | AK6: Jun Remain | AL6: 비 고 (딜러별 특이사항, 경쟁사 마켓상황) | AM6: 1H Total (ACT) | AN6: 1H Differ(vs Portion) | AO6: Rebate Target(1H) | AQ6: ="+/-" -> +/- | AR6: =AR4-AR3 -> -4611.22 | AS6: ="+/-" -> +/- | AT6: =AT4-AT3 -> -8725 | AU6: ="+/-" -> +/- | AV6: =AV4-AV3 -> -1602.22 | BB6: 비중(%) | BD6: Qty
C7: Total(PIC+B2C+경영기획 포함) | E7: =E8+E372 -> 118802 | F7: =F8+F372 -> 299094 | G7: =E7+F7 -> 417896 | H7: =H8+H372 -> 168939 | I7: =I8+I372 -> 229810 | J7: =H7+I7 -> 398749 | K7: =K8+K372 -> 146824 | L7: =L8+L372 -> 190816 | M7: =K7+L7 -> 337640 | N7: =N8+N372 -> 129512 | O7: =O8+O372 -> 207898 | P7: =N7+O7 -> 337410 | Q7: =Q8+Q372 -> 140443 | R7: =R8+R372 -> 221794 | S7: =Q7+R7 -> 362237 | T7: =T8+T372 -> 151392 | U7: =U8+U372 -> 286144 | V7: =T7+U7 -> 437536 | X7: =X8+X372 -> 337640 | Y7: =Y8+Y372 -> 337410 | Z7: =Z8+Z372 -> 362237 | AA7: =AA8+AA372 -> 437498 | AC7: =AC8+AC372 -> 18261 | AD7: =AD8+AD372 -> 25372 | AE7: =AE8+AE372 -> 30678 | AF7: =AF8+AF372 -> 31741 | AG7: =AG8+AG372 -> 35505 | AH7: =AH8+AH372 -> 42119 | AI7: =AI8+AI372 -> 37507.78 | AJ7: =AJ8+AJ372 -> 33446 | AK7: =AK8+AK372 -> 7122.78 | AM7: =AM8+AM372 -> 175003 | AN7: =AN8+AN372 -> -8140 | AO7: Qty | AP7: Amt | AW7: MTO-W | BB7: 도매 | BC7: 소매 | BD7: 도매 | BE7: 소매
C8: PCR Total(PIC + B2C) 경영기획 제외 | D8: =SUM(D9:D371) -> 1 | E8: =E9+E15+E43+E73+E84+E116+E142+E178+E216+E240+E253+E254 -> 118167 | F8: =F9+F15+F43+F73+F84+F116+F142+F178+F216+F240+F253+F254 -> 298427 | G8: =E8+F8 -> 416594 | H8: =H9+H15+H43+H73+H84+H116+H142+H178+H216+H240+H253+H254 -> 168417 | I8: =I9+I15+I43+I73+I84+I116+I142+I178+I216+I240+I253+I254 -> 229218 | J8: =H8+I8 -> 397635 | K8: =K9+K15+K43+K73+K84+K116+K142+K178+K216+K240+K253+K254 -> 146145 | L8: =L9+L15+L43+L73+L84+L116+L142+L178+L216+L240+L253+L254 -> 190167 | M8: =K8+L8 -> 336312 | N8: =N9+N15+N43+N73+N84+N116+N142+N178+N216+N240+N253+N254 -> 129043 | O8: =O9+O15+O43+O73+O84+O116+O142+O178+O216+O240+O253+O254 -> 207026 | P8: =N8+O8 -> 336069 | Q8: =Q9+Q15+Q43+Q73+Q84+Q116+Q142+Q178+Q216+Q240+Q253+Q254 -> 139715 | R8: =R9+R15+R43+R73+R84+R116+R142+R178+R216+R240+R253+R254 -> 221068 | S8: =Q8+R8 -> 360783 | T8: =T9+T15+T43+T73+T84+T116+T142+T178+T216+T240+T253+T254 -> 150810 | U8: =U9+U15+U43+U73+U84+U116+U142+U178+U216+U240+U253+U254 -> 285356 | V8: =T8+U8 -> 436166 | W8: =W9+W15+W43+W73+W84+W116+W142+W178+W216+W240+W253+W254 -> 397635 | X8: =X9+X15+X43+X73+X84+X116+X142+X178+X216+X240+X253+X254 -> 336312 | Y8: =Y9+Y15+Y43+Y73+Y84+Y116+Y142+Y178+Y216+Y240+Y253+Y254 -> 336069 | Z8: =Z9+Z15+Z43+Z73+Z84+Z116+Z142+Z178+Z216+Z240+Z253+Z254 -> 360783 | AA8: =AA9+AA15+AA43+AA73+AA84+AA116+AA142+AA178+AA216+AA240+AA253+AA254 -> 436128 | AB8: =AB9+AB15+AB43+AB73+AB84+AB116+AB142+AB178+AB216+AB240+AB253+AB254 -> 1 | AC8: =AC9+AC15+AC43+AC73+AC84+AC116+AC142+AC178+AC216+AC240+AC253+AC254 -> 18164 | AD8: =AD9+AD15+AD43+AD73+AD84+AD116+AD142+AD178+AD216+AD240+AD253+AD254 -> 25292 | ... AK8: =AK9+AK15+AK43+AK73+AK84+AK116+AK142+AK178+AK216+AK240+AK253+AK254 -> 7122.78 | AM8: =AM9+AM15+AM43+AM73+AM84+AM116+AM142+AM178+AM216+AM240+AM253+AM254 -> 174375 | AN8: =AN9+AN15+AN43+AN73+AN84+AN116+AN142+AN178+AN216+AN240+AN253+AN254 -> -8140 | AO8: =AO9+AO15+AO43+AO73+AO84+AO116+AO142+AO178+AO216+AO240+AO253+AO254 -> 115527.31 | AP8: =AP9+AP15+AP43+AP73+AP84+AP116+AP142+AP178+AP216+AP240+AP253+AP254 -> #REF! | AQ8: #6월 세일즈 계획 | BB8: =BB9+BB15+BB43+BB73+BB84+BB116+BB142+BB178+BB216+BB240+BB253+BB254 -> 0 | BC8: =BC9+BC15+BC43+BC73+BC84+BC116+BC142+BC178+BC216+BC240+BC253+BC254 -> 0 | BD8: =BD9+BD15+BD43+BD73+BD84+BD116+BD142+BD178+BD216+BD240+BD253+BD254 -> 219552.4 | BE8: =BE9+BE15+BE43+BE73+BE84+BE116+BE142+BE178+BE216+BE240+BE253+BE254 -> 215466.6
C9: B2C | D9: 0.0064752056 | G9: =E9+F9 -> 0 | J9: =H9+I9 -> 0 | M9: =K9+L9 -> 0 | P9: =N9+O9 -> 0 | Q9: 0 | R9: 0 | S9: =Q9+R9 -> 0 | T9: 298 | U9: 803 | V9: =T9+U9 -> 1101 | W9: =J9 -> 0 | X9: =M9 -> 0 | Y9: =P9 -> 0 | Z9: =S9 -> 0 | AA9: =V9 -> 1101 | AB9: =IFERROR(AA9/$AA$8,0) -> 0.0025244882 | AC9: 65 | AD9: 86 | AE9: 83 | AF9: 189 | AG9: 213 | AH9: =D9*$AR$3 -> 272.72918 | AJ9: =SUMIF('6월 매출현황(6.26)'!$E:$E,"송강호",'6월 매출현황(6.26)'!$N:$N) -> 82 | AM9: =AC9+AD9+AE9+AF9+AG9+AJ9 -> 718 | AN9: =AM9-(D9*$AJ$2) -> -463.59551 | AQ9: PTTN | AR9: 내 용
B10: 김주성 | C10: 주식회사 남서울상사(구_콘티넨탈남서울) | E10: 4936 | F10: 22594 | G10: =E10+F10 -> 27530 | H10: 5526 | I10: 8406 | J10: =H10+I10 -> 13932 | K10: 8511 | L10: 11802 | M10: =K10+L10 -> 20313 | N10: 12939 | O10: 16615 | P10: =N10+O10 -> 29554 | Q10: 12984 | R10: 23678 | S10: =Q10+R10 -> 36662 | T10: 13709 | U10: 23402 | V10: =T10+U10 -> 37111 | W10: =J10 -> 13932 | X10: =M10 -> 20313 | Y10: =P10 -> 29554 | Z10: =S10 -> 36662 | AA10: =V10 -> 37111 | AB10: =IFERROR(AA10/$AA$8,0) -> 0.085091991 | AC10: 773 | AD10: 2436 | AE10: 2368 | AF10: 3360 | AG10: 2621 | AI10: 2562 | AJ10: =SUMIF('6월 매출현황(6.26)'!$B:$B,Main!C10,'6월 매출현황(6.26)'!$N:$N) -> 2346 | AK10: =AI10-AJ10 -> 216 | AM10: =AC10+AD10+AE10+AF10+AG10+AJ10 -> 13904 | AO10: 14120.27 | AP10: 1.5948219e+09 | AQ10: OE | AR10: Early(~12일까지) 255/40R/20 MO 20% | AW10: 얼리 | BB10: 0.8 | BC10: 0.2 | BD10: =AA10*BB10 -> 29688.8 | BE10: =AA10*BC10 -> 7422.2
B11: 김주성 | C11: 주식회사롤(ROLL CO.,Ltd)_태백 | E11: 0 | F11: 29262 | G11: =E11+F11 -> 29262 | H11: 17171 | I11: 29576 | J11: =H11+I11 -> 46747 | K11: 12528 | L11: 17083 | M11: =K11+L11 -> 29611 | N11: 19524 | O11: 20656 | P11: =N11+O11 -> 40180 | Q11: 14572 | R11: 22893 | S11: =Q11+R11 -> 37465 | T11: 9716 | U11: 30659 | V11: =T11+U11 -> 40375 | W11: =J11 -> 46747 | X11: =M11 -> 29611 | Y11: =P11 -> 40180 | Z11: =S11 -> 37465 | AA11: =V11 -> 40375 | AB11: =IFERROR(AA11/$AA$8,0) -> 0.092576033 | AC11: 1880 | AD11: 3463 | AE11: 2204 | AF11: 3162 | AG11: 4896 | AI11: 6734 | AJ11: =SUMIF('6월 매출현황(6.26)'!$B:$B,Main!C11,'6월 매출현황(6.26)'!$N:$N) -> 5238 | AK11: 380 | AL11: 창고 문제로 인한 재고 Full | AM11: =AC11+AD11+AE11+AF11+AG11+AJ11 -> 20843 | AO11: 23965.731 | AP11: 2.2527837e+09 | AQ11: RE004 | AR11: 55% 기안 | AW11: 기안필요 | BB11: 0.9 | BC11: 0.1 | BD11: =AA11*BB11 -> 36337.5 | BE11: =AA11*BC11 -> 4037.5
B12: 김주성 | C12: 오토 엠(AUTO M)_태백 | E12: 3098 | F12: 12197 | G12: =E12+F12 -> 15295 | H12: 2579 | I12: 11290 | J12: =H12+I12 -> 13869 | K12: 7925 | L12: 15524 | M12: =K12+L12 -> 23449 | N12: 5763 | O12: 13319 | P12: =N12+O12 -> 19082 | Q12: 7858 | R12: 10054 | S12: =Q12+R12 -> 17912 | T12: 9593 | U12: 8832 | V12: =T12+U12 -> 18425 | W12: =J12 -> 13869 | X12: =M12 -> 23449 | Y12: =P12 -> 19082 | Z12: =S12 -> 17912 | AA12: =V12 -> 18425 | AB12: =IFERROR(AA12/$AA$8,0) -> 0.042246772 | AC12: 97 | AD12: 442 | AE12: 915 | AF12: 0 | AG12: 850 | AJ12: =SUMIF('6월 매출현황(6.26)'!$B:$B,Main!C12,'6월 매출현황(6.26)'!$N:$N) -> 1114 | AM12: =AC12+AD12+AE12+AF12+AG12+AJ12 -> 3418 | AO12: 0 | AP12: 0 | AQ12: PS-AS, T-EV | AR12: 45% 기안(3~5딜러 선정) 그 외 소매 30% | AW12: 기안필요 | BB12: 0.9 | BC12: 0.1 | BD12: =AA12*BB12 -> 16582.5 | BE12: =AA12*BC12 -> 1842.5
B13: 김주성 | C13: (주)타이어커넥션(태백) | E13: 11906 | F13: 39722 | G13: =E13+F13 -> 51628 | H13: 4469 | I13: 5106 | J13: =H13+I13 -> 9575 | K13: 1139 | L13: 3488 | M13: =K13+L13 -> 4627 | N13: 1521 | O13: 1748 | P13: =N13+O13 -> 3269 | Q13: 160 | R13: 1712 | S13: =Q13+R13 -> 1872 | T13: 112 | U13: 1810 | V13: =T13+U13 -> 1922 | W13: =J13 -> 9575 | X13: =M13 -> 4627 | Y13: =P13 -> 3269 | Z13: =S13 -> 1872 | AA13: =V13 -> 1922 | AB13: =IFERROR(AA13/$AA$8,0) -> 0.0044069631 | AC13: 25 | AD13: 4 | AE13: 14 | AF13: 16 | AG13: 13 | AJ13: =SUMIF('6월 매출현황(6.26)'!$B:$B,Main!C13,'6월 매출현황(6.26)'!$N:$N) -> 2 | AM13: =AC13+AD13+AE13+AF13+AG13+AJ13 -> 74 | AO13: 0 | AP13: 0 | AQ13: H/L422+ | AR13: 255/45/20 17%~20%(팀장님보고) 255/50/20 27% | BB13: 0.9 | BC13: 0.1 | BD13: =AA13*BB13 -> 1729.8 | BE13: =AA13*BC13 -> 192.2
E14: 0 | F14: 0 | G14: =E14+F14 -> 0 | H14: 0 | I14: 0 | J14: =H14+I14 -> 0 | K14: 0 | L14: 0 | M14: =K14+L14 -> 0 | N14: 0 | O14: 0 | P14: =N14+O14 -> 0 | Q14: 0 | R14: 0 | S14: =Q14+R14 -> 0 | T14: 0 | U14: 0 | V14: =T14+U14 -> 0 | W14: =J14 -> 0 | X14: =M14 -> 0 | Y14: =P14 -> 0 | Z14: =S14 -> 0 | AA14: =V14 -> 0 | AB14: =IFERROR(AA14/$AA$8,0) -> 0 | AC14: 0 | AD14: 0 | AE14: 0 | AF14: 0 | AG14: 0 | AJ14: =SUMIF('6월 매출현황(6.26)'!$B:$B,Main!C14,'6월 매출현황(6.26)'!$N:$N) -> 0 | AM14: =AC14+AD14+AE14+AF14+AG14+AJ14 -> 0 | AO14: 0 | AP14: 0 | AQ14: LVR | AR14: 상시 - 소매 20본 26%, 도매 100본 28% | BD14: =AA14*BB14 -> 0 | BE14: =AA14*BC14 -> 0 | BG14: 6734
B15: 김주성 | C15: 김주성 Total | D15: 0.22069991 | E15: =SUM(E10:E14) -> 19940 | F15: =SUM(F10:F14) -> 103775 | G15: =E15+F15 -> 123715 | H15: =SUM(H10:H14) -> 29745 | I15: =SUM(I10:I14) -> 54378 | J15: =H15+I15 -> 84123 | K15: =SUM(K10:K14) -> 30103 | L15: =SUM(L10:L14) -> 47897 | M15: =K15+L15 -> 78000 | N15: =SUM(N10:N14) -> 39747 | O15: =SUM(O10:O14) -> 52338 | P15: =N15+O15 -> 92085 | Q15: =SUM(Q10:Q14) -> 35574 | R15: =SUM(R10:R14) -> 58337 | S15: =Q15+R15 -> 93911 | T15: =SUM(T10:T14) -> 33130 | U15: =SUM(U10:U14) -> 64703 | V15: =SUM(V10:V14) -> 97833 | W15: =SUM(W10:W14) -> 84123 | X15: =SUM(X10:X14) -> 78000 | Y15: =SUM(Y10:Y14) -> 92085 | Z15: =SUM(Z10:Z14) -> 93911 | AA15: =SUM(AA10:AA14) -> 97833 | AB15: =IFERROR(AA15/$AA$8,0) -> 0.22432176 | AC15: =SUM(AC10:AC14) -> 2775 | AD15: =SUM(AD10:AD14) -> 6345 | AE15: =SUM(AE10:AE14) -> 5501 | AF15: =SUM(AF10:AF14) -> 6538 | AG15: =SUM(AG10:AG14) -> 8380 | AH15: =$D15*$AR$3 -> 9295.6593 | AI15: =SUM(AI10:AI14) -> 9296 | AJ15: =SUM(AJ10:AJ14) -> 8700 | AK15: =SUM(AK10:AK14) -> 596 | AM15: =SUM(AM10:AM14) -> 38239 | AN15: =AM15-(D15*$AJ$2) -> -2034.3187 | AO15: =SUM(AO10:AO14) -> 38086.001 | AP15: =SUM(AP10:AP14) -> 3.8476056e+09 | AQ15: DHPS-AS | AR15: 전 사이즈 27% 기안 | AW15: 기안필요 | BD15: =SUM(BD10:BD14) -> 84338.6 | BE15: =SUM(BE10:BE14) -> 13494.4 | BG15: 6354
B16: 이승희 | C16: 주식회사 한울상사 | E16: 0 | F16: 0 | G16: =E16+F16 -> 0 | H16: 2389 | I16: 30541 | J16: =H16+I16 -> 32930 | K16: 18430 | L16: 12489 | M16: =K16+L16 -> 30919 | N16: 8555 | O16: 12171 | P16: =N16+O16 -> 20726 | Q16: 3627 | R16: 6265 | S16: =Q16+R16 -> 9892 | T16: 4771 | U16: 6652 | V16: =T16+U16 -> 11423 | W16: =J16 -> 32930 | X16: =M16 -> 30919 | Y16: =P16 -> 20726 | Z16: =S16 -> 9892 | AA16: =V16 -> 11423 | AB16: =IFERROR(AA16/$AA$8,0) -> 0.026191852 | AC16: 563 | AD16: 230 | AE16: 414 | AF16: 633 | AG16: 1309 | AI16: 1647.78 | AJ16: =SUMIF('6월 매출현황(6.26)'!$B:$B,Main!C16,'6월 매출현황(6.26)'!$N:$N) -> 863 | AK16: =AO16-AM16 -> 784.78004 | AL16: 26년 윈터 재고 입고시 매출 필요. 약 900본- 1천본 예상 | AM16: =AC16+AD16+AE16+AF16+AG16+AJ16 -> 4012 | AO16: 4796.78 | AP16: 3.6172427e+08 | AQ16: Winter | AR16: 25년 윈터 45% 기안 (한울) | AW16: 기안필요 | BB16: 0.8 | BC16: 0.2 | BD16: =AA16*BB16 -> 9138.4 | BE16: =AA16*BC16 -> 2284.6 | BG16: =BG14-BG15 -> 380
B17: 이승희 | C17: 신화타이어판매주식회사 | E17: 11250 | F17: 14849 | G17: =E17+F17 -> 26099 | H17: 12849 | I17: 11234 | J17: =H17+I17 -> 24083 | K17: 2076 | L17: 9251 | M17: =K17+L17 -> 11327 | N17: 3850 | O17: 12742 | P17: =N17+O17 -> 16592 | Q17: 3605 | R17: 7774 | S17: =Q17+R17 -> 11379 | T17: 4729 | U17: 10457 | V17: =T17+U17 -> 15186 | W17: =J17 -> 24083 | X17: =M17 -> 11327 | Y17: =P17 -> 16592 | Z17: =S17 -> 11379 | AA17: =V17 -> 15186 | AB17: =IFERROR(AA17/$AA$8,0) -> 0.034820053 | AC17: 499 | AD17: 436 | AE17: 1012 | AF17: 1109 | AG17: 807 | AI17: 1100 | AJ17: =SUMIF('6월 매출현황(6.26)'!$B:$B,Main!C17,'6월 매출현황(6.26)'!$N:$N) -> 1311 | AK17: 200 | AM17: =AC17+AD17+AE17+AF17+AG17+AJ17 -> 5174 | AO17: 4952.8374 | AP17: 5.108311e+08 | AQ17: D400 | AR17: Early(~12일까지) - MAX 27% (소매: 20, 도매 50) | AW17: 얼리 | BB17: 0.3 | BC17: 0.7 | BD17: =AA17*BB17 -> 4555.8 | BE17: =AA17*BC17 -> 10630.2
B18: 이승희 | C18: 타이어랜드 주식회사 (신화) | E18: 0 | F18: 0 | G18: =E18+F18 -> 0 | H18: 0 | I18: 0 | J18: =H18+I18 -> 0 | K18: 1212 | L18: 1656 | M18: =K18+L18 -> 2868 | N18: 169 | O18: 0 | P18: =N18+O18 -> 169 | Q18: 0 | R18: 0 | S18: =Q18+R18 -> 0 | T18: 0 | U18: 0 | V18: =T18+U18 -> 0 | W18: =J18 -> 0 | X18: =M18 -> 2868 | Y18: =P18 -> 169 | Z18: =S18 -> 0 | AA18: =V18 -> 0 | AB18: =IFERROR(AA18/$AA$8,0) -> 0 | AC18: 0 | AD18: 0 | AE18: 0 | AF18: 0 | AG18: 0 | AJ18: =SUMIF('6월 매출현황(6.26)'!$B:$B,Main!C18,'6월 매출현황(6.26)'!$N:$N) -> 0 | AL18: 6월 한국타이어 LVR 숏티지 예상됨. -> 6월 LVR 매출 위주로 타겟 달성 예정. | AM18: =AC18+AD18+AE18+AF18+AG18+AJ18 -> 0 | AO18: 0 | AP18: 0 | AQ18: Ep300 | AR18: Early(~12일까지) - MAX 27% 245/45/18 (소매: 20, 도매 50) | AW18: 얼리 | BD18: =AA18*BB18 -> 0 | BE18: =AA18*BC18 -> 0
B19: 이승희 | C19: 제이앤씨상사 주식회사 (J&C) | E19: 0 | F19: 0 | G19: =E19+F19 -> 0 | H19: 0 | I19: 4330 | J19: =H19+I19 -> 4330 | K19: 2042 | L19: 4738 | M19: =K19+L19 -> 6780 | N19: 2424 | O19: 4288 | P19: =N19+O19 -> 6712 | Q19: 2689 | R19: 4589 | S19: =Q19+R19 -> 7278 | T19: 2088 | U19: 4920 | V19: =T19+U19 -> 7008 | W19: =J19 -> 4330 | X19: =M19 -> 6780 | Y19: =P19 -> 6712 | Z19: =S19 -> 7278 | AA19: =V19 -> 7008 | AB19: =IFERROR(AA19/$AA$8,0) -> 0.016068677 | AC19: 0 | AD19: 0 | AE19: 0 | AF19: 0 | AG19: 853 | AJ19: =SUMIF('6월 매출현황(6.26)'!$B:$B,Main!C19,'6월 매출현황(6.26)'!$N:$N) -> 0 | AM19: =AC19+AD19+AE19+AF19+AG19+AJ19 -> 853 | AO19: 2296.8 | AP19: 2.4251843e+08 | AQ19: Key man | AR19: DHPS, PSAS, TEV 본당 1만, SERENITY&RE005 본당 5천원 | BB19: 0.9 | BC19: 0.1 | BD19: =AA19*BB19 -> 6307.2 | BE19: =AA19*BC19 -> 700.8
B20: 이승희 | C20: 주식회사타이어사랑-송도지점 | E20: 0 | F20: 0 | G20: =E20+F20 -> 0 | H20: 0 | I20: 0 | J20: =H20+I20 -> 0 | K20: 0 | L20: 0 | M20: =K20+L20 -> 0 | N20: 0 | O20: 0 | P20: =N20+O20 -> 0 | Q20: 0 | R20: 456 | S20: =Q20+R20 -> 456 | T20: 558 | U20: 647 | V20: =T20+U20 -> 1205 | W20: =J20 -> 0 | X20: =M20 -> 0 | Y20: =P20 -> 0 | Z20: =S20 -> 456 | AA20: =V20 -> 1205 | AB20: =IFERROR(AA20/$AA$8,0) -> 0.0027629503 | AC20: 203 | AD20: 34 | AE20: 31 | AF20: 120 | AG20: 154 | AI20: 150 | AJ20: =SUMIF('6월 매출현황(6.26)'!$B:$B,Main!C20,'6월 매출현황(6.26)'!$N:$N) -> 92 | AK20: 30 | AM20: =AC20+AD20+AE20+AF20+AG20+AJ20 -> 634 | AO20: 0 | AP20: 0 | AQ20: 세레니티 | AR20: 24년 DOT 기안(50~60%) | AW20: 기안필요 | BC20: 1 | BD20: =AA20*BB20 -> 0 | BE20: =AA20*BC20 -> 1205
B21: 이승희 | C21: 오토상사 | E21: 237 | F21: 813 | G21: =E21+F21 -> 1050 | H21: 215 | I21: 291 | J21: =H21+I21 -> 506 | K21: 241 | L21: 268 | M21: =K21+L21 -> 509 | N21: 195 | O21: 437 | P21: =N21+O21 -> 632 | Q21: 420 | R21: 263 | S21: =Q21+R21 -> 683 | T21: 212 | U21: 299 | V21: =T21+U21 -> 511 | W21: =J21 -> 506 | X21: =M21 -> 509 | Y21: =P21 -> 632 | Z21: =S21 -> 683 | AA21: =V21 -> 511 | AB21: =IFERROR(AA21/$AA$8,0) -> 0.0011716744 | AC21: 1 | AD21: 10 | AE21: 11 | AF21: 4 | AG21: 4 | AJ21: =SUMIF('6월 매출현황(6.26)'!$B:$B,Main!C21,'6월 매출현황(6.26)'!$N:$N) -> 0 | AM21: =AC21+AD21+AE21+AF21+AG21+AJ21 -> 30 | AO21: 0 | AP21: 0 | BC21: 1 | BD21: =AA21*BB21 -> 0 | BE21: =AA21*BC21 -> 511
B22: 이승희 | C22: 거상대리점 | E22: 300 | F22: 253 | G22: =E22+F22 -> 553 | H22: 241 | I22: 454 | J22: =H22+I22 -> 695 | K22: 359 | L22: 466 | M22: =K22+L22 -> 825 | N22: 343 | O22: 379 | P22: =N22+O22 -> 722 | Q22: 358 | R22: 428 | S22: =Q22+R22 -> 786 | T22: 278 | U22: 360 | V22: =T22+U22 -> 638 | W22: =J22 -> 695 | X22: =M22 -> 825 | Y22: =P22 -> 722 | Z22: =S22 -> 786 | AA22: =V22 -> 638 | AB22: =IFERROR(AA22/$AA$8,0) -> 0.0014628733 | AC22: 34 | AD22: 77 | AE22: 73 | AF22: 74 | AG22: 0 | AJ22: =SUMIF('6월 매출현황(6.26)'!$B:$B,Main!C22,'6월 매출현황(6.26)'!$N:$N) -> 39 | AM22: =AC22+AD22+AE22+AF22+AG22+AJ22 -> 297 | AO22: 0 | AP22: 0 | BC22: 1 | BD22: =AA22*BB22 -> 0 | BE22: =AA22*BC22 -> 638
B23: 이승희 | C23: 남양점현대자동차(구_자동차마을) | E23: 213 | F23: 304 | G23: =E23+F23 -> 517 | H23: 205 | I23: 419 | J23: =H23+I23 -> 624 | K23: 105 | L23: 238 | M23: =K23+L23 -> 343 | N23: 197 | O23: 240 | P23: =N23+O23 -> 437 | Q23: 52 | R23: 160 | S23: =Q23+R23 -> 212 | T23: 6 | U23: 16 | V23: =T23+U23 -> 22 | W23: =J23 -> 624 | X23: =M23 -> 343 | Y23: =P23 -> 437 | Z23: =S23 -> 212 | AA23: =V23 -> 22 | AB23: =IFERROR(AA23/$AA$8,0) -> 5.0443906e-05 | AC23: 0 | AD23: 0 | AE23: 0 | AF23: 2 | AG23: 0 | AJ23: =SUMIF('6월 매출현황(6.26)'!$B:$B,Main!C23,'6월 매출현황(6.26)'!$N:$N) -> 0 | AM23: =AC23+AD23+AE23+AF23+AG23+AJ23 -> 2 | AO23: 0 | AP23: 0 | AQ23: *경쟁사 마켓현황 | BC23: 1 | BD23: =AA23*BB23 -> 0 | BE23: =AA23*BC23 -> 22
B24: 이승희 | C24: 준타이어 | E24: 0 | F24: 0 | G24: =E24+F24 -> 0 | H24: 0 | I24: 0 | J24: =H24+I24 -> 0 | K24: 0 | L24: 0 | M24: =K24+L24 -> 0 | N24: 0 | O24: 0 | P24: =N24+O24 -> 0 | Q24: 0 | R24: 0 | S24: =Q24+R24 -> 0 | T24: 39 | U24: 0 | V24: =T24+U24 -> 39 | W24: =J24 -> 0 | X24: =M24 -> 0 | Y24: =P24 -> 0 | Z24: =S24 -> 0 | AA24: =V24 -> 39 | AB24: =IFERROR(AA24/$AA$8,0) -> 8.9423289e-05 | AC24: 0 | AD24: 0 | AE24: 0 | AF24: 0 | AG24: 0 | AJ24: =SUMIF('6월 매출현황(6.26)'!$B:$B,Main!C24,'6월 매출현황(6.26)'!$N:$N) -> 0 | AM24: =AC24+AD24+AE24+AF24+AG24+AJ24 -> 0 | AO24: 0 | AP24: 0 | AQ24: - 전체적으로 시장자체가 어려운 상황 | BC24: 1 | BD24: =AA24*BB24 -> 0 | BE24: =AA24*BC24 -> 39
B25: 이승희 | C25: 타이어프로당하점 | E25: 0 | F25: 0 | G25: =E25+F25 -> 0 | H25: 0 | I25: 0 | J25: =H25+I25 -> 0 | K25: 0 | L25: 0 | M25: =K25+L25 -> 0 | N25: 0 | O25: 0 | P25: =N25+O25 -> 0 | Q25: 0 | R25: 0 | S25: =Q25+R25 -> 0 | T25: 0 | U25: 158 | V25: =T25+U25 -> 158 | W25: =J25 -> 0 | X25: =M25 -> 0 | Y25: =P25 -> 0 | Z25: =S25 -> 0 | AA25: =V25 -> 158 | AB25: =IFERROR(AA25/$AA$8,0) -> 0.00036227896 | AC25: 0 | AD25: 12 | AE25: 22 | AF25: 42 | AG25: 18 | AI25: 20 | AJ25: =SUMIF('6월 매출현황(6.26)'!$B:$B,Main!C25,'6월 매출현황(6.26)'!$N:$N) -> 8 | AM25: =AC25+AD25+AE25+AF25+AG25+AJ25 -> 102 | AO25: 0 | AP25: 0 | AQ25: - HK : 가격인상 이슈(미확정) , LVR 숏티지 예상 | BC25: 1 | BD25: =AA25*BB25 -> 0 | BE25: =AA25*BC25 -> 158
B26: 이승희 | C26: 정왕타이어 | E26: 0 | F26: 0 | G26: =E26+F26 -> 0 | H26: 0 | I26: 0 | J26: =H26+I26 -> 0 | K26: 0 | L26: 0 | M26: =K26+L26 -> 0 | N26: 0 | O26: 0 | P26: =N26+O26 -> 0 | Q26: 0 | R26: 288 | S26: =Q26+R26 -> 288 | T26: 0 | U26: 6 | V26: =T26+U26 -> 6 | W26: =J26 -> 0 | X26: =M26 -> 0 | Y26: =P26 -> 0 | Z26: =S26 -> 288 | AA26: =V26 -> 6 | AB26: =IFERROR(AA26/$AA$8,0) -> 1.3757429e-05 | AC26: 1 | AD26: 0 | AE26: 0 | AF26: 2 | AG26: 0 | AJ26: =SUMIF('6월 매출현황(6.26)'!$B:$B,Main!C26,'6월 매출현황(6.26)'!$N:$N) -> 0 | AM26: =AC26+AD26+AE26+AF26+AG26+AJ26 -> 3 | AO26: 0 | AP26: 0 | AQ26: - KH : 가격인상 이슈(미확정) | BC26: 1 | BD26: =AA26*BB26 -> 0 | BE26: =AA26*BC26 -> 6
B27: 이승희 | C27: 타이어프로 목감점 | E27: 0 | F27: 0 | G27: =E27+F27 -> 0 | H27: 20 | I27: 30 | J27: =H27+I27 -> 50 | K27: 27 | L27: 22 | M27: =K27+L27 -> 49 | N27: 20 | O27: 50 | P27: =N27+O27 -> 70 | Q27: 39 | R27: 84 | S27: =Q27+R27 -> 123 | T27: 91 | U27: 40 | V27: =T27+U27 -> 131 | W27: =J27 -> 50 | X27: =M27 -> 49 | Y27: =P27 -> 70 | Z27: =S27 -> 123 | AA27: =V27 -> 131 | AB27: =IFERROR(AA27/$AA$8,0) -> 0.00030037053 | AC27: 0 | AD27: 0 | AE27: 0 | AF27: 0 | AG27: 2 | AJ27: =SUMIF('6월 매출현황(6.26)'!$B:$B,Main!C27,'6월 매출현황(6.26)'!$N:$N) -> 2 | AM27: =AC27+AD27+AE27+AF27+AG27+AJ27 -> 4 | AO27: 0 | AP27: 0 | AQ27: - MI, CO : 공격적인 프로모션 진행 중 (상품권 등) | BC27: 1 | BD27: =AA27*BB27 -> 0 | BE27: =AA27*BC27 -> 131
B28: 이승희 | C28: 트루맨컴퍼니 | AC28: 28 | AD28: 0 | AE28: 0 | AF28: 0 | AG28: 6 | AI28: 10 | AJ28: =SUMIF('6월 매출현황(6.26)'!$B:$B,Main!C28,'6월 매출현황(6.26)'!$N:$N) -> 0 | AM28: =AC28+AD28+AE28+AF28+AG28+AJ28 -> 34 | AO28: 0 | AP28: 0 | BC28: 1 | BD28: =AA28*BB28 -> 0 | BE28: =AA28*BC28 -> 0
B29: 이승희 | C29: 타이어월드(BS시흥) | E29: 190 | F29: 197 | G29: =E29+F29 -> 387 | H29: 44 | I29: 147 | J29: =H29+I29 -> 191 | K29: 180 | L29: 368 | M29: =K29+L29 -> 548 | N29: 349 | O29: 364 | P29: =N29+O29 -> 713 | Q29: 174 | R29: 323 | S29: =Q29+R29 -> 497 | T29: 174 | U29: 255 | V29: =T29+U29 -> 429 | W29: =J29 -> 191 | X29: =M29 -> 548 | Y29: =P29 -> 713 | Z29: =S29 -> 497 | AA29: =V29 -> 429 | AB29: =IFERROR(AA29/$AA$8,0) -> 0.00098365617 | AC29: 27 | AD29: 38 | AE29: 30 | AF29: 37 | AG29: 18 | AI29: 20 | AJ29: =SUMIF('6월 매출현황(6.26)'!$B:$B,Main!C29,'6월 매출현황(6.26)'!$N:$N) -> 27 | AM29: =AC29+AD29+AE29+AF29+AG29+AJ29 -> 177 | AO29: 0 | AP29: 0 | BC29: 1 | BD29: =AA29*BB29 -> 0 | BE29: =AA29*BC29 -> 429
B30: 이승희 | C30: 타이어피플 | AG30: 20 | AI30: 20 | AJ30: =SUMIF('6월 매출현황(6.26)'!$B:$B,Main!C30,'6월 매출현황(6.26)'!$N:$N) -> 60 | AK30: 20 | AM30: =AC30+AD30+AE30+AF30+AG30+AJ30 -> 80
B31: 이승희 | C31: 타이어아울렛 (마석 본점) | E31: 0 | F31: 0 | G31: =E31+F31 -> 0 | H31: 0 | I31: 0 | J31: =H31+I31 -> 0 | K31: 0 | L31: 0 | M31: =K31+L31 -> 0 | N31: 0 | O31: 0 | P31: =N31+O31 -> 0 | S31: =Q31+R31 -> 0 | T31: 0 | U31: 153 | V31: =T31+U31 -> 153 | W31: =J31 -> 0 | X31: =M31 -> 0 | Y31: =P31 -> 0 | Z31: =S31 -> 0 | AA31: =V31 -> 153 | AB31: =IFERROR(AA31/$AA$8,0) -> 0.00035081444 | AC31: 30 | AD31: 24 | AE31: 20 | AF31: 0 | AG31: 0 | AJ31: =SUMIF('6월 매출현황(6.26)'!$B:$B,Main!C31,'6월 매출현황(6.26)'!$N:$N) -> 0 | AM31: =AC31+AD31+AE31+AF31+AG31+AJ31 -> 74 | AO31: 0 | AP31: 0 | BC31: 1 | BD31: =AA31*BB31 -> 0 | BE31: =AA31*BC31 -> 153
B32: 이승희 | C32: 주식회사 북항현대판매(구_신광사) | E32: 9 | F32: 16 | G32: =E32+F32 -> 25 | H32: 10 | I32: 8 | J32: =H32+I32 -> 18 | K32: 4 | L32: 16 | M32: =K32+L32 -> 20 | N32: 4 | O32: 1 | P32: =N32+O32 -> 5 | Q32: 6 | R32: 18 | S32: =Q32+R32 -> 24 | T32: 0 | U32: 10 | V32: =T32+U32 -> 10 | W32: =J32 -> 18 | X32: =M32 -> 20 | Y32: =P32 -> 5 | Z32: =S32 -> 24 | AA32: =V32 -> 10 | AB32: =IFERROR(AA32/$AA$8,0) -> 2.2929048e-05 | AC32: 2 | AD32: 0 | AE32: 0 | AF32: 0 | AG32: 6 | AJ32: =SUMIF('6월 매출현황(6.26)'!$B:$B,Main!C32,'6월 매출현황(6.26)'!$N:$N) -> 4 | AM32: =AC32+AD32+AE32+AF32+AG32+AJ32 -> 12 | AO32: 0 | AP32: 0 | BC32: 1 | BD32: =AA32*BB32 -> 0 | BE32: =AA32*BC32 -> 10
B33: 이승희 | C33: 춘천타이어 2호점 | E33: 0 | F33: 0 | G33: =E33+F33 -> 0 | H33: 0 | I33: 0 | J33: =H33+I33 -> 0 | K33: 0 | L33: 0 | M33: =K33+L33 -> 0 | N33: 0 | O33: 0 | P33: =N33+O33 -> 0 | S33: =Q33+R33 -> 0 | T33: 0 | U33: 32 | V33: =T33+U33 -> 32 | W33: =J33 -> 0 | X33: =M33 -> 0 | Y33: =P33 -> 0 | Z33: =S33 -> 0 | AA33: =V33 -> 32 | AB33: =IFERROR(AA33/$AA$8,0) -> 7.3372955e-05 | AC33: 14 | AD33: 11 | AE33: 0 | AF33: 8 | AG33: 0 | AI33: 20 | AJ33: =SUMIF('6월 매출현황(6.26)'!$B:$B,Main!C33,'6월 매출현황(6.26)'!$N:$N) -> 0 | AM33: =AC33+AD33+AE33+AF33+AG33+AJ33 -> 33 | AO33: 0 | AP33: 0 | BC33: 1 | BD33: =AA33*BB33 -> 0 | BE33: =AA33*BC33 -> 32
B34: 이승희 | C34: 타이어프로 신천IC점 | E34: 0 | F34: 0 | G34: =E34+F34 -> 0 | H34: 0 | I34: 0 | J34: =H34+I34 -> 0 | K34: 0 | L34: 0 | M34: =K34+L34 -> 0 | N34: 0 | O34: 79 | P34: =N34+O34 -> 79 | Q34: 13 | R34: 7 | S34: =Q34+R34 -> 20 | T34: 0 | U34: 0 | V34: =T34+U34 -> 0 | W34: =J34 -> 0 | X34: =M34 -> 0 | Y34: =P34 -> 79 | Z34: =S34 -> 20 | AA34: =V34 -> 0 | AB34: =IFERROR(AA34/$AA$8,0) -> 0 | AC34: 0 | AD34: 0 | AE34: 0 | AF34: 0 | AG34: 0 | AJ34: =SUMIF('6월 매출현황(6.26)'!$B:$B,Main!C34,'6월 매출현황(6.26)'!$N:$N) -> 0 | AM34: =AC34+AD34+AE34+AF34+AG34+AJ34 -> 0 | AO34: 0 | AP34: 0 | BC34: 1 | BD34: =AA34*BB34 -> 0 | BE34: =AA34*BC34 -> 0
B35: 이승희 | C35: (주)유일이엔티 | E35: 0 | F35: 0 | G35: =E35+F35 -> 0 | H35: 0 | I35: 226 | J35: =H35+I35 -> 226 | K35: 551 | L35: 181 | M35: =K35+L35 -> 732 | N35: 27 | O35: 0 | P35: =N35+O35 -> 27 | Q35: 0 | R35: 0 | S35: =Q35+R35 -> 0 | T35: 0 | U35: 0 | V35: =T35+U35 -> 0 | W35: =J35 -> 226 | X35: =M35 -> 732 | Y35: =P35 -> 27 | Z35: =S35 -> 0 | AA35: =V35 -> 0 | AB35: =IFERROR(AA35/$AA$8,0) -> 0 | AC35: 0 | AD35: 0 | AE35: 0 | AF35: 0 | AG35: 0 | AJ35: =SUMIF('6월 매출현황(6.26)'!$B:$B,Main!C35,'6월 매출현황(6.26)'!$N:$N) -> 0 | AM35: =AC35+AD35+AE35+AF35+AG35+AJ35 -> 0 | AO35: 0 | AP35: 0 | BC35: 1 | BD35: =AA35*BB35 -> 0 | BE35: =AA35*BC35 -> 0
B36: 이승희 | C36: 타이어팩토리 호계점 | E36: 0 | F36: 0 | G36: =E36+F36 -> 0 | H36: 0 | I36: 0 | J36: =H36+I36 -> 0 | K36: 0 | L36: 0 | M36: =K36+L36 -> 0 | N36: 0 | O36: 20 | P36: =N36+O36 -> 20 | Q36: 0 | R36: 0 | S36: =Q36+R36 -> 0 | T36: 0 | U36: 0 | V36: =T36+U36 -> 0 | W36: =J36 -> 0 | X36: =M36 -> 0 | Y36: =P36 -> 20 | Z36: =S36 -> 0 | AA36: =V36 -> 0 | AB36: =IFERROR(AA36/$AA$8,0) -> 0 | AC36: 0 | AD36: 0 | AE36: 0 | AF36: 0 | AG36: 0 | AJ36: =SUMIF('6월 매출현황(6.26)'!$B:$B,Main!C36,'6월 매출현황(6.26)'!$N:$N) -> 0 | AM36: =AC36+AD36+AE36+AF36+AG36+AJ36 -> 0 | AO36: 0 | AP36: 0 | BC36: 1 | BD36: =AA36*BB36 -> 0 | BE36: =AA36*BC36 -> 0
B37: 이승희 | C37: 티스테이션 시흥은계점 | E37: 0 | F37: 0 | G37: =E37+F37 -> 0 | H37: 44 | I37: 105 | J37: =H37+I37 -> 149 | K37: 22 | L37: 147 | M37: =K37+L37 -> 169 | N37: 30 | O37: 50 | P37: =N37+O37 -> 80 | Q37: 0 | R37: 27 | S37: =Q37+R37 -> 27 | T37: 11 | U37: 0 | V37: =T37+U37 -> 11 | W37: =J37 -> 149 | X37: =M37 -> 169 | Y37: =P37 -> 80 | Z37: =S37 -> 27 | AA37: =V37 -> 11 | AB37: =IFERROR(AA37/$AA$8,0) -> 2.5221953e-05 | AC37: 0 | AD37: 0 | AE37: 0 | AF37: 0 | AG37: 0 | AJ37: =SUMIF('6월 매출현황(6.26)'!$B:$B,Main!C37,'6월 매출현황(6.26)'!$N:$N) -> 0 | AM37: =AC37+AD37+AE37+AF37+AG37+AJ37 -> 0 | AO37: 0 | AP37: 0 | BC37: 1 | BD37: =AA37*BB37 -> 0 | BE37: =AA37*BC37 -> 11
B38: 이승희 | C38: 평촌오토자동차(주) | E38: 0 | F38: 0 | G38: =E38+F38 -> 0 | H38: 0 | I38: 0 | J38: =H38+I38 -> 0 | K38: 50 | L38: 0 | M38: =K38+L38 -> 50 | N38: 0 | O38: 0 | P38: =N38+O38 -> 0 | Q38: 0 | R38: 0 | S38: =Q38+R38 -> 0 | T38: 0 | U38: 0 | V38: =T38+U38 -> 0 | W38: =J38 -> 0 | X38: =M38 -> 50 | Y38: =P38 -> 0 | Z38: =S38 -> 0 | AA38: =V38 -> 0 | AB38: =IFERROR(AA38/$AA$8,0) -> 0 | AC38: 0 | AD38: 0 | AE38: 0 | AF38: 0 | AG38: 0 | AJ38: =SUMIF('6월 매출현황(6.26)'!$B:$B,Main!C38,'6월 매출현황(6.26)'!$N:$N) -> 0 | AM38: =AC38+AD38+AE38+AF38+AG38+AJ38 -> 0 | AO38: 0 | AP38: 0 | BC38: 1 | BD38: =AA38*BB38 -> 0 | BE38: =AA38*BC38 -> 0
B39: 이승희 | C39: 동림TDS(2010) | E39: 2 | F39: 0 | G39: =E39+F39 -> 2 | H39: 0 | I39: 0 | J39: =H39+I39 -> 0 | K39: 0 | L39: 0 | M39: =K39+L39 -> 0 | N39: 0 | O39: 0 | P39: =N39+O39 -> 0 | Q39: 0 | R39: 4 | S39: =Q39+R39 -> 4 | T39: 0 | U39: 0 | V39: =T39+U39 -> 0 | W39: =J39 -> 0 | X39: =M39 -> 0 | Y39: =P39 -> 0 | Z39: =S39 -> 4 | AA39: =V39 -> 0 | AB39: =IFERROR(AA39/$AA$8,0) -> 0 | AC39: 0 | AD39: 0 | AE39: 0 | AF39: 0 | AG39: 0 | AJ39: =SUMIF('6월 매출현황(6.26)'!$B:$B,Main!C39,'6월 매출현황(6.26)'!$N:$N) -> 0 | AM39: =AC39+AD39+AE39+AF39+AG39+AJ39 -> 0 | AO39: 0 | AP39: 0 | BC39: 1 | BD39: =AA39*BB39 -> 0 | BE39: =AA39*BC39 -> 0
B40: 이승희 | C40: (주)동림산업-BDG | E40: 4 | F40: 0 | G40: =E40+F40 -> 4 | H40: 0 | I40: 0 | J40: =H40+I40 -> 0 | K40: 0 | L40: 0 | M40: =K40+L40 -> 0 | N40: 0 | O40: 2 | P40: =N40+O40 -> 2 | Q40: 0 | R40: 0 | S40: =Q40+R40 -> 0 | T40: 2 | U40: 0 | V40: =T40+U40 -> 2 | W40: =J40 -> 0 | X40: =M40 -> 0 | Y40: =P40 -> 2 | Z40: =S40 -> 0 | AA40: =V40 -> 2 | AB40: =IFERROR(AA40/$AA$8,0) -> 4.5858097e-06 | AC40: 0 | AD40: 0 | AE40: 0 | AF40: 0 | AG40: 0 | AJ40: =SUMIF('6월 매출현황(6.26)'!$B:$B,Main!C40,'6월 매출현황(6.26)'!$N:$N) -> 0 | AM40: =AC40+AD40+AE40+AF40+AG40+AJ40 -> 0 | AO40: 0 | AP40: 0 | BC40: 1 | BD40: =AA40*BB40 -> 0 | BE40: =AA40*BC40 -> 2
...

Sheet Sheet4

Sheet Y26 3+9(5.6)
B2: Y26 3+9 Masterfile
B4: Q'ty | E4: FCST | Q4: Total | X4: Y27 Total | Y4: Y28 Total
E5: Jan | F5: Feb | G5: Mar | H5: Apr | I5: May | J5: Jun | K5: Jul | L5: Aug | M5: Sep | N5: Oct | O5: Nov | P5: Dec
B6: PSR | C6: REP | E6: ='[52](PSR) 3+9'!I3 -> 18205 | F6: ='[52](PSR) 3+9'!N3 -> 25326 | G6: ='[52](PSR) 3+9'!S3 -> 30594 | H6: 31580 | I6: 34656 | J6: 42119 | K6: ='[52](PSR) 3+9'!AM3 -> 41678 | L6: ='[52](PSR) 3+9'!AR3 -> 50165 | M6: ='[52](PSR) 3+9'!AW3 -> 48461 | N6: ='[52](PSR) 3+9'!BB3 -> 51017 | O6: ='[52](PSR) 3+9'!BG3 -> 48287 | P6: ='[52](PSR) 3+9'!BL3 -> 52147 | Q6: =SUM(E6:P6) -> 474235 | X6: ='[52](PSR) 3+9'!BU3 -> 481949 | Y6: ='[52](PSR) 3+9'!BZ3 -> 506046 | Z6: 473893.48 | AA6: =Z6-Q6 -> -341.51798 | AC6: =SUM(K6:P6) -> 291755
C7: OE | Q7: =SUM(E7:P7) -> 0
C8: PSR(G) TTL | E8: =+E7+E6 -> 18205 | F8: =+F7+F6 -> 25326 | G8: =+G7+G6 -> 30594 | H8: =+H7+H6 -> 31580 | I8: =+I7+I6 -> 34656 | J8: =+J7+J6 -> 42119 | K8: =+K7+K6 -> 41678 | L8: =+L7+L6 -> 50165 | ... P8: =+P7+P6 -> 52147 | Q8: =Q6+Q7 -> 474235 | R8: =+R6+R7 -> 0 | S8: =+S6+S7 -> 0 | T8: =+T6+T7 -> 0 | U8: =+U6+U7 -> 0 | V8: =+V6+V7 -> 0 | W8: =+W6+W7 -> 0 | X8: =+X6+X7 -> 481949 | Y8: =+Y6+Y7 -> 506046
B9: TBR | C9: REP | E9: ='[52](TBR) 3+9'!I3 -> 5233 | F9: ='[52](TBR) 3+9'!N3 -> 9850 | G9: ='[52](TBR) 3+9'!S3 -> 20655 | H9: 15997 | I9: ='[52](TBR) 3+9'!AC3 -> 17800 | J9: 29532 | K9: 18510 | L9: ='[52](TBR) 3+9'!AR3 -> 24540 | M9: ='[52](TBR) 3+9'!AW3 -> 28815 | N9: ='[52](TBR) 3+9'!BB3 -> 29310 | O9: ='[52](TBR) 3+9'!BG3 -> 39993 | P9: ='[52](TBR) 3+9'!BL3 -> 46365 | Q9: =SUM(E9:P9) -> 286600 | R9: =SUM(F9:Q9) -> 567967 | S9: =SUM(G9:R9) -> 1126084 | T9: =SUM(H9:S9) -> 2231513 | U9: =SUM(I9:T9) -> 4447029 | V9: =SUM(J9:U9) -> 8876258 | W9: =SUM(K9:V9) -> 17722984 | X9: ='[52](TBR) 3+9'!BU3 -> 297190 | Y9: ='[52](TBR) 3+9'!BZ3 -> 303134 | Z9: 292363 | AA9: =Z9-Q9 -> 5763 | AC9: =SUM(K9:P9) -> 187533
C10: OE | D10: HMC | Q10: =SUM(E10:P10) -> 0 | R10: =SUM(F10:Q10) -> 0 | S10: =SUM(G10:R10) -> 0 | T10: =SUM(H10:S10) -> 0 | U10: =SUM(I10:T10) -> 0 | V10: =SUM(J10:U10) -> 0 | W10: =SUM(K10:V10) -> 0 | X10: =SUM(L10:W10) -> 0 | Y10: =SUM(M10:X10) -> 0
D11: TATA | Q11: =SUM(E11:P11) -> 0 | R11: =SUM(F11:Q11) -> 0 | S11: =SUM(G11:R11) -> 0 | T11: =SUM(H11:S11) -> 0 | U11: =SUM(I11:T11) -> 0 | V11: =SUM(J11:U11) -> 0 | W11: =SUM(K11:V11) -> 0 | X11: ='[52](TBR-TATA) 26OB 2nd Pass'!BU3 -> 12064 | Y11: ='[52](TBR-TATA) 26OB 2nd Pass'!BZ3 -> 13772
C12: TBR(G) TTL | E12: =+E11+E10+E9 -> 5233 | F12: =+F11+F10+F9 -> 9850 | G12: =+G11+G10+G9 -> 20655 | H12: =+H11+H10+H9 -> 15997 | I12: =+I11+I10+I9 -> 17800 | J12: =+J11+J10+J9 -> 29532 | K12: =+K11+K10+K9 -> 18510 | L12: =+L11+L10+L9 -> 24540 | ... P12: =+P11+P10+P9 -> 46365 | Q12: =+Q9+Q10+Q11 -> 286600 | R12: =+R9+R10+R11 -> 567967 | S12: =+S9+S10+S11 -> 1126084 | T12: =+T9+T10+T11 -> 2231513 | U12: =+U9+U10+U11 -> 4447029 | V12: =+V9+V10+V11 -> 8876258 | W12: =+W9+W10+W11 -> 17722984 | X12: =+X9+X10+X11 -> 309254 | Y12: =+Y9+Y10+Y11 -> 316906
B13: Total | E13: =E9+E6 -> 23438 | F13: =F9+F6 -> 35176 | G13: =G9+G6 -> 51249 | H13: =H9+H6 -> 47577 | I13: =I9+I6 -> 52456 | J13: =J9+J6 -> 71651 | K13: =K9+K6 -> 60188 | L13: =L9+L6 -> 74705 | ... Y13: =Y9+Y6 -> 809180
B15: A'mt | E15: FCST | Q15: Total | X15: Y27 Total | Y15: Y28 Total
E16: Jan | F16: Feb | G16: Mar | H16: Apr | I16: May | J16: Jun | K16: Jul | L16: Aug | M16: Sep | N16: Oct | O16: Nov | P16: Dec
B17: PSR | C17: REP | D17: Gross | E17: ='[52](PSR) 3+9'!J3 -> 2169081861 | F17: ='[52](PSR) 3+9'!O3 -> 2813777342 | G17: ='[52](PSR) 3+9'!T3 -> 3505593416 | H17: 3859532675 | I17: ='[52](PSR) 3+9'!AD3 -> 4.4906167e+09 | J17: ='[52](PSR) 3+9'!AI3 -> 5.4321657e+09 | K17: ='[52](PSR) 3+9'!AN3 -> 5.5521653e+09 | L17: ='[52](PSR) 3+9'!AS3 -> 6.759813e+09 | M17: ='[52](PSR) 3+9'!AX3 -> 6.4611522e+09 | N17: ='[52](PSR) 3+9'!BC3 -> 6.6730406e+09 | O17: ='[52](PSR) 3+9'!BH3 -> 6.2263572e+09 | P17: ='[52](PSR) 3+9'!BM3 -> 6.691804e+09 | Q17: =SUM(E17:P17) -> 6.06351e+10 | R17: =SUM(F17:Q17) -> 1.1910112e+11 | S17: =SUM(G17:R17) -> 2.3538846e+11 | T17: =SUM(H17:S17) -> 4.6727133e+11 | U17: =SUM(I17:T17) -> 9.3068312e+11 | V17: =SUM(J17:U17) -> 1.8568756e+12 | W17: =SUM(K17:V17) -> 3.7083191e+12 | X17: ='[52](PSR) 3+9'!BV3 -> 6.2283951e+10 | Y17: ='[52](PSR) 3+9'!CA3 -> 6.5394312e+10 | AB17: PSR REP : 2월 전체 Net 금액은 변화없지만, BPC별로 살짝 수정함 B2B 최종을 최종으로 반영해서 큰차이는 없습니다.
D18: Rebate | E18: =E17-E19 -> 1.0133074e+08 | F18: =F17-F19 -> 1.6319909e+08 | G18: =G17-G19 -> 1.6650831e+08 | H18: 491159455 | I18: =I17-I19 -> 5.7189221e+08 | J18: =J17-J19 -> 7.0516978e+08 | K18: =K17-K19 -> 5.6045727e+08 | L18: =L17-L19 -> 6.885916e+08 | M18: =M17-M19 -> 6.5627206e+08 | N18: =N17-N19 -> 6.7854301e+08 | O18: =O17-O19 -> 6.2916107e+08 | P18: =P17-P19 -> 6.745392e+08 | ... Y18: =Y17-Y19 -> 6.5730733e+09 | AB18: 이대운 매니저 수식 안물린거 6월에 수정 그래서 최종 맞춤
D19: Net | E19: ='[52](PSR) 3+9'!K3 -> 2.0677511e+09 | F19: ='[52](PSR) 3+9'!P3 -> 2.6505783e+09 | G19: ='[52](PSR) 3+9'!U3 -> 3.3390851e+09 | H19: 3366229324 | I19: ='[52](PSR) 3+9'!AE3 -> 3.9187245e+09 | J19: ='[52](PSR) 3+9'!AJ3 -> 4.7269959e+09 | K19: ='[52](PSR) 3+9'!AO3 -> 4.9917081e+09 | L19: ='[52](PSR) 3+9'!AT3 -> 6.0712214e+09 | M19: ='[52](PSR) 3+9'!AY3 -> 5.8048802e+09 | N19: ='[52](PSR) 3+9'!BD3 -> 5.9944976e+09 | O19: ='[52](PSR) 3+9'!BI3 -> 5.5971961e+09 | P19: ='[52](PSR) 3+9'!BN3 -> 6.0172648e+09 | Q19: =SUM(E19:P19) -> 5.4546132e+10 | V19: 4.9988117e+10 | W19: =V19-Q19 -> -4.5580156e+09 | X19: 5.6020227e+10 | Y19: 5.8821239e+10 | Z19: 5.3352598e+10 | AA19: =Z19-Q19 -> -1.1935349e+09 | AC19: =SUM(K19:P19) -> 3.4476768e+10
C20: OE | D20: Net | Q20: =SUM(E20:P20) -> 0 | R20: =SUM(F20:Q20) -> 0 | S20: =SUM(G20:R20) -> 0 | T20: =SUM(H20:S20) -> 0 | U20: =SUM(I20:T20) -> 0 | V20: =SUM(J20:U20) -> 0 | W20: =SUM(K20:V20) -> 0 | X20: =SUM(L20:W20) -> 0 | Y20: =SUM(M20:X20) -> 0
C21: PSR(G) TTL | E21: =E20+E19 -> 2.0677511e+09 | F21: =F20+F19 -> 2.6505783e+09 | G21: =G20+G19 -> 3.3390851e+09 | H21: =H20+H19 -> 3366229324 | I21: =I20+I19 -> 3.9187245e+09 | J21: =J20+J19 -> 4.7269959e+09 | K21: =K20+K19 -> 4.9917081e+09 | L21: =L20+L19 -> 6.0712214e+09 | ... P21: =P20+P19 -> 6.0172648e+09 | Q21: =Q19+Q20 -> 5.4546132e+10 | R21: =R19+R20 -> 0 | S21: =S19+S20 -> 0 | T21: =T19+T20 -> 0 | U21: =U19+U20 -> 0 | V21: =V19+V20 -> 4.9988117e+10 | W21: =W19+W20 -> -4.5580156e+09 | X21: =X19+X20 -> 5.6020227e+10 | Y21: =Y19+Y20 -> 5.8821239e+10
B22: TBR | C22: REP | D22: Gross | E22: ='[52](TBR) 3+9'!J3 -> 1436598400 | F22: ='[52](TBR) 3+9'!O3 -> 3042567725 | G22: ='[52](TBR) 3+9'!T3 -> 6148037027 | H22: 4975223663 | I22: ='[52](TBR) 3+9'!AD3 -> 5.428073e+09 | J22: ='[52](TBR) 3+9'!AI3 -> 9.0575725e+09 | K22: ='[52](TBR) 3+9'!AN3 -> 5.8519039e+09 | L22: ='[52](TBR) 3+9'!AS3 -> 7.6146604e+09 | M22: ='[52](TBR) 3+9'!AX3 -> 9.0128557e+09 | N22: ='[52](TBR) 3+9'!BC3 -> 9.1291261e+09 | O22: ='[52](TBR) 3+9'!BH3 -> 1.2476612e+10 | P22: ='[52](TBR) 3+9'!BM3 -> 1.4411214e+10 | Q22: =SUM(E22:P22) -> 8.8584444e+10 | R22: =SUM(F22:Q22) -> 1.7573229e+11 | S22: =SUM(G22:R22) -> 3.4842201e+11 | T22: =SUM(H22:S22) -> 6.9069599e+11 | U22: =SUM(I22:T22) -> 1.3764168e+12 | V22: =SUM(J22:U22) -> 2.7474054e+12 | W22: =SUM(K22:V22) -> 5.4857533e+12 | X22: ='[52](TBR) 3+9'!BV3 -> 9.0484792e+10 | Y22: ='[52](TBR) 3+9'!CA3 -> 9.1934061e+10
D23: Rebate | E23: =E22-E24 -> 0 | F23: =F22-F24 -> 3.3854638e+08 | G23: =G22-G24 -> 2.8491364e+08 | H23: 324238377 | I23: =I22-I24 -> 4.121848e+08 | J23: =J22-J24 -> 6.6950534e+08 | K23: =K22-K24 -> 3.7309979e+08 | L23: =L22-L24 -> 4.9928943e+08 | M23: =M22-M24 -> 5.8474234e+08 | N23: =N22-N24 -> 6.0117618e+08 | O23: =O22-O24 -> 8.074094e+08 | P23: =P22-P24 -> 9.4358928e+08 | Q23: =SUM(E23:P23) -> 5.838695e+09 | R23: =SUM(F23:Q23) -> 1.167739e+10 | S23: =SUM(G23:R23) -> 2.3016233e+10 | T23: =SUM(H23:S23) -> 4.5747553e+10 | U23: =SUM(I23:T23) -> 9.1170868e+10 | V23: =SUM(J23:U23) -> 1.8192955e+11 | W23: =SUM(K23:V23) -> 3.631896e+11 | X23: =X22-X24 -> 6.249576e+09 | Y23: =Y22-Y24 -> 6.3510822e+09
D24: Net | E24: ='[52](TBR) 3+9'!K3 -> 1436598400 | F24: ='[52](TBR) 3+9'!P3 -> 2.7040213e+09 | G24: ='[52](TBR) 3+9'!U3 -> 5.8631234e+09 | H24: 4650985286 | I24: ='[52](TBR) 3+9'!AE3 -> 5.0158882e+09 | J24: ='[52](TBR) 3+9'!AJ3 -> 8.3880671e+09 | K24: ='[52](TBR) 3+9'!AO3 -> 5.4788041e+09 | L24: ='[52](TBR) 3+9'!AT3 -> 7.115371e+09 | M24: ='[52](TBR) 3+9'!AY3 -> 8.4281133e+09 | N24: ='[52](TBR) 3+9'!BD3 -> 8.5279499e+09 | O24: ='[52](TBR) 3+9'!BI3 -> 1.1669203e+10 | P24: ='[52](TBR) 3+9'!BN3 -> 1.3467625e+10 | Q24: =SUM(E24:P24) -> 8.2745749e+10 | R24: =SUM(F24:Q24) -> 1.640549e+11 | S24: =SUM(G24:R24) -> 3.2540578e+11 | T24: =SUM(H24:S24) -> 6.4494844e+11 | U24: =SUM(I24:T24) -> 1.2852459e+12 | V24: =SUM(J24:U24) -> 2.5654759e+12 | W24: =SUM(K24:V24) -> 5.1225637e+12 | X24: ='[52](TBR) 3+9'!BW3 -> 8.4235216e+10 | Y24: ='[52](TBR) 3+9'!CB3 -> 8.5582979e+10 | Z24: 8.3763106e+10 | AA24: =Z24-Q24 -> 1.0173569e+09 | AB24: =Q24-AA24 -> 8.1728393e+10 | AC24: =SUM(K24:P24) -> 5.4687066e+10
C25: OE | D25: HMC | Q25: =SUM(E25:P25) -> 0 | R25: =SUM(F25:Q25) -> 0 | S25: =SUM(G25:R25) -> 0 | T25: =SUM(H25:S25) -> 0 | U25: =SUM(I25:T25) -> 0 | V25: =SUM(J25:U25) -> 0 | W25: =SUM(K25:V25) -> 0
D26: TATA | Q26: =SUM(E26:P26) -> 0 | R26: =SUM(F26:Q26) -> 0 | S26: =SUM(G26:R26) -> 0 | T26: =SUM(H26:S26) -> 0 | U26: =SUM(I26:T26) -> 0 | V26: =SUM(J26:U26) -> 0 | W26: =SUM(K26:V26) -> 0 | X26: ='[52](TBR-TATA) 26OB 2nd Pass'!BW3 -> 3402289390 | Y26: ='[52](TBR-TATA) 26OB 2nd Pass'!CB3 -> 3842999930
C27: TBR(G) TTL | E27: =E24+E25+E26 -> 1436598400 | F27: =F24+F25+F26 -> 2.7040213e+09 | G27: =G24+G25+G26 -> 5.8631234e+09 | H27: =H24+H25+H26 -> 4650985286 | I27: =I24+I25+I26 -> 5.0158882e+09 | J27: =J24+J25+J26 -> 8.3880671e+09 | K27: =K24+K25+K26 -> 5.4788041e+09 | L27: =L24+L25+L26 -> 7.115371e+09 | ... P27: =P24+P25+P26 -> 1.3467625e+10 | Q27: =SUM(E27:P27) -> 8.2745749e+10 | R27: =SUM(F27:Q27) -> 1.640549e+11 | S27: =SUM(G27:R27) -> 3.2540578e+11 | T27: =SUM(H27:S27) -> 6.4494844e+11 | U27: =SUM(I27:T27) -> 1.2852459e+12 | V27: =SUM(J27:U27) -> 2.5654759e+12 | W27: =SUM(K27:V27) -> 5.1225637e+12 | X27: =SUM(X24:X26) -> 8.7637505e+10 | Y27: =SUM(Y24:Y26) -> 8.9425979e+10
B28: Total | E28: =E19+E24 -> 3.5043495e+09 | F28: =F19+F24 -> 5.3545996e+09 | G28: =G19+G24 -> 9.2022085e+09 | H28: =H19+H24 -> 8017214610 | I28: =I19+I24 -> 8.9346126e+09 | J28: =J19+J24 -> 1.3115063e+10 | K28: =K19+K24 -> 1.0470512e+10 | L28: =L19+L24 -> 1.3186592e+10 | ... P28: =P19+P24 -> 1.9484889e+10 | Q28: =SUM(E28:P28) -> 1.3729188e+11 | R28: =SUM(F28:Q28) -> 2.7107941e+11 | S28: =SUM(G28:R28) -> 5.3680423e+11 | T28: =SUM(H28:S28) -> 1.0644062e+12 | U28: =SUM(I28:T28) -> 2.1207953e+12 | V28: =SUM(J28:U28) -> 4.232656e+12 | W28: =SUM(K28:V28) -> 8.4521969e+12
E30: 18205 | F30: 25326 | G30: 30586.511
E31: =E30-E6 -> 0 | F31: =F30-F6 -> 0 | G31: =G30-G6 -> -7.488586
E32: 2.0677511e+09 | F32: 2.6505783e+09 | G32: 3.3231633e+09
E33: =E32-E19 -> 0 | F33: =F32-F19 -> 0 | G33: =G32-G19 -> -15921816
E34: 1436598400 | F34: 2.7040213e+09 | G34: 5508000000
E35: =E34-E24 -> 0 | F35: =F34-F24 -> 0 | G35: =G34-G24 -> -3.5512339e+08
E37: 5233 | F37: 9850 | G37: 20300
E38: =E37-E9 -> 0 | F38: =F37-F9 -> 0 | G38: =G37-G9 -> -355
K48: =K23/K22 -> 0.063756992 | L48: =L23/L22 -> 0.065569494 | M48: =M23/M22 -> 0.064878698 | N48: =N23/N22 -> 0.065852544 | O48: =O23/O22 -> 0.064713834 | P48: =P23/P22 -> 0.065476044
E49: =E6 -> 18205 | F49: =F6 -> 25326 | G49: =G6 -> 30594 | H49: =H6 -> 31580 | I49: =I6 -> 34656 | J49: =J6 -> 42119 | K49: =K6 -> 41678 | L49: =L6 -> 50165 | ... Q49: =Q6 -> 474235
E50: =E9 -> 5233 | F50: =F9 -> 9850 | G50: =G9 -> 20655 | H50: =H9 -> 15997 | I50: =I9 -> 17800 | J50: =J9 -> 29532 | K50: =K9 -> 18510 | L50: =L9 -> 24540 | ... Q50: =Q9 -> 286600
E51: =E11 -> 0 | F51: =F11 -> 0 | G51: =G11 -> 0 | H51: =H11 -> 0 | I51: =I11 -> 0 | J51: =J11 -> 0 | K51: =K11 -> 0 | L51: =L11 -> 0 | ... Q51: =Q11 -> 0
E52: =SUM(E49:E51) -> 23438 | F52: =SUM(F49:F51) -> 35176 | G52: =SUM(G49:G51) -> 51249 | H52: =SUM(H49:H51) -> 47577 | I52: =SUM(I49:I51) -> 52456 | J52: =SUM(J49:J51) -> 71651 | K52: =SUM(K49:K51) -> 60188 | L52: =SUM(L49:L51) -> 74705 | ... Q52: =SUM(Q49:Q51) -> 760835
E53: =E17 -> 2169081861 | F53: =F17 -> 2813777342 | G53: =G17 -> 3505593416 | H53: =H17 -> 3859532675 | I53: =I17 -> 4.4906167e+09 | J53: =J17 -> 5.4321657e+09 | K53: =K17 -> 5.5521653e+09 | L53: =L17 -> 6.759813e+09 | ... Q53: =Q17 -> 6.06351e+10
E54: =-E18 -> -1.0133074e+08 | F54: =-F18 -> -1.6319909e+08 | G54: =-G18 -> -1.6650831e+08 | H54: =-H18 -> -491159455 | I54: =-I18 -> -5.7189221e+08 | J54: =-J18 -> -7.0516978e+08 | K54: =-K18 -> -5.6045727e+08 | L54: =-L18 -> -6.885916e+08 | ... Q54: =-Q18 -> -6.0889677e+09
...

Sheet Y26 Plan (4.3)
E1: =E10/E2 -> 1.3411669 | F1: =F10/F2 -> 1.1084074 | G1: =G10/G2 -> 1.1628278 | H1: =H10/H2 -> 1.181595 | I1: =I10/I2 -> 1.2192621 | J1: =J10/J2 -> 1.2355529 | K1: =K10/K2 -> 1.0631428 | L1: =L10/L2 -> 1.1588283 | ... W1: =W10/W2 -> 1.1246463 | Z1: LE3 | AA1: 30000 | AB1: 83664.405 | AC1: =AB1*AA1 -> 2.5099321e+09
C2: 25 Act | D2: Q'ty | E2: 13574 | F2: 22849 | G2: 26310 | H2: =+E2+F2+G2 -> 62733 | I2: 24788 | J2: 26574 | K2: 36964 | L2: =+I2+J2+K2 -> 88326 | M2: =L2+H2 -> 151059 | N2: 31347 | O2: 45956 | P2: 46959 | Q2: =+N2+O2+P2 -> 124262 | R2: 51299 | S2: 57760 | T2: 52316 | U2: =+R2+S2+T2 -> 161375 | V2: =U2+Q2 -> 285637 | W2: =V2+M2 -> 436696 | Z2: Winter | AA2: -15000 | AB2: 123000 | AC2: =AB2*AA2 -> -1845000000
D3: Net AMT | E3: 1.645403e+09 | F3: 2.4686141e+09 | G3: 2.7993785e+09 | H3: =+E3+F3+G3 -> 6.9133957e+09 | I3: 2.8310113e+09 | J3: 2.8958416e+09 | K3: 4.347935e+09 | L3: =+I3+J3+K3 -> 1.0074788e+10 | M3: =L3+H3 -> 1.6988184e+10 | N3: 3.6750325e+09 | O3: 5.4434825e+09 | P3: 5.0580172e+09 | Q3: =+N3+O3+P3 -> 1.4176532e+10 | R3: 5.6019277e+09 | S3: 5.6937983e+09 | T3: 6.1335519e+09 | U3: =+R3+S3+T3 -> 1.7429278e+10 | V3: =U3+Q3 -> 3.160581e+10 | W3: =V3+M3 -> 4.8593994e+10 | Y3: 17235.537 | AC3: =AC2+AC1 -> 6.6493214e+08 | AD3: =AC3/15000 -> 44328.809
C5: Volume : pcs | E5: Jan | F5: Feb | G5: Mar | H5: 1Q | I5: Apr | J5: May | K5: Jun | L5: 2Q | M5: 1H TTL | N5: Jul | O5: Aug | P5: Sep | Q5: 3Q | R5: Oct | S5: Nov | T5: Dec | U5: 4Q | V5: 2H TTL | W5: FY TTL | Y5: FY TTL | Z5: LE3+winter impact | AA5: 소물류 fcst | AB5: TTL | AC5: Turanza AS6
C6: OB | D6: Q'ty | E6: 16091 | F6: 22633 | G6: 26329 | H6: =+E6+F6+G6 -> 65053 | I6: 29180 | J6: 31700 | K6: 41311 | L6: =+I6+J6+K6 -> 102191 | M6: =H6+L6 -> 167244 | N6: 41678 | O6: 50165 | P6: 48461 | Q6: =+N6+O6+P6 -> 140304 | R6: 51017 | S6: 48287 | T6: 52147 | U6: =+R6+S6+T6 -> 151451 | V6: =+Q6+U6 -> 291755 | W6: =V6+M6 -> 458999 | Y6: 458999 | AB6: 458999
C7: RF | D7: Q'ty | E7: 18205 | F7: 25326 | G7: 30594 | H7: =+E7+F7+G7 -> 74125 | I7: 30055 | J7: 32651 | K7: 38085 | L7: =+I7+J7+K7 -> 100791 | M7: =L7+H7 -> 174916 | N7: 42928 | O7: 51670 | P7: 49915 | Q7: =+N7+O7+P7 -> 144513 | R7: 51017 | S7: 49736 | T7: 53711 | U7: =+R7+S7+T7 -> 154464 | V7: =U7+Q7 -> 298977 | W7: =V7+M7 -> 473893 | Y7: 463305.75 | AB7: 463305.75
C8: SL | D8: Q'ty | I8: 168.06901 | J8: 182.58354 | K8: 213.01188 | L8: =+I8+J8+K8 -> 563.66443 | M8: =L8+H8 -> 563.66443 | N8: 240.05416 | O8: 288.93701 | P8: 279.12243 | Q8: =+N8+O8+P8 -> 808.1136 | R8: 285.28573 | S8: 278.12023 | T8: 300.3528 | U8: =+R8+S8+T8 -> 863.75877 | V8: =U8+Q8 -> 1671.8724 | W8: =V8+M8 -> 2235.5368
C9: Add | D9: Q'ty | K9: 1000 | L9: =+I9+J9+K9 -> 1000 | M9: =L9+H9 -> 1000 | N9: 2000 | O9: 2000 | P9: 2000 | Q9: =+N9+O9+P9 -> 6000 | R9: 2000 | S9: 3000 | T9: 3000 | U9: =+R9+S9+T9 -> 8000 | V9: =U9+Q9 -> 14000 | W9: =V9+M9 -> 15000
C10: ACT/Fcst | D10: Q'ty | E10: =E7+E8+E9 -> 18205 | F10: =F7+F8+F9 -> 25326 | G10: =G7+G8+G9 -> 30594 | H10: =H7+H8+H9 -> 74125 | I10: =I7+I8+I9 -> 30223.069 | J10: =J7+J8+J9 -> 32833.584 | K10: =K7+K8+K9 -> 39298.012 | L10: =L7+L8+L9 -> 102354.66 | ... W10: =W7+W8+W9 -> 491128.54 | Y10: 473893 | Z10: 15000 | AA10: 2200 | AB10: =Y10+Z10+AA10 -> 491093 | AC10: 13000 | AD10: =AC10+AB10 -> 504093
D11: % vs RF | E11: =E10/E7 -> 1 | F11: =F10/F7 -> 1 | G11: =G10/G7 -> 1 | H11: =H10/H7 -> 1 | I11: =I10/I7 -> 1.005592 | J11: =J10/J7 -> 1.005592 | K11: =K10/K7 -> 1.0318501 | L11: =L10/L7 -> 1.0155139 | ... W11: =W10/W7 -> 1.0363701 | Y11: 1.0228527
D12: % vs OB | E12: =E10/E6 -> 1.1313778 | F12: =F10/F6 -> 1.1189856 | G12: =G10/G6 -> 1.1619887 | H12: =H10/H6 -> 1.1394555 | I12: =I10/I6 -> 1.035746 | J12: =J10/J6 -> 1.0357597 | K12: =K10/K6 -> 0.95127235 | L12: =L10/L6 -> 1.0016016 | ... W12: =W10/W6 -> 1.0699991 | Y12: 1.03245 | AB12: =AB10/AB6 -> 1.0699217 | AD12: =AD10/AB6 -> 1.0982442
D13: +/- vs OB | E13: =E10-E6 -> 2114 | F13: =F10-F6 -> 2693 | G13: =G10-G6 -> 4265 | H13: =H10-H6 -> 9072 | I13: =I10-I6 -> 1043.069 | J13: =J10-J6 -> 1133.5835 | K13: =K10-K6 -> -2012.9881 | L13: =L10-L6 -> 163.66443 | ... Q13: =Q10-Q6 -> 11017.114 | S13: =S10-S6 -> 4727.1202 | U13: =U10-U6 -> 11876.759 | V13: =V10-V6 -> 22893.872 | W13: =W10-W6 -> 32129.537 | Y13: 14894.54
D14: vs PY | E14: =E10/E2 -> 1.3411669 | F14: =F10/F2 -> 1.1084074 | G14: =G10/G2 -> 1.1628278 | H14: =H10/H2 -> 1.181595 | I14: =I10/I2 -> 1.2192621 | J14: =J10/J2 -> 1.2355529 | K14: =K10/K2 -> 1.0631428 | L14: =L10/L2 -> 1.1588283 | ... W14: =W10/W2 -> 1.1246463 | Y14: 1.0851795
C16: Net Amount : MKkrw | E16: Jan | F16: Feb | G16: Mar | H16: 1Q | I16: Apr | J16: May | K16: Jun | L16: 2Q | M16: 1H TTL | N16: Jul | O16: Aug | P16: Sep | Q16: 3Q | R16: Oct | S16: Nov | T16: Dec | U16: 4Q | V16: 2H TTL | W16: FY TTL | Y16: FY TTL | AC16: 121000
C17: OB | D17: Net AMT | E17: 1.8991156e+09 | F17: 2.6051572e+09 | G17: 3.0210575e+09 | H17: =+E17+F17+G17 -> 7.5253304e+09 | I17: 3.2949287e+09 | J17: 3.6081728e+09 | K17: 4.7887515e+09 | L17: =+I17+J17+K17 -> 1.1691853e+10 | M17: =L17+H17 -> 1.9217183e+10 | N17: 4.9422852e+09 | O17: 6.0111103e+09 | P17: 5.7474061e+09 | Q17: =+N17+O17+P17 -> 1.6700802e+10 | R17: 5.9351462e+09 | S17: 5.5417783e+09 | T17: 5.9576879e+09 | U17: =+R17+S17+T17 -> 1.7434612e+10 | V17: =U17+Q17 -> 3.4135414e+10 | W17: =V17+M17 -> 5.3352598e+10 | Y17: 5.3352598e+10 | AB17: 5.3352598e+10
C18: RF | D18: Net AMT | E18: 2.0677511e+09 | F18: 2.6505783e+09 | G18: 3.3390851e+09 | H18: =+E18+F18+G18 -> 8.0574145e+09 | I18: 3.2949287e+09 | J18: 3.6081728e+09 | K18: 4.2566674e+09 | L18: =+I18+J18+K18 -> 1.1159769e+10 | M18: =L18+H18 -> 1.9217183e+10 | N18: 4.9422852e+09 | O18: 6.0111103e+09 | P18: 5.7474061e+09 | Q18: =+N18+O18+P18 -> 1.6700802e+10 | R18: 5.9351462e+09 | S18: 5.5417783e+09 | T18: 5.9576879e+09 | U18: =+R18+S18+T18 -> 1.7434612e+10 | V18: =U18+Q18 -> 3.4135414e+10 | W18: =V18+M18 -> 5.3352598e+10 | Y18: 5.3352598e+10 | AB18: 5.3352598e+10
C19: SL | D19: Net AMT | H19: =+E19+F19+G19 -> 0 | I19: 30398674 | J19: 33288632 | K19: 39428254 | L19: =+I19+J19+K19 -> 1.0311556e+08 | M19: =L19+H19 -> 1.0311556e+08 | N19: 45597016 | O19: 55457886 | P19: 53024978 | Q19: =+N19+O19+P19 -> 1.5407988e+08 | R19: 54757049 | S19: 51127878 | T19: 54965017 | U19: =+R19+S19+T19 -> 1.6084994e+08 | V19: =U19+Q19 -> 3.1492982e+08 | W19: =V19+M19 -> 4.1804538e+08
C20: Add | D20: Net AMT | H20: =+E20+F20+G20 -> 0 | K20: 44328809 | L20: =+I20+J20+K20 -> 44328809 | M20: =L20+H20 -> 44328809 | N20: 88657619 | O20: 88657619 | P20: 88657619 | Q20: =+N20+O20+P20 -> 2.6597286e+08 | R20: 88657619 | S20: 1.3298643e+08 | T20: 1.3298643e+08 | U20: =+R20+S20+T20 -> 3.5463047e+08 | V20: =U20+Q20 -> 6.2060333e+08 | W20: =V20+M20 -> 6.6493214e+08
C21: ACT/Fcst | D21: Net AMT | E21: =E18+E19+E20 -> 2.0677511e+09 | F21: =F18+F19+F20 -> 2.6505783e+09 | G21: =G18+G19+G20 -> 3.3390851e+09 | H21: =H18+H19+H20 -> 8.0574145e+09 | I21: =I18+I19+I20 -> 3.3253274e+09 | J21: =J18+J19+J20 -> 3.6414615e+09 | K21: =K18+K19+K20 -> 4.3404245e+09 | L21: =L18+L19+L20 -> 1.1307213e+10 | ... W21: =W18+W19+W20 -> 5.4435575e+10 | Y21: 5.3352598e+10 | Z21: =AC3 -> 6.6493214e+08 | AA21: 418000000 | AB21: =Y21+Z21+AA21 -> 5.443553e+10 | AC21: =AC10*AC16 -> 1573000000 | AD21: =AB21+AC21 -> 5.600853e+10
D22: % vs RF | E22: =E21/E18 -> 1 | F22: =F21/F18 -> 1 | G22: =G21/G18 -> 1 | H22: =H21/H18 -> 1 | I22: =I21/I18 -> 1.0092259 | J22: =J21/J18 -> 1.0092259 | K22: =K21/K18 -> 1.0196767 | L22: =L21/L18 -> 1.0132121 | ... W22: =W21/W18 -> 1.0202985 | Y22: 1 | AB22: =AB21/AB17 -> 1.0202976 | AD22: =AD21/AB18 -> 1.0497807
D23: % vs OB | E23: =E21/E17 -> 1.0887968 | F23: =F21/F17 -> 1.017435 | G23: =G21/G17 -> 1.1052703 | H23: =H21/H17 -> 1.0707057 | I23: =I21/I17 -> 1.0092259 | J23: =J21/J17 -> 1.0092259 | K23: =K21/K17 -> 0.90637915 | L23: =L21/L17 -> 0.9671019 | ... W23: =W21/W17 -> 1.0202985 | Y23: 1
D24: +/- vs OB | E24: =E21-E17 -> 1.6863547e+08 | F24: =F21-F17 -> 45421021 | G24: =G21-G17 -> 3.1802757e+08 | H24: =H21-H17 -> 5.3208407e+08 | I24: =I21-I17 -> 30398674 | J24: =J21-J17 -> 33288632 | K24: =K21-K17 -> -4.48327e+08 | L24: =L21-L17 -> -3.846397e+08 | ... W24: =W21-W17 -> 1.0829775e+09 | Y24: 0
D25: vs PY | E25: =E21/E3 -> 1.2566837 | F25: =F21/F3 -> 1.0737111 | G25: =G21/G3 -> 1.1927951 | H25: =H21/H3 -> 1.1654786 | I25: =I21/I3 -> 1.1746076 | J25: =J21/J3 -> 1.2574795 | K25: =K21/K3 -> 0.99827263 | L25: =L21/L3 -> 1.1223277 | ... W25: =W21/W3 -> 1.120212 | Y25: 1.0979258
C26: ASP | D26: OB | E26: =E17/E6 -> 118023.47 | F26: =F17/F6 -> 115104.37 | G26: =G17/G6 -> 114742.59 | H26: =H17/H6 -> 115679.99 | I26: =I17/I6 -> 112917.37 | J26: =J17/J6 -> 113822.49 | K26: =K17/K6 -> 115919.52 | L26: =L17/L6 -> 114411.77 | ... W26: =W17/W6 -> 116236.85 | Y26: 116236.85
D27: ACT/FCST | E27: =E21/E10 -> 113581.5 | F27: =F21/F10 -> 104658.38 | G27: =G21/G10 -> 109141.83 | H27: =H21/H10 -> 108700.36 | I27: =I21/I10 -> 110026.13 | J27: =J21/J10 -> 110906.61 | K27: =K21/K10 -> 110448.96 | L27: =L21/L10 -> 110470.91 | ... W27: =W21/W10 -> 110837.74 | Y27: 112583.51
C29: 1. Mar sales review
C30: - Qty : 116.2% vs 26OB | E30: ▶ Dealers' purchases have increased before price increase
E31: ▶ Successful launching of RE005(Sales : 3,170 pcs / Preorder : 12,000 pcs)
C32: - Amt :110.5% vs 26OB | E32: ▶ Although sales vol increased, there is amt gap due to mix sales
C34: 2. Apr sales plan
C35: - Qty : 103% vs 26OB | E35: ▶ Plan to achieve 103% of volume to meet revenue target.
E36: ▶ Increase sales volume with early bird promotion(LVR)
C37: - Amt : 100% vs 26OB | E37: ▶ The price increase settles down in the market to secure the target ASP.
E38: ▶ Focus on selling high ASP products with various promotions(Potenza sport AS, Turanza EV, KOE)

Sheet 6월 매출현황(6.26)
N1: =SUBTOTAL(109,N3:N2000) -> 33446
A2: NO | B2: 거래처 | C2: 품목분류 | D2: MTP분류 | E2: 이익부서 | F2: ProdCode | G2: SIZE | H2: PTTN | I2: 원산지 | J2: 공장도가 | K2: 2026-06 | L2: QTY | M2: 합계금액 | N2: 합계수량
A3: 1 | B3: 동남타이어(순천) | C3: PSR | D3: UHP(17UP） | E3: 이양희 | F3: PSR0174F | G3: 235/60R/18 | H3: WEATHERGRIP | I3: 일본 | J3: 281930 | K3: 212729 | L3: 2 | M3: 212729 | N3: 2
A4: 2 | B4: 타이어파크(타이어프로남구점) | C4: PSR | D4: 4x4(L) | E4: 이상호 | F4: PSR17613 | G4: 245/50R/20 (HD PALISADE) | H4: DHPS-AS | I4: 일본 | J4: 414370 | K4: 188953 | L4: 1 | M4: 188953 | N4: 1
A5: 3 | B5: 종합타이어(마산) | C5: PSR | D5: UHP(17UP） | E5: 이양희 | F5: PSR0V258 | G5: 225/45R/18 (SERENITY PLUS) | H5: EL64Z | I5: 베트남 | J5: 269390 | K5: 431024 | L5: 4 | M5: 431024 | N5: 4
A6: 4 | B6: (주)드래곤드림 | C6: PSR | D6: LVR | E6: 임봉빈 | F6: LVR09734 | G6: 215/75R/16 (ISUZU ELF) | H6: R294 | I6: 일본 | J6: 281490 | K6: 886847 | L6: 8 | M6: 886847 | N6: 8
A7: 5 | B7: 주식회사태안가설기업 | C7: PSR | D7: UHP(17UP） | E7: 송강호 | F7: PSR0G819 | G7: 255/45R/20 (BMW 7 series),B-Silent | H7: TURANZA 6 | I7: 유럽 | J7: 681010 | K7: 763636 | L7: 2 | M7: 763636 | N7: 2
A8: 6 | B8: 주식회사태안가설기업 | C8: PSR | D8: UHP(17UP） | E8: 송강호 | F8: PSR0G820 | G8: 285/40R/20 (BMW 7series/ENLITEN) | H8: TURANZA 6 | I8: 유럽 | J8: 756580 | K8: 854546 | L8: 2 | M8: 854546 | N8: 2
A9: 7 | B9: 주식회사태안가설기업 | C9: PSR | D9: RFT | E9: 송강호 | F9: PSR0U466 | G9: 245/50R/19 RFT (BMW 2018 X3) | H9: ALENZA 001 | I9: 미국 | J9: 585750 | K9: 927273 | L9: 3 | M9: 927273 | N9: 3
A10: 8 | B10: 한국타이어김천판매(주) | C10: PSR | D10: 4x4(L) | E10: 이상호 | F10: PSR0183F | G10: 235/55R/19 | H10: DESTINATION LE3 | I10: 일본 | J10: 257620 | K10: 398140 | L10: 4 | M10: 398140 | N10: 4
A11: 9 | B11: 한국타이어김천판매(주) | C11: PSR | D11: 4x4(L) | E11: 이상호 | F11: PSR0184F | G11: 235/60R/18 | H11: DESTINATION LE3 | I11: 일본 | J11: 252010 | K11: 389470 | L11: 4 | M11: 389470 | N11: 4
A12: 10 | B12: 한국타이어김천판매(주) | C12: PSR | D12: 4x4(L) | E12: 이상호 | F12: PSR0189F | G12: 235/65R/17 | H12: DESTINATION LE3 | I12: 일본 | J12: 219450 | K12: 339150 | L12: 4 | M12: 339150 | N12: 4
A13: 11 | B13: 한국타이어김천판매(주) | C13: PSR | D13: UHP(17UP） | E13: 이상호 | F13: PSR0197F | G13: 235/55R/18 | H13: FS-All season | I13: 일본 | J13: 218020 | K13: 336940 | L13: 4 | M13: 336940 | N13: 4
A14: 12 | B14: 한국타이어김천판매(주) | C14: PSR | D14: 4x4(L) | E14: 이상호 | F14: PSR0209F | G14: 255/50R/20 | H14: DESTINATION LE3 | I14: 일본 | J14: 305800 | K14: 472600 | L14: 4 | M14: 472600 | N14: 4
... A1863: 1861 | B1863: 타이어킹박사(주) | C1863: PSR | D1863: UHP(17UP） | E1863: 이양희 | F1863: PSR0NJD0 | G1863: 245/45R/19 (SERENITY PLUS) | H1863: EL64Z | I1863: 인도네시아 | J1863: 356290 | K1863: 570064 | L1863: 4 | M1863: 570064 | N1863: 4

Sheet 5월 매출현황(5.31)
N1: =SUBTOTAL(109,N3:N2000) -> 35505
A2: NO | B2: 거래처 | C2: 품목분류 | D2: MTP분류 | E2: 이익부서 | F2: ProdCode | G2: SIZE | H2: PTTN | I2: 원산지 | J2: 공장도가 | K2: 2026-05 | L2: QTY | M2: 합계금액 | N2: 합계수량
A3: 1 | B3: 타이어파크(타이어프로남구점) | C3: PSR | D3: UHP(17UP） | E3: 이상호 | F3: PSR0251F | G3: 215/55R/17 | H3: FS-All season | I3: 일본 | J3: 199650 | K3: 150645 | L3: 2 | M3: 150645 | N3: 2
A4: 2 | B4: 타이어파크(타이어프로남구점) | C4: PSR | D4: UHP(17UP） | E4: 이상호 | F4: PSR0259F | G4: 225/55R/17 | H4: FS-All season | I4: 일본 | J4: 203610 | K4: 468303 | L4: 6 | M4: 468303 | N4: 6
A5: 3 | B5: 타이어파크(타이어프로남구점) | C5: PSR | D5: UHP(17UP） | E5: 이상호 | F5: PSR0G165 | G5: 225/40R/19 (Benz A-CLASS, B-CLASS, CLA) | H5: T005 | I5: 유럽 | J5: 560890 | K5: 290643 | L5: 2 | M5: 290643 | N5: 2
A6: 4 | B6: 타이어파크(타이어프로남구점) | C6: PSR | D6: UHP(17UP） | E6: 이상호 | F6: PSR0LD19 | G6: 225/50R/17 | H6: EP300 | I6: 태국 | J6: 194370 | K6: 155496 | L6: 2 | M6: 155496 | N6: 2
A7: 5 | B7: 타이어파크(타이어프로남구점) | C7: PSR | D7: UHP(17UP） | E7: 이상호 | F7: PSR0LD20 | G7: 245/45R/18 | H7: EP300 | I7: 태국 | J7: 203170 | K7: 1483141 | L7: 20 | M7: 1483141 | N7: 20
A8: 6 | B8: 타이어파크(타이어프로남구점) | C8: PSR | D8: UHP(17UP） | E8: 이상호 | F8: PSR0NJD2 | G8: 225/45R/17 (SERENITY PLUS) | H8: EL64Z | I8: 인도네시아 | J8: 231330 | K8: 370128 | L8: 4 | M8: 370128 | N8: 4
A9: 7 | B9: 타이어파크(타이어프로남구점) | C9: PSR | D9: 4x4(L) | E9: 이상호 | F9: PSR0W470 | G9: 235/60R/18 | H9: D400 | I9: 중국 | J9: 232870 | K9: 1061887 | L9: 12 | M9: 1061887 | N9: 12
A10: 8 | B10: 타이어파크(타이어프로남구점) | C10: PSR | D10: UHP(17UP） | E10: 이상호 | F10: PSR17734 | G10: 235/45R/18 (TOYOTA CAMRY & ES) | H10: EL440 | I10: 일본 | J10: 420530 | K10: 810629 | L10: 4 | M10: 810629 | N10: 4
A11: 9 | B11: 타이어파크(타이어프로남구점) | C11: PSR | D11: UHP(17UP） | E11: 이상호 | F11: PSR17888 | G11: 255/55R/18 (LEXUS RZ, ENLITEN) | H11: EL450 | I11: 일본 | J11: 400840 | K11: 764365 | L11: 4 | M11: 764365 | N11: 4
A12: 10 | B12: 타이어파크(타이어프로남구점) | C12: PSR | D12: 4x4(L) | E12: 이상호 | F12: PSR18007 | G12: 235/55R/19 | H12: D400 | I12: 일본 | J12: 270490 | K12: 1233434 | L12: 12 | M12: 1233434 | N12: 12
A13: 11 | B13: 타이어피플 | C13: PSR | D13: 4x4(L) | E13: 이승희 | F13: PSR0182F | G13: 225/55R/18 | H13: DESTINATION LE3 | I13: 일본 | J13: 238810 | K13: 360386 | L13: 4 | M13: 360386 | N13: 4
A14: 12 | B14: 타이어피플 | C14: PSR | D14: 4x4(L) | E14: 이승희 | F14: PSR0183F | G14: 235/55R/19 | H14: DESTINATION LE3 | I14: 일본 | J14: 257620 | K14: 388772 | L14: 4 | M14: 388772 | N14: 4
... A1963: 1961 | B1963: 타이어킹박사(주) | C1963: PSR | D1963: UHP(17UP） | E1963: 이양희 | F1963: PSR0NJC8 | G1963: 235/45R/18 (SERENITY PLUS) | H1963: EL64Z | I1963: 인도네시아 | J1963: 270600 | K1963: 865920 | L1963: 8 | M1963: 865920 | N1963: 8

Sheet Sheet1
B2: 거래처 | C2: 품목분류 | D2: MTP분류 | E2: 이익부서 | F2: ProdCode | G2: SIZE | H2: PTTN | I2: 원산지 | J2: 공장도가 | K2: 2026-04 | L2: QTY | M2: 합계금액 | N2: 합계수량
B3: 비케이모터스(구.대경) | C3: PSR | D3: LVR | E3: 이상호 | F3: LVR0L328 | G3: 195/70R/15 | H3: R710 | I3: 태국 | J3: 208890 | K3: 3653676 | L3: 52 | M3: 3653676 | N3: 52 | P3: R710 | Q3: =SUMIF($H:$H,P3,$N:$N) -> 138
B4: 비케이모터스(구.대경) | C4: PSR | D4: LVR | E4: 이상호 | F4: LVR0L331 | G4: 195R/15 | H4: R710 | I4: 태국 | J4: 193710 | K4: 2736594 | L4: 42 | M4: 2736594 | N4: 42 | P4: DESTINATION LE3 | Q4: =SUMIF($H:$H,P4,$N:$N) -> 249
B5: 비케이모터스(구.대경) | C5: PSR | D5: LVR | E5: 이상호 | F5: LVR0L334 | G5: 215/70R/16 | H5: R710 | I5: 태국 | J5: 247610 | K5: 2665184 | L5: 32 | M5: 2665184 | N5: 32 | P5: FS-All season | Q5: =SUMIF($H:$H,P5,$N:$N) -> 6
B6: 비케이모터스(구.대경) | C6: PSR | D6: LVR | E6: 이상호 | F6: LVR0L337 | G6: 185R/14 | H6: R710 | I6: 태국 | J6: 182600 | K6: 614200 | L6: 10 | M6: 614200 | N6: 10 | P6: D685 | Q6: =SUMIF($H:$H,P6,$N:$N) -> 20
B7: 비케이모터스(구.대경) | C7: PSR | D7: LVR | E7: 이상호 | F7: LVR0L338 | G7: 195R/14 | H7: R710 | I7: 태국 | J7: 204710 | K7: 141436 | L7: 2 | M7: 141436 | N7: 2 | P7: ALENZA 001 | Q7: =SUMIF($H:$H,P7,$N:$N) -> 0 | T7: R710 | U7: 138
B8: 비케이모터스(구.대경) | C8: PSR | D8: 4x4(L) | E8: 이상호 | F8: PSR0182F | G8: 225/55R/18 | H8: DESTINATION LE3 | I8: 일본 | J8: 238810 | K8: 3430180 | L8: 40 | M8: 3430180 | N8: 40 | P8: T005 | Q8: =SUMIF($H:$H,P8,$N:$N) -> 8 | T8: DESTINATION LE3 | U8: 249
B9: 비케이모터스(구.대경) | C9: PSR | D9: 4x4(L) | E9: 이상호 | F9: PSR0183F | G9: 235/55R/19 | H9: DESTINATION LE3 | I9: 일본 | J9: 257620 | K9: 17576710 | L9: 190 | M9: 17576710 | N9: 190 | P9: DHPA | Q9: =SUMIF($H:$H,P9,$N:$N) -> 2 | T9: RE005 | U9: 291
B10: 비케이모터스(구.대경) | C10: PSR | D10: 4x4(L) | E10: 이상호 | F10: PSR0184F | G10: 235/60R/18 | H10: DESTINATION LE3 | I10: 일본 | J10: 252010 | K10: -570459 | L10: -6 | M10: -570459 | N10: -6 | P10: POTENZA SPORT | Q10: =SUMIF($H:$H,P10,$N:$N) -> 1 | T10: EL64Z | U10: 111
B11: 비케이모터스(구.대경) | C11: PSR | D11: 4x4(L) | E11: 이상호 | F11: PSR0186F | G11: 225/60R/18 | H11: DESTINATION LE3 | I11: 일본 | J11: 244970 | K11: -1773806 | L11: -19 | M11: -1773806 | N11: -19 | P11: S005 | Q11: =SUMIF($H:$H,P11,$N:$N) -> 1
B12: 비케이모터스(구.대경) | C12: PSR | D12: 4x4(L) | E12: 이상호 | F12: PSR0187F | G12: 225/65R/17 | H12: DESTINATION LE3 | I12: 일본 | J12: 222310 | K12: 83871 | L12: 1 | M12: 83871 | N12: 1 | P12: TURANZA 6 | Q12: =SUMIF($H:$H,P12,$N:$N) -> 25
