Workbook
Name asdasff: [1]!TORIHIKI_GET_B
Name asdasff: [1]!TORIHIKI_GET_B
Name brand: OFFSET([2]list!$W$8,0,0,COUNTA([2]list!$W:$W)-4,1)
Name compound: OFFSET([2]list!$BA$8,0,0,COUNTA([2]list!$BA:$BA)-4,1)
Name compulsoryRegistrationFlg: OFFSET([2]list!$B$8,0,0,COUNTA([2]list!$B:$B)-4,1)
Name data8012: #REF!
Name data8012: #REF!
Name data8012: #REF!
Name data8012: #REF!
Name dd: #REF!
Name dd: #REF!
Name dd: #REF!
Name dd: #REF!
Name disconCodeType: OFFSET([2]list!$AM$8,0,0,COUNTA([2]list!$AM:$AM)-4,1)
Name doubleSizeExpression: OFFSET([2]list!$AX$8,0,0,COUNTA([2]list!$AX:$AX)-4,1)
Name draftingDep: OFFSET([2]list!$H$8,0,0,COUNTA([2]list!$H:$H)-4,1)
Name draftingSbu: OFFSET([2]list!$G$8,0,0,COUNTA([2]list!$G:$G)-4,1)
Name expectedDevPole: OFFSET([2]list!$AP$8,0,0,COUNTA([2]list!$AP:$AP)-4,1)
Name extraLoadReinforced: OFFSET([2]list!$AE$8,0,0,COUNTA([2]list!$AE:$AE)-4,1)
Name FF_jisseki: #REF!
Name FF_jisseki: #REF!
Name FF_jisseki: #REF!
Name FF_jisseki: #REF!
Name gdcUse: OFFSET([2]list!$BE$8,0,0,COUNTA([2]list!$BE:$BE)-4,1)
Name holiday: [3]休日!$A$2:$A$999
Name ignoreFlg: OFFSET([2]list!$C$8,0,0,COUNTA([2]list!$C:$C)-4,1)
Name importantFlg: OFFSET([2]list!$BH$8,0,0,COUNTA([2]list!$BH:$BH)-4,1)
Name inSeasonAdd: OFFSET([2]list!$E$8,0,0,COUNTA([2]list!$E:$E)-4,1)
Name jisseki: #REF!
Name jisseki: #REF!
Name jisseki: #REF!
Name jisseki: #REF!
Name liAutoSettingYearbookCheck: OFFSET([2]list!$T$8,0,0,COUNTA([2]list!$T:$T)-4,1)
Name LLLF: '[4]4×4'!$A$1:$A$101
Name loadRange: OFFSET([2]list!$AD$8,0,0,COUNTA([2]list!$AD:$AD)-4,1)
Name moldInfo: OFFSET([2]list!$BJ$8,0,0,COUNTA([2]list!$BJ:$BJ)-4,1)
Name mudSnowExpression: OFFSET([2]list!$BC$8,0,0,COUNTA([2]list!$BC:$BC)-4,1)
Name oeCode: OFFSET([2]list!$L$8,0,0,COUNTA([2]list!$L:$L)-4,1)
Name offtake: OFFSET([2]list!$BF$8,0,0,COUNTA([2]list!$BF:$BF)-4,1)
Name patternType: OFFSET([2]list!$S$8,0,0,COUNTA([2]list!$S:$S)-4,1)
Name pfNecessity: OFFSET([2]list!$BI$8,0,0,COUNTA([2]list!$BI:$BI)-4,1)
Name plyRating: OFFSET([2]list!$AC$8,0,0,COUNTA([2]list!$AC:$AC)-4,1)
Name productCategory: OFFSET([2]list!$O$8,0,0,COUNTA([2]list!$O:$O)-4,1)
Name productGroupBsj: OFFSET([2]list!$V$8,0,0,COUNTA([2]list!$V:$V)-4,1)
Name productLayer: OFFSET([2]list!$BG$8,0,0,COUNTA([2]list!$BG:$BG)-4,1)
Name productName: OFFSET([5]list!$K$8,0,0,COUNTA([5]list!$K:$K)-4,1)
Name productName: OFFSET([6]list!$K$8,0,0,COUNTA([6]list!$K:$K)-4,1)
Name psReliable: OFFSET([2]list!$AO$8,0,0,COUNTA([2]list!$AO:$AO)-4,1)
Name radialBiasType: OFFSET([2]list!$AF$8,0,0,COUNTA([2]list!$AF:$AF)-4,1)
Name radialMark: OFFSET([2]list!$Z$8,0,0,COUNTA([2]list!$Z:$Z)-4,1)
Name radialMark: OFFSET([7]list!$Z$8,0,0,COUNTA([7]list!$Z:$Z)-4,1)
Name RE01ﾌﾟﾚﾐｱﾑ: #REF!
Name RE01ﾌﾟﾚﾐｱﾑ: #REF!
Name RE01ﾌﾟﾚﾐｱﾑ: #REF!
Name RE01ﾌﾟﾚﾐｱﾑ: #REF!
Name registrationFlg: OFFSET([2]list!$A$8,0,0,COUNTA([2]list!$A:$A)-5,1)
Name registrationReason: OFFSET([2]list!$I$8,0,0,COUNTA([2]list!$I:$I)-4,1)
Name regroovable: OFFSET([2]list!$AT$8,0,0,COUNTA([2]list!$AT:$AT)-4,1)
Name repOe: OFFSET([2]list!$J$8,0,0,COUNTA([2]list!$J:$J)-4,1)
Name rftType: OFFSET([2]list!$AG$8,0,0,COUNTA([2]list!$AG:$AG)-4,1)

Sheet Y26 Plan (2)
E1: =E10/E2 -> 1.3411669 | F1: =F10/F2 -> 1.1084074 | G1: =G10/G2 -> 1.1628278 | H1: =H10/H2 -> 1.181595 | I1: =I10/I2 -> 1.2740036 | J1: =J10/J2 -> 1.3341988 | K1: =K10/K2 -> 1.13946 | L1: =L10/L2 -> 1.2358083 | ... X1: =X10/X2 -> 1.0493254
C2: 25 Act | D2: Q'ty | E2: 13574 | F2: 22849 | G2: 26310 | H2: =+E2+F2+G2 -> 62733 | I2: 24788 | J2: 26574 | K2: 36964 | L2: =+I2+J2+K2 -> 88326 | M2: =L2+H2 -> 151059 | N2: 31347 | O2: 45956 | P2: 46959 | Q2: =+N2+O2+P2 -> 124262 | R2: 51299 | S2: 57760 | T2: 52316 | U2: =+R2+S2+T2 -> 161375 | V2: =U2+Q2 -> 285637 | W2: =V2+M2 -> 436696 | X2: 468043
D3: Net AMT | E3: 1.645403e+09 | F3: 2.4686141e+09 | G3: 2.7993785e+09 | H3: =+E3+F3+G3 -> 6.9133957e+09 | I3: 2.8310113e+09 | J3: 2.8958416e+09 | K3: 4.347935e+09 | L3: =+I3+J3+K3 -> 1.0074788e+10 | M3: =L3+H3 -> 1.6988184e+10 | N3: 3.6750325e+09 | O3: 5.4434825e+09 | P3: 5.0580172e+09 | Q3: =+N3+O3+P3 -> 1.4176532e+10 | R3: 5.6019277e+09 | S3: 5.6937983e+09 | T3: 6.1335519e+09 | U3: =+R3+S3+T3 -> 1.7429278e+10 | V3: =U3+Q3 -> 3.160581e+10 | W3: =V3+M3 -> 4.8593994e+10 | X3: 5.2269026e+10
C5: Volume : pcs | E5: Jan | F5: Feb | G5: Mar | H5: 1Q | I5: Apr | J5: May | K5: Jun | L5: 2Q | M5: 1H TTL | N5: Jul | O5: Aug | P5: Sep | Q5: 3Q | R5: Oct | S5: Nov | T5: Dec | U5: 4Q | V5: 2H TTL | W5: FY TTL | X5: FY TTL
C6: OB | D6: Q'ty | E6: 16091 | F6: 22633 | G6: 26329 | H6: =+E6+F6+G6 -> 65053 | I6: 29180 | J6: 31700 | K6: 41311 | L6: =+I6+J6+K6 -> 102191 | M6: =H6+L6 -> 167244 | N6: 41678 | O6: 50165 | P6: 48461 | Q6: =+N6+O6+P6 -> 140304 | R6: 51017 | S6: 48287 | T6: 52147 | U6: =+R6+S6+T6 -> 151451 | V6: =+Q6+U6 -> 291755 | W6: =V6+M6 -> 458999 | X6: 458999
C7: RF | D7: Q'ty | E7: 18205 | F7: 25326 | G7: 30594 | H7: =+E7+F7+G7 -> 74125 | I7: 30055 | J7: 32651 | K7: 38085 | L7: =+I7+J7+K7 -> 100791 | M7: =L7+H7 -> 174916 | N7: 42928 | O7: 51670 | P7: 49915 | Q7: =+N7+O7+P7 -> 144513 | R7: 51017 | S7: 49736 | T7: 53711 | U7: =+R7+S7+T7 -> 154464 | V7: =U7+Q7 -> 298977 | W7: =V7+M7 -> 473893 | X7: 473893 | Y7: =X7*11% -> 52128.23
C8: SL | D8: Q'ty | I8: 168.06901 | J8: 182.58354 | K8: 213.01188 | L8: =+I8+J8+K8 -> 563.66443 | M8: =L8+H8 -> 563.66443 | N8: 240.05416 | O8: 288.93701 | P8: 279.12243 | Q8: =+N8+O8+P8 -> 808.1136 | R8: 285.28573 | S8: 278.12023 | T8: 300.3528 | U8: =+R8+S8+T8 -> 863.75877 | V8: =U8+Q8 -> 1671.8724 | W8: =V8+M8 -> 2235.5368 | X8: 2235.5368
C9: Add | D9: Q'ty | K9: 1000 | L9: =+I9+J9+K9 -> 1000 | M9: =L9+H9 -> 1000 | N9: 2000 | O9: 2000 | P9: 2000 | Q9: =+N9+O9+P9 -> 6000 | R9: 2000 | S9: 3000 | T9: 3000 | U9: =+R9+S9+T9 -> 8000 | V9: =U9+Q9 -> 14000 | W9: =V9+M9 -> 15000 | X9: 15000
C10: ACT/Fcst | D10: Q'ty | E10: =E7+E8+E9 -> 18205 | F10: =F7+F8+F9 -> 25326 | G10: =G7+G8+G9 -> 30594 | H10: =+E10+F10+G10 -> 74125 | I10: 31580 | J10: 35455 | K10: 42119 | L10: =+I10+J10+K10 -> 109154 | M10: =L10+H10 -> 183279 | N10: 45168.054 | O10: 53958.937 | P10: 52194.122 | Q10: =+N10+O10+P10 -> 151321.11 | R10: 53302.286 | S10: 50014 | T10: 54012 | U10: =+R10+S10+T10 -> 157328.29 | V10: =U10+Q10 -> 308649.4 | W10: =V10+M10 -> 491928.4 | X10: 491129.4 | Y10: =X10-X6 -> 32130.399
D11: % vs RF | E11: =E10/E7 -> 1 | F11: =F10/F7 -> 1 | G11: =G10/G7 -> 1 | H11: =H10/H7 -> 1 | I11: =I10/I7 -> 1.0507403 | J11: =J10/J7 -> 1.0858779 | K11: =K10/K7 -> 1.105921 | L11: =L10/L7 -> 1.0829737 | ... W11: =W10/W7 -> 1.038058 | X11: 1.0363719
D12: % vs OB | E12: =E10/E6 -> 1.1313778 | F12: =F10/F6 -> 1.1189856 | G12: =G10/G6 -> 1.1619887 | H12: =H10/H6 -> 1.1394555 | I12: =I10/I6 -> 1.0822481 | J12: =J10/J6 -> 1.1184543 | K12: =K10/K6 -> 1.019559 | L12: =L10/L6 -> 1.0681371 | ... W12: =W10/W6 -> 1.0717418 | X12: 1.070001
D13: +/- vs OB | E13: =E10-E6 -> 2114 | F13: =F10-F6 -> 2693 | G13: =G10-G6 -> 4265 | H13: =H10-H6 -> 9072 | I13: =I10-I6 -> 2400 | J13: =J10-J6 -> 3755 | K13: =K10-K6 -> 808 | L13: =L10-L6 -> 6963 | ... Q13: =Q10-Q6 -> 11017.114 | S13: =S10-S6 -> 1727 | U13: =U10-U6 -> 5877.2857 | V13: =V10-V6 -> 16894.399 | W13: =W10-W6 -> 32929.399 | X13: 32129.537
D14: vs PY | E14: =E10/E2 -> 1.3411669 | F14: =F10/F2 -> 1.1084074 | G14: =G10/G2 -> 1.1628278 | H14: =H10/H2 -> 1.181595 | I14: =I10/I2 -> 1.2740036 | J14: =J10/J2 -> 1.3341988 | K14: =K10/K2 -> 1.13946 | L14: =L10/L2 -> 1.2358083 | ... W14: =W10/W2 -> 1.1264779 | X14: 1.1246463
C16: Net Amount : MKkrw | E16: Jan | F16: Feb | G16: Mar | H16: 1Q | I16: Apr | J16: May | K16: Jun | L16: 2Q | M16: 1H TTL | N16: Jul | O16: Aug | P16: Sep | Q16: 3Q | R16: Oct | S16: Nov | T16: Dec | U16: 4Q | V16: 2H TTL | W16: FY TTL | X16: FY TTL | AB16: 1H TTL
C17: OB | D17: Net AMT | E17: 1.8991156e+09 | F17: 2.6051572e+09 | G17: 3.0210575e+09 | H17: =+E17+F17+G17 -> 7.5253304e+09 | I17: 3.2949287e+09 | J17: 3.6081728e+09 | K17: 4.7887515e+09 | L17: =+I17+J17+K17 -> 1.1691853e+10 | M17: =L17+H17 -> 1.9217183e+10 | N17: 4.9422852e+09 | O17: 6.0111103e+09 | P17: 5.7474061e+09 | Q17: =+N17+O17+P17 -> 1.6700802e+10 | R17: 5.9351462e+09 | S17: 5.5417783e+09 | T17: 5.9576879e+09 | U17: =+R17+S17+T17 -> 1.7434612e+10 | V17: =U17+Q17 -> 3.4135414e+10 | W17: =V17+M17 -> 5.3352598e+10 | X17: 5.3352598e+10 | Z17: 3.6081728e+09 | AB17: 1.9217183e+10
C18: RF | D18: Net AMT | E18: 2.0677511e+09 | F18: 2.6505783e+09 | G18: 3.3390851e+09 | H18: =+E18+F18+G18 -> 8.0574145e+09 | I18: 3.2949287e+09 | J18: 3.6081728e+09 | K18: 4.2566674e+09 | L18: =+I18+J18+K18 -> 1.1159769e+10 | M18: =L18+H18 -> 1.9217183e+10 | N18: 4.9422852e+09 | O18: 6.0111103e+09 | P18: 5.7474061e+09 | Q18: =+N18+O18+P18 -> 1.6700802e+10 | R18: 5.9351462e+09 | S18: 5.5417783e+09 | T18: 5.9576879e+09 | U18: =+R18+S18+T18 -> 1.7434612e+10 | V18: =U18+Q18 -> 3.4135414e+10 | W18: =V18+M18 -> 5.3352598e+10 | X18: 5.3352598e+10 | Z18: 3.6081728e+09 | AB18: 1.9217183e+10
C19: SL | D19: Net AMT | H19: =+E19+F19+G19 -> 0 | I19: 30398674 | J19: 33288632 | K19: 39428254 | L19: =+I19+J19+K19 -> 1.0311556e+08 | M19: =L19+H19 -> 1.0311556e+08 | N19: 45597016 | O19: 55457886 | P19: 53024978 | Q19: =+N19+O19+P19 -> 1.5407988e+08 | R19: 54757049 | S19: 51127878 | T19: 54965017 | U19: =+R19+S19+T19 -> 1.6084994e+08 | V19: =U19+Q19 -> 3.1492982e+08 | W19: =V19+M19 -> 4.1804538e+08 | X19: 4.1804538e+08 | Z19: 33288632 | AB19: 1.0311556e+08
C20: Add | D20: Net AMT | H20: =+E20+F20+G20 -> 0 | K20: 44328809 | L20: =+I20+J20+K20 -> 44328809 | M20: =L20+H20 -> 44328809 | N20: 88657619 | O20: 88657619 | P20: 88657619 | Q20: =+N20+O20+P20 -> 2.6597286e+08 | R20: 88657619 | S20: 1.3298643e+08 | T20: 1.3298643e+08 | U20: =+R20+S20+T20 -> 3.5463047e+08 | V20: =U20+Q20 -> 6.2060333e+08 | W20: =V20+M20 -> 6.6493214e+08 | X20: 6.6493214e+08 | AB20: 44328809
C21: ACT/Fcst | D21: Net AMT | E21: =E18+E19+E20 -> 2.0677511e+09 | F21: =F18+F19+F20 -> 2.6505783e+09 | G21: =G18+G19+G20 -> 3.3390851e+09 | H21: =+E21+F21+G21 -> 8.0574145e+09 | I21: 3.3662293e+09 | J21: 3.7368023e+09 | K21: 4.7269959e+09 | L21: =+I21+J21+K21 -> 1.1830028e+10 | M21: =L21+H21 -> 1.9887442e+10 | N21: 5.0220284e+09 | O21: 6.1015418e+09 | P21: 5.8352005e+09 | Q21: =+N21+O21+P21 -> 1.6958771e+10 | R21: 6.024818e+09 | S21: 5.6275165e+09 | T21: 6.0475852e+09 | U21: =+R21+S21+T21 -> 1.769992e+10 | V21: =U21+Q21 -> 3.465869e+10 | W21: =V21+M21 -> 5.4546132e+10 | X21: 5.4546132e+10 | Y21: =X21-W21 -> 0 | Z21: 3.9187245e+09 | AA21: =Z21-J21 -> 1.8192214e+08 | AB21: 1.9887442e+10 | AC21: =AB21-M21 -> 0
D22: % vs RF | E22: =E21/E18 -> 1 | F22: =F21/F18 -> 1 | G22: =G21/G18 -> 1 | H22: =H21/H18 -> 1 | I22: =I21/I18 -> 1.0216395 | J22: =J21/J18 -> 1.0356495 | K22: =K21/K18 -> 1.1104922 | L22: =L21/L18 -> 1.0600603 | ... W22: =W21/W18 -> 1.0223707 | X22: 1.0223707 | Z22: 1.0860689 | AB22: 1.0348781
D23: % vs OB | E23: =E21/E17 -> 1.0887968 | F23: =F21/F17 -> 1.017435 | G23: =G21/G17 -> 1.1052703 | H23: =H21/H17 -> 1.0707057 | I23: =I21/I17 -> 1.0216395 | J23: =J21/J17 -> 1.0356495 | K23: =K21/K17 -> 0.98710404 | L23: =L21/L17 -> 1.011818 | ... W23: =W21/W17 -> 1.0223707 | X23: 1.0223707 | Y23: =Y21/6 -> 0 | Z23: 1.0860689 | AA23: =J21/Z21 -> 0.95357619 | AB23: 1.0348781
D24: +/- vs OB | E24: =E21-E17 -> 1.6863547e+08 | F24: =F21-F17 -> 45421021 | G24: =G21-G17 -> 3.1802757e+08 | H24: =H21-H17 -> 5.3208407e+08 | I24: =I21-I17 -> 71300599 | J24: =J21-J17 -> 1.286295e+08 | K24: =K21-K17 -> -61755530 | L24: =L21-L17 -> 1.3817457e+08 | ... W24: =W21-W17 -> 1.1935349e+09 | X24: 1.0829775e+09 | Z24: 3.1055164e+08 | AB24: 6.7025864e+08
D25: vs PY | E25: =E21/E3 -> 1.2566837 | F25: =F21/F3 -> 1.0737111 | G25: =G21/G3 -> 1.1927951 | H25: =H21/H3 -> 1.1654786 | I25: =I21/I3 -> 1.1890554 | J25: =J21/J3 -> 1.2904029 | K25: =K21/K3 -> 1.0871818 | L25: =L21/L3 -> 1.174221 | ... W25: =W21/W3 -> 1.1224871 | X25: 1.120212 | Z25: 1.3532247 | AB25: 1.1706632
C26: ASP | D26: OB | E26: =E17/E6 -> 118023.47 | F26: =F17/F6 -> 115104.37 | G26: =G17/G6 -> 114742.59 | H26: =H17/H6 -> 115679.99 | I26: =I17/I6 -> 112917.37 | J26: =J17/J6 -> 113822.49 | K26: =K17/K6 -> 115919.52 | L26: =L17/L6 -> 114411.77 | ... W26: =W17/W6 -> 116236.85 | X26: 116236.85 | Z26: 113822.49 | AB26: 114905.07
D27: ACT/FCST | E27: =E21/E10 -> 113581.5 | F27: =F21/F10 -> 104658.38 | G27: =G21/G10 -> 109141.83 | H27: =H21/H10 -> 108700.36 | I27: =I21/I10 -> 106593.71 | J27: =J21/J10 -> 105395.64 | K27: =K21/K10 -> 112229.54 | L27: =L21/L10 -> 108379.24 | ... W27: =W21/W10 -> 110882.26 | X27: 110837.74 | Z27: 113074.92 | AB27: 108509.12
C29: 1. May sales review
C30: - Qty : 111.8% vs 26OB | E30: ▶ Fully utilized early bird promotion, we have achieved Qty target
C31: - Amt :103.6% vs 26OB | E31: ▶ Although sales vol increased, the amount gap was caused by the application of old price.
C33: 2. Jun sales plan
C34: - Qty : 102% vs 26OB | E34: ▶ Plan to achieve 109% of volume to meet revenue target.
E35: ▶ Increase sales volume with early bird promotion(LVR, EP300, H/L)
C36: - Amt : 98.7% vs 26OB | E36: ▶ The price increase settles down in the market to secure the target ASP.
E37: ▶ Focus on selling high ASP products with various promotions(Potenza sport AS, Turanza EV, KOE)

Sheet Summary
C1: PCR - 2026 JUL PRODUCTION ORDER SHEET Summary
E2: ='PCR Order Sheet final'!T4 -> 4 | F2: ='PCR Order Sheet final'!U4 -> 931 | G2: ='PCR Order Sheet final'!V4 -> 6500 | H2: ='PCR Order Sheet final'!W4 -> 4387 | I2: ='PCR Order Sheet final'!X4 -> 3044 | J2: ='PCR Order Sheet final'!Y4 -> 15404 | K2: ='PCR Order Sheet final'!Z4 -> 9588 | L2: ='PCR Order Sheet final'!AA4 -> 8860 | M2: ='PCR Order Sheet final'!CO4 -> 32593 | N2: ='PCR Order Sheet final'!AC4 -> 13053 | O2: ='PCR Order Sheet final'!CB4 -> 28400 | P2: ='PCR Order Sheet final'!AO4 -> 29642 | Q2: ='PCR Order Sheet final'!CP4 -> 1846 | R2: ='PCR Order Sheet final'!BG4 -> 16430 | S2: ='PCR Order Sheet final'!BH4 -> 13532 | T2: ='PCR Order Sheet final'!BI4 -> 292
B3: No. | C3: Pttn | D3: Origin | E3: Sales | F3: Stock1 | G3: Ship01 | H3: Sales1 | I3: Stock2 | J3: Ship11 | K3: Sales2 | L3: Stock3 | M3: Ship12 | N3: Sales3 | O3: Stock4 | P3: ProdOrder | Q3: Ship13 | R3: Sales4 | S3: Sales5 | T3: Sales6 | W3: Mth | Y3: Pattern | Z3: Y24 OB | AA3: Portion
E4: 46170 | F4: 46170 | G4: =EDATE(F4,1) -> 46201 | H4: =EDATE(F4,1) -> 46201 | I4: =EDATE(F4,1) -> 46201 | J4: =EDATE(I4,1) -> 46231 | K4: =EDATE(I4,1) -> 46231 | L4: =EDATE(H4,1) -> 46231 | M4: =EDATE(K4,1) -> 46262 | N4: =EDATE(L4,1) -> 46262 | O4: =EDATE(K4,1) -> 46262 | P4: =EDATE(H4,1) -> 46231 | Q4: =EDATE(O4,1) -> 46293 | R4: =EDATE(O4,1) -> 46293 | S4: =EDATE(R4,1) -> 46323 | T4: =EDATE(S4,1) -> 46354 | W4: As of E/May | Y4: OE | Z4: 73962 | AA4: 0.19
B5: 1 | C5: RFT | D5: BSJ,BSEU,BATO | E5: 769 | F5: 2088 | G5: 123 | H5: 482 | I5: 1729 | J5: 465 | K5: 619 | L5: 1575 | M5: 925 | N5: 727 | O5: 1773 | P5: 392 | Q5: 769 | R5: 859 | S5: 660 | T5: 792 | W5: =IF(O5=0,0,IF(O5<=R5,O5/R5,IF(O5<R5+S5,1+(O5-R5)/S5,IF(O5<R5+S5+T5,2+(O5-R5-S5)/T5,IF(O5<R5+S5+T5+T5,3+((O5-R5-S5-T5)/(T5)),4))))) -> 2.3207071 | Y5: DRGU+ | Z5: 18303 | AA5: 0.05
B6: 2 | C6: Drive Guard | D6: BSJ | E6: 1722 | F6: 1183 | G6: 1272 | H6: 1742 | I6: 713 | J6: 1867 | K6: 729 | L6: 1851 | M6: 2066 | N6: 839 | O6: 3078 | P6: 2066 | Q6: 1991 | R6: 1560 | S6: 1706 | T6: 2060 | W6: =IF(O6=0,0,IF(O6<=R6,O6/R6,IF(O6<R6+S6,1+(O6-R6)/S6,IF(O6<R6+S6+T6,2+(O6-R6-S6)/T6,IF(O6<R6+S6+T6+T6,3+((O6-R6-S6-T6)/(T6)),4))))) -> 1.8898007 | Y6: T005A | Z6: 1508 | AA6: 0
B7: 3 | C7: OE-After | D7: BSJ, BSEU, BATO | E7: 2888 | F7: 10291 | G7: 5546 | H7: 4651 | I7: 11186 | J7: 5481 | K7: 4550 | L7: 12117 | M7: 5458 | N7: 5291 | O7: 12284 | P7: 4800 | Q7: 4362 | R7: 5828 | S7: 5221 | T7: 6056 | W7: =IF(O7=0,0,IF(O7<=R7,O7/R7,IF(O7<R7+S7,1+(O7-R7)/S7,IF(O7<R7+S7+T7,2+(O7-R7-S7)/T7,IF(O7<R7+S7+T7+T7,3+((O7-R7-S7-T7)/(T7)),4))))) -> 2.20393 | Y7: D400 | Z7: 16386 | AA7: 0.04
B8: 4 | C8: KOE | D8: BSFC, BTMV | E8: 44 | F8: 3250 | G8: 256 | H8: 400 | I8: 3106 | J8: 0 | K8: 300 | L8: 2806 | M8: 298 | N8: 300 | O8: 2804 | P8: 0 | Q8: 0 | R8: 440 | S8: 652 | T8: 1434 | W8: =IF(O8=0,0,IF(O8<=R8,O8/R8,IF(O8<R8+S8,1+(O8-R8)/S8,IF(O8<R8+S8+T8,2+(O8-R8-S8)/T8,IF(O8<R8+S8+T8+T8,3+((O8-R8-S8-T8)/(T8)),4))))) -> 3.1938633
B9: 5 | C9: Potenza sport AS | D9: BATO | E9: 144 | F9: 5745 | G9: 32 | H9: 1268 | I9: 4509 | J9: 1100 | K9: 1256 | L9: 4353 | M9: 0 | N9: 1222 | O9: 3131 | P9: 0 | Q9: 235 | R9: 1076 | S9: 875 | T9: 1057 | W9: =IF(O9=0,0,IF(O9<=R9,O9/R9,IF(O9<R9+S9,1+(O9-R9)/S9,IF(O9<R9+S9+T9,2+(O9-R9-S9)/T9,IF(O9<R9+S9+T9+T9,3+((O9-R9-S9-T9)/(T9)),4))))) -> 3.1163671 | Y9: EL64Z | Z9: 71148 | AA9: 0.19
B10: 6 | C10: Turanza EV | D10: BATO | E10: 48 | F10: 1238 | G10: 43 | H10: 359 | I10: 922 | J10: 1273 | K10: 466 | L10: 1729 | M10: 0 | N10: 537 | O10: 1192 | P10: 0 | Q10: 329 | R10: 459 | S10: 402 | T10: 416 | W10: =IF(O10=0,0,IF(O10<=R10,O10/R10,IF(O10<R10+S10,1+(O10-R10)/S10,IF(O10<R10+S10+T10,2+(O10-R10-S10)/T10,IF(O10<R10+S10+T10+T10,3+((O10-R10-S10-T10)/(T10)),4))))) -> 2.7956731 | Y10: EA04 | Z10: 39504 | AA10: 0.1
B11: 7 | C11: H/L | D11: BSJ | E11: 3400 | F11: 5687 | G11: 2633 | H11: 3154 | I11: 5166 | J11: 2875 | K11: 1220 | L11: 6821 | M11: 3498 | N11: 2110 | O11: 8209 | P11: 3288 | Q11: 4020 | R11: 2640 | S11: 4678 | T11: 5610 | W11: =IF(O11=0,0,IF(O11<=R11,O11/R11,IF(O11<R11+S11,1+(O11-R11)/S11,IF(O11<R11+S11+T11,2+(O11-R11-S11)/T11,IF(O11<R11+S11+T11+T11,3+((O11-R11-S11-T11)/(T11)),4))))) -> 2.1588235
B12: 8 | C12: Serenity Plus | D12: BTMV,TBSC,BSIN | E12: 3350 | F12: 8345 | H12: 5506 | I12: 15637 | J12: 2546 | K12: 5086 | L12: 13097 | M12: 9548 | N12: 4865 | O12: 17780 | P12: 1907 | Q12: 1907 | R12: 4822 | S12: 7360 | T12: 7316 | W12: =IF(O12=0,0,IF(O12<=R12,O12/R12,IF(O12<R12+S12,1+(O12-R12)/S12,IF(O12<R12+S12+T12,2+(O12-R12-S12)/T12,IF(O12<R12+S12+T12+T12,3+((O12-R12-S12-T12)/(T12)),4))))) -> 2.7651722 | X12: 4
B13: 9 | C13: RE005 | D13: TBSC | E13: 5134 | F13: 2550 | G13: 5120 | H13: 3898 | I13: 3772 | J13: 6362 | K13: 6029 | L13: 4105 | M13: 3523 | N13: 6373 | O13: 1255 | P13: 15479 | Q13: 15479 | R13: 5938 | S13: 5647 | T13: 5878 | W13: =IF(O13=0,0,IF(O13<=R13,O13/R13,IF(O13<R13+S13,1+(O13-R13)/S13,IF(O13<R13+S13+T13,2+(O13-R13-S13)/T13,IF(O13<R13+S13+T13+T13,3+((O13-R13-S13-T13)/(T13)),4))))) -> 0.21135062 | X13: 3 | Y13: EP300 | Z13: 28155 | AA13: 0.07
B14: 10 | C14: HL 001 | D14: TBSC,BSFC,BSJ | E14: 628 | F14: 2602 | G14: 159 | H14: 955 | I14: 1806 | J14: 402 | K14: 824 | L14: 1384 | M14: 941 | N14: 949 | O14: 1376 | P14: 1379 | Q14: 1379 | R14: 928 | S14: 1007 | T14: 883 | W14: =IF(O14=0,0,IF(O14<=R14,O14/R14,IF(O14<R14+S14,1+(O14-R14)/S14,IF(O14<R14+S14+T14,2+(O14-R14-S14)/T14,IF(O14<R14+S14+T14+T14,3+((O14-R14-S14-T14)/(T14)),4))))) -> 1.4448858 | Y14: HL001 | Z14: 6412 | AA14: 0.02
B15: 11 | C15: EP300 | D15: TBSC | E15: 1535 | F15: 4585 | G15: 800 | H15: 2045 | I15: 3340 | J15: 1128 | K15: 1367 | L15: 3101 | M15: 1645 | N15: 1329 | O15: 3417 | P15: 1134 | Q15: 1134 | R15: 1443 | S15: 1301 | T15: 1494 | W15: =IF(O15=0,0,IF(O15<=R15,O15/R15,IF(O15<R15+S15,1+(O15-R15)/S15,IF(O15<R15+S15+T15,2+(O15-R15-S15)/T15,IF(O15<R15+S15+T15+T15,3+((O15-R15-S15-T15)/(T15)),4))))) -> 2.4504685 | X15: Order confirmation | Y15: LE3 | Z15: 38000 | AA15: 0.1
B16: 12 | C16: LE3 | D16: BSJ | E16: 10213 | F16: 7799 | G16: 16033 | H16: 9138 | I16: 14694 | J16: 10715 | K16: 8901 | L16: 16508 | M16: 12984 | N16: 10964 | O16: 18528 | P16: 12984 | Q16: 11667 | R16: 9538 | S16: 9586 | T16: 12119 | U16: 6743 | V16: 7000 | W16: =IF(O16=0,0,IF(O16<=R16,O16/R16,IF(O16<R16+S16,1+(O16-R16)/S16,IF(O16<R16+S16+T16,2+(O16-R16-S16)/T16,IF(O16<R16+S16+T16+T16,3+((O16-R16-S16-T16)/(T16)),4))))) -> 1.937826 | X16: 2
B17: 13 | C17: FS A/S | D17: BSJ, BTMV | E17: 1578 | F17: 3106 | G17: 2619 | H17: 1940 | I17: 3785 | J17: 2132 | K17: 1550 | L17: 4367 | M17: 1733 | N17: 1518 | O17: 4582 | P17: 1997 | Q17: 1935 | R17: 2271 | S17: 2126 | T17: 2231 | W17: =IF(O17=0,0,IF(O17<=R17,O17/R17,IF(O17<R17+S17,1+(O17-R17)/S17,IF(O17<R17+S17+T17,2+(O17-R17-S17)/T17,IF(O17<R17+S17+T17+T17,3+((O17-R17-S17-T17)/(T17)),4))))) -> 2.0829225 | Y17: Weathergrip | Z17: 10263 | AA17: 0.03
B18: 15 | C18: R624/710 | D18: TBSC,BSIN,BSJ | E18: 3317 | F18: 6849 | G18: 364 | H18: 1433 | I18: 5780 | J18: 183 | K18: 2046 | L18: 3917 | M18: 4363 | N18: 3114 | O18: 5166 | P18: 3044 | Q18: 3044 | R18: 2747 | S18: 2943 | T18: 2859 | W18: =IF(O18=0,0,IF(O18<=R18,O18/R18,IF(O18<R18+S18,1+(O18-R18)/S18,IF(O18<R18+S18+T18,2+(O18-R18-S18)/T18,IF(O18<R18+S18+T18+T18,3+((O18-R18-S18-T18)/(T18)),4))))) -> 1.8219504 | Y18: Nextry | Z18: 0 | AA18: 0
B19: 14 | C19: Weather grip | D19: BSJ | E19: 534 | F19: 1141 | G19: 968 | H19: 594 | I19: 1515 | J19: 405 | K19: 563 | L19: 1357 | M19: 405 | N19: 574 | O19: 1188 | P19: 405 | Q19: 481 | R19: 457 | S19: 605 | T19: 645 | W19: =IF(O19=0,0,IF(O19<=R19,O19/R19,IF(O19<R19+S19,1+(O19-R19)/S19,IF(O19<R19+S19+T19,2+(O19-R19-S19)/T19,IF(O19<R19+S19+T19+T19,3+((O19-R19-S19-T19)/(T19)),4))))) -> 2.1953488 | Y19: Winter | Z19: 47000 | AA19: 0.12
B20: 16 | C20: Winter | D20: BSJ, BSEU | E20: 4 | F20: 931 | G20: 6500 | H20: 4387 | I20: 3044 | J20: 15404 | K20: 9588 | L20: 8860 | M20: 22445 | N20: 13053 | O20: 18252 | P20: 19494 | Q20: 908 | R20: 11012 | S20: 8148 | T20: 0 | W20: =IF(O20=0,0,IF(O20<=R20,O20/R20,IF(O20<R20+S20,1+(O20-R20)/S20,IF(O20<R20+S20+T20,2+(O20-R20-S20)/T20,IF(O20<R20+S20+T20+T20,3+((O20-R20-S20-T20)/(T20)),4))))) -> 1.8885616 | X20: 1 | Y20: Total | Z20: 379912
B21: 17 | C21: T005A, Alenza 001 RE71RS, S007 | D21: TBSC,BSIN,BSJ | E21: 80 | F21: 631 | G21: 0 | H21: 62 | I21: 569 | J21: 0 | K21: 70 | L21: 499 | M21: 2 | N21: 103 | O21: 398 | P21: 2 | Q21: 60 | R21: 209 | S21: 196 | T21: 60 | W21: =IF(O21=0,0,IF(O21<=R21,O21/R21,IF(O21<R21+S21,1+(O21-R21)/S21,IF(O21<R21+S21+T21,2+(O21-R21-S21)/T21,IF(O21<R21+S21+T21+T21,3+((O21-R21-S21-T21)/(T21)),4))))) -> 1.9642857
B22: Total | E22: =SUM(E5:E21) -> 35388 | F22: =SUM(F5:F21) -> 68021 | G22: =SUM(G5:G21) -> 42468 | H22: =SUM(H5:H21) -> 42014 | I22: =SUM(I5:I21) -> 81273 | J22: =SUM(J5:J21) -> 52338 | K22: =SUM(K5:K21) -> 45164 | L22: =SUM(L5:L21) -> 88447 | ... T22: =SUM(T5:T21) -> 50910 | W22: =IF(O22=0,0,IF(O22<=R22,O22/R22,IF(O22<R22+S22,1+(O22-R22)/S22,IF(O22<R22+S22+T22,2+(O22-R22-S22)/T22,IF(O22<R22+S22+T22+T22,3+((O22-R22-S22-T22)/(T22)),4))))) -> 1.9825466
C23: Summary
X27: 58295
X28: =P22 -> 68371
X29: =X28/X27 -> 1.172845
L83: s
C87: 23OB(Y230601)
C216: 23OB(Y231201)

Sheet PSR(G)_Optional_
A2: Ⅱ：個別層別 | D2: 製品在庫管理を行う上で適切な切り口をベースに、在庫見込みをご連絡願います。
D3: 切り口例毎の在庫管理フォーマット（Sample）を下記致しますので、貴方管理の
D4: 切り口に合わせて調整頂き、送付用フォーマットとして設定の上、返信願います。
D5: ※ 切り口例：OE／REP／EXP別、夏／冬別、卸／小売別、メインサイズ／レアサイズ別
D6: ※ 管理フォーマット（Sample）の切り口は必要に応じて変更頂いて構いません。
HU8: h | HV8: h | HW8: h | HX8: h | HY8: h | HZ8: h | IA8: h | IB8: i | IF8: u | IH8: u
IJ9: sales | IM9: in | IR9: IN | IS9: ='[11]PCR Order Sheet final'!V4/1000 -> 0 | IT9: ='[11]PCR Order Sheet final'!Z4/1000 -> 0 | IU9: ='[11]PCR Order Sheet final'!CM4/1000 -> 0
GJ10: 2018 | GV10: 2019 | HH10: 2020 | IJ10: incom | IM10: out | IX10: IN
P11: 単位：千本 | IX11: OUT
A12: Stock Month Forecast | HT12: Y2021 | IF12: Y2022 | IR12: Y2023 | JD12: Y2024
C13: Target month | E13: Target Month | F13: 40148 | H13: 40179 | J13: 40210 | L13: 40238 | N13: 40269 | P13: 40299 | R13: 40330 | T13: 40360 | V13: 40391 | X13: 40422 | Z13: 40452 | AB13: 40483 | AD13: 40513 | AF13: 11 - Jan | AH13: Feb | AJ13: Mar | AL13: Apr | AN13: May | AP13: Jun | AR13: Jul | AT13: Aug | AV13: Sep | AX13: Oct | AZ13: Nov | BB13: Dec | BD13: 40909 | BF13: Feb-12 | BH13: Mar-12 | BJ13: Apr | BL13: May | BN13: Jun | BP13: Jul | BR13: Aug | BT13: Sep | BV13: Oct | BX13: Nov | BZ13: Dec | CB13: Jan | CD13: FEB | CF13: MAR | CH13: Apr | CJ13: MAY | CL13: June | CN13: July | CP13: Aug | CR13: SEP | CT13: OCT | CV13: Nov | CX13: DEC | CZ13: JAN | DB13: FEB | DD13: Mar | DF13: Apr | DH13: May | DJ13: June | DL13: July | DN13: Aug | DP13: Sep | DR13: Oct | DT13: Nov | DV13: Dec | DX13: Jan | DZ13: Feb | EB13: Mar | ED13: Apr | EF13: May | EH13: Jun | EJ13: Jul | EL13: Aug | EN13: Sep | EP13: Oct | ER13: Nov | ET13: Dec | EV13: Jan | EX13: Feb | EZ13: Mar | FB13: Apr | FD13: May | FF13: Jun | FH13: Jul | FJ13: Aug | FL13: Sep | FN13: Oct | FP13: Nov | FR13: Dec | FT13: Jan | FV13: Feb | FX13: Mar | FZ13: Apr | GB13: May | GC13: Jun | GD13: Jul | GE13: Aug | GF13: Sep | GG13: Oct | GH13: Nov | GI13: Dec | GJ13: Jan | GK13: Feb | GL13: Mar | GM13: Apr | GN13: May | GO13: Jun | GP13: Jul | GQ13: Aug | GR13: Sep | GS13: Oct | GT13: Nov | GU13: Dec | GV13: Jan | GW13: Feb | GX13: Mar | GY13: Apr | GZ13: May | HA13: Jun | HB13: Jul | HC13: Aug | HD13: Sep | HE13: Oct | HF13: Nov | HG13: Dec | HH13: Jan | HI13: Feb | HJ13: Mar | HK13: Apr | HL13: May | HM13: Jun | HN13: Jul | HO13: Aug | HP13: Sep | HQ13: Oct | HR13: Nov | HS13: Dec | HT13: Jan | HU13: Feb | HV13: Mar | HW13: Apr | HX13: May | HY13: Jun | HZ13: Jul | IA13: Aug | IB13: Sep | IC13: Oct | ID13: Nov | IE13: Dec | IF13: Jan | IG13: Feb | IH13: Mar | II13: Apr | IJ13: May | IK13: Jun | IL13: Jul | IM13: Aug | IN13: Sep | IO13: Oct | IP13: Nov | IQ13: Dec | IR13: Jan | IS13: Feb | IT13: Mar | IU13: Apr | IV13: May | IW13: Jun | IX13: Jul | IY13: Aug | IZ13: Sep | JA13: Oct | JB13: Nov | JC13: Dec | JD13: Jan | JE13: Feb | JF13: Mar | JG13: Apr | JH13: May | JI13: Jun | JJ13: Jul | JK13: Aug | JL13: Sep | JM13: Oct | JN13: Nov | JO13: Dec
F14: RB | G14: FCST | H14: BGT | I14: FCST | J14: BGT | K14: FCST | L14: BGT | M14: FCST | N14: BGT | O14: FCST | P14: BGT | Q14: FCST | R14: BGT | S14: FCST | T14: BGT | U14: FCST | V14: BGT | W14: FCST | X14: BGT | Y14: FCST | Z14: BGT | AA14: FCST | AB14: BGT | AC14: FCST | AD14: BGT | AE14: FCST | AF14: OB | AG14: FCST | AH14: OB | AI14: FCST | AJ14: OB | AK14: FCST | AL14: OB | AM14: FCST | AN14: OB | AO14: FCST | AP14: OB | AQ14: FCST | AR14: OB | AS14: FCST | AT14: OB | AU14: FCST | AV14: OB | AW14: FCST | AX14: OB | AY14: FCST | AZ14: OB | BA14: FCST | BB14: OB | BC14: FCST | BD14: OB | BE14: FCST | BF14: OB | BG14: FCST | BH14: OB | BI14: FCST | BJ14: OB | BK14: FCST | BL14: RB | BM14: Act | BN14: RB | BO14: Act | BP14: RB | BQ14: Act | BR14: RB | BS14: Act | BT14: RB | BU14: Act | BV14: RB | BW14: Act | BX14: RB | BY14: ACT | BZ14: RB | CA14: ACT | CB14: RB | CC14: ACT | CD14: RB | CE14: ACT | CF14: RB | CG14: ACT | CH14: RB | CI14: ACT | CJ14: RB | CK14: ACT | CL14: RB | CM14: ACT | CN14: RB | CO14: ACT | CP14: RB | CQ14: ACT | CR14: RB | CS14: ACT | CT14: RB | CU14: ACT | CV14: RB | CW14: ACT | CX14: RB | CY14: ACT | CZ14: OB | DA14: ACT | DB14: OB | DC14: ACT | DD14: OB | DE14: ACT | DF14: OB | DG14: ACT | DH14: OB | DI14: ACT | DJ14: OB | DK14: ACT | DL14: RB | DM14: Act | DN14: RB | DO14: Act | DP14: RB | DQ14: Act | DR14: RB | DS14: Act | DT14: RB | DU14: Act | DV14: RB | DW14: Act | DX14: OB | DY14: Act | DZ14: OB | EA14: Act | EB14: OB | EC14: Act | ED14: OB | EE14: Act | EF14: OB | EG14: Act | EH14: OB | EI14: Act | EJ14: RB | EK14: Act | EL14: RB | EM14: Act | EN14: RB | EO14: Act | EP14: RB | EQ14: Act | ER14: RB | ES14: Act | ET14: RB | EU14: Act | EV14: OB | EW14: FCST | EX14: OB | EY14: FCST | EZ14: OB | FA14: FCST | FB14: OB | FC14: FCST | FD14: OB | FE14: FCST | FF14: OB | FG14: FCST | FH14: RB | FI14: Act | FJ14: RB | FK14: Act | FL14: RB | FM14: Act | FN14: RB | FO14: Act | FP14: RB | FQ14: Act | FR14: RB | FS14: Act | FT14: OB | FU14: Act | FV14: OB | FW14: Act | FX14: OB | FY14: FCST | FZ14: OB | GA14: Act | GB14: Act | GC14: Act | GD14: Act | GE14: Act | GF14: FCST | GG14: FCST | GH14: FCST | GI14: FCST | GJ14: FCST | GK14: FCST | GL14: FCST | GM14: ACT | GN14: ACT | GO14: ACT | GP14: ACT | GQ14: ACT | GR14: ACT | GS14: ACT | GT14: ACT | GU14: ACT | GV14: ACT | GW14: ACT | GX14: ACT | GY14: ACT | GZ14: ACT | HA14: ACT | HB14: ACT | HC14: ACT | HD14: ACT | HE14: ACT | HF14: ACT | HG14: ACT | HH14: ACT | HI14: ACT | HJ14: Act | HK14: Act | HL14: Act | HM14: Act | HN14: Act | HO14: Act | HP14: Act | HQ14: Act | HR14: Act | HS14: Act | HT14: Act | HU14: Act | HV14: Act | HW14: Act | HX14: Act | HY14: Act | HZ14: Act | IA14: Act | IB14: Act | IC14: Act | ID14: Act | IE14: Act | IF14: Act | IG14: Act | IH14: Act | II14: Act | IJ14: Act | IK14: Act | IL14: Act | IM14: Act | IN14: Act | IO14: Act | IP14: Act | IQ14: Act | IR14: Act | IS14: Act | IT14: Act | IU14: Act | IV14: Act | IW14: Act | IX14: Act | IY14: FCST | IZ14: FCST | JA14: Act | JB14: FCST | JC14: FCST | JD14: Act | JE14: Act | JF14: Act | JG14: Act | JH14: Act | JI14: Act | JJ14: Act | JK14: FCST | JL14: FCST | JM14: FCST | JN14: FCST | JO14: FCST
B15: RFT | C15: 3 | D15: In | F15: 0.2 | G15: 0.104 | H15: 0.192 | I15: 0.03 | J15: =H16 -> 0.133 | K15: 0.192 | L15: 0.25 | M15: 0.778 | N15: 0.35 | O15: 0.77 | P15: 0.25 | Q15: 0.272 | R15: 0.18 | S15: 0.863 | T15: 0.3 | U15: 0.148 | V15: 0.35 | W15: 0.093 | X15: 0.4 | Y15: 0.722 | Z15: =X16 -> 0.3 | AA15: 0.484 | AB15: 0.18 | AC15: 0.256 | AD15: 0.15 | AE15: 0.187 | AF15: 0.282 | AG15: 0.071 | AH15: 0.265 | AI15: 0.459 | AJ15: 0.385 | AK15: 0.472 | AL15: 0.484 | AM15: 0.859 | AN15: 0.564 | AO15: 0.397 | AP15: 0.63 | AQ15: 0.259 | AR15: 0.449 | AS15: 1.157 | AT15: 0.329 | AU15: 0.525 | AV15: 0.519 | AW15: 1.144 | AX15: 0.649 | AY15: 1.212 | AZ15: 0.773 | BA15: 0.124 | BB15: 0.672 | BC15: 0.008 | BD15: 0.268 | BE15: 0.04 | BF15: 0.336 | BG15: 0.663 | BH15: 0.438 | BI15: 0.657 | BJ15: 0.554 | BK15: 1.113 | BL15: 0.64 | BM15: 0.508 | BN15: 0.664 | BO15: 1.153 | BP15: 0.592 | BQ15: 0.278 | BR15: 0.876 | BS15: 0.665 | BT15: 0.95 | BU15: 0.744 | BV15: 1.021 | BW15: 0.768 | BX15: 0.9944 | BY15: 1.076 | BZ15: 1.0143 | CA15: 0.823 | CB15: 0.606 | CC15: 0.595 | CD15: =+CD16 -> 0.532 | CE15: 0.555 | CF15: 0.807 | CG15: 1.189 | CH15: 0.734 | CI15: 0.722 | CJ15: 0.879 | CK15: 0.507 | CL15: 0.985 | CM15: 0.73 | CN15: 0.845 | CO15: 1.471 | CP15: 0.987 | CQ15: 0.237 | CR15: 1.09 | CS15: 0.922 | CT15: 1.095 | CU15: 0.621 | CV15: 1.362 | CW15: 0.245 | CX15: 1.305 | CY15: 1.116 | CZ15: 0.693 | DA15: 0.44 | DB15: 0.686 | DC15: 0.102 | DD15: 0.952 | DE15: 0.837 | DF15: 1.035 | DG15: =[12]PCR!$J$218 -> 0.098 | DH15: 1.037 | DI15: =[13]PCR!$J$227 -> 1.238 | DJ15: 1.25 | DK15: 1.131 | DL15: 0.894 | DM15: 1.59 | DN15: 1.048 | DO15: 1.328 | DP15: 1.177 | DQ15: 0.722 | DR15: 1.283 | DS15: 1.662 | DT15: 1.505 | DU15: =[14]PCR!$J$284 -> 1.042 | DV15: 1.44 | DW15: =[15]PCR!$J$279 -> 3.088 | DX15: 0.676 | DY15: =[16]PCR!$J$247 -> 0 | DZ15: 0.694 | EA15: =[17]PCR!$J$239 -> 3.103 | EB15: 1.004 | EC15: =[18]PCR!$J$241 -> 1.281 | ED15: 1.049 | EE15: =[19]PCR!$J$241 -> 0.412 | EF15: 1.193 | EG15: =[20]PCR!$J$245 -> 1.814 | EH15: 1.408 | EI15: =[21]PCR!$J$261 -> 0.452 | EJ15: 1.05 | EK15: =[22]PCR!$J$269 -> 0.778 | EL15: 1.23 | EM15: =[23]PCR!$J$292 -> 1.561 | EN15: 1.439 | EO15: =[24]PCR!$J$313 -> 1.657 | EP15: 1.766 | EQ15: =[25]PCR!$J$318 -> 0.398 | ER15: 1.891 | ES15: =[26]PCR!$J$285 -> 0.906 | ET15: 1.9 | EU15: =[27]PCR!$J$269 -> 0.646 | EV15: 0.738 | EW15: =[28]PCR!$J$242 -> 0.778 | EX15: 0.903 | EY15: =[29]PCR!$J$247 -> #REF! | EZ15: 1.025 | FA15: =[30]PCR!$J$251 -> 2.446 | FB15: 1.759 | FC15: 5.463 | FD15: 2.587 | FE15: =[31]PCR!$J$242 -> 2.299 | FF15: 2.763 | FG15: =[32]PCR!$J$249 -> 3.113 | FH15: 2.1245953 | FI15: =[33]PCR!$J$260 -> 2.108 | FJ15: 2.144657 | FK15: =[34]PCR!$J$257 -> 1.976 | FL15: 2.0376141 | FM15: =[35]PCR!$J$270 -> 3.056 | FN15: 2.1261572 | FO15: =[36]PCR!$J$263 -> 1.847 | FP15: 2.681 | FQ15: =[37]PCR!$J$262 -> 2.863 | FR15: 2.717 | FS15: =[38]PCR!$J$247 -> 1.091 | FT15: 2.486 | FU15: =[39]PCR!$J$241 -> 3.039 | FV15: 2.764 | FW15: =[40]PCR!$J$235 -> 1.64 | FX15: 2.104 | FY15: =[41]PCR!$J$224 -> 4.025 | FZ15: 4.678 | GA15: =[42]PCR!$J$232 -> 4.615 | GB15: 2.325 | GC15: 3.698 | GD15: 2.326 | GE15: 2.606 | GF15: 4.327 | GG15: 2.745 | GH15: 4.761 | GI15: 2.963 | GJ15: 3.127 | GK15: 5.651 | GL15: 3.356 | GM15: 3.974 | GN15: 2.811 | GO15: 2.207 | GP15: 5.899 | GQ15: 2.793 | GR15: 2.093 | GS15: 2.981 | GT15: 1.73 | GU15: 0.823 | GV15: 1.316 | GW15: 2.625 | GX15: 4.32 | GY15: 4.183 | GZ15: 2.174 | HA15: 1.53 | HB15: 5.038 | HC15: 1.93 | HD15: 4.4 | HE15: 4.16 | HF15: 5.292 | HG15: 1.891 | HH15: =[43]PCR!$I$503 -> 1.973 | HI15: =[44]PCR!$I$503 -> 2.04 | HJ15: 2.839 | HK15: =[45]PCR!$I$503 -> 1.138 | HL15: 0.992 | HM15: 1.443 | HN15: 2.378 | HO15: 0.246 | HP15: 2.067 | HQ15: 3.327 | HR15: 2.694 | HS15: 3.079 | HT15: 0.783 | HU15: 3.576 | HV15: 3.044 | HW15: 1.742 | HX15: 1.968 | HY15: =[46]Cate!I503 -> 7.255 | HZ15: 0.619 | IA15: =[47]Cate!I503 -> 3.73 | IB15: =[48]Cate!I503 -> 1.067 | IC15: 0.526 | ID15: =[49]PCR!$I$503 -> 4.169 | IE15: 3.999 | IF15: 3.401 | IG15: 0.539 | IH15: 0.599 | II15: 1.59 | IJ15: 1.558 | IK15: 0.096 | IL15: 2.058 | IM15: 3.206 | IN15: 1.377 | IO15: 3.458 | IP15: 2.485 | IQ15: 1.281 | IR15: 2.538 | IS15: 0.493 | IT15: 1.737 | IU15: 2.405 | IV15: 0.86 | IW15: 4.151 | IX15: 3.646 | IY15: 2.075 | IZ15: 3.505 | JA15: 2.826 | JB15: 1.572 | JC15: 1.296 | JD15: 1.866 | JE15: 0.741 | JF15: 2.882 | JG15: 2.328 | JH15: 2.274
D16: Out | F16: 0.193 | G16: 0.329 | H16: 0.133 | I16: 0.088 | J16: 0.133 | K16: 0.203 | L16: 0.195 | M16: 0.551 | N16: 0.287 | O16: 0.481 | P16: 0.212 | Q16: 0.312 | R16: 0.325 | S16: 0.586 | T16: 0.25 | U16: 0.324 | V16: 0.15 | W16: 0.156 | X16: 0.3 | Y16: 0.316 | Z16: 0.37 | AA16: 0.296 | AB16: 0.4 | AC16: 0.463 | AD16: 0.315 | AE16: 0.504 | AF16: 0.282 | AG16: 0.257 | AH16: 0.265 | AI16: 0.167 | AJ16: 0.385 | AK16: 0.423 | AL16: 0.484 | AM16: 0.605 | AN16: 0.564 | AO16: 0.432 | AP16: 0.63 | AQ16: 0.668 | AR16: 0.449 | AS16: 0.359 | AT16: 0.329 | AU16: 0.627 | AV16: 0.519 | AW16: 0.456 | AX16: 0.649 | AY16: 0.486 | AZ16: 0.773 | BA16: 0.598 | BB16: 0.672 | BC16: 0.726 | BD16: 0.268 | BE16: 0.261 | BF16: 0.336 | BG16: 0.844 | BH16: 0.438 | BI16: 0.353 | BJ16: 0.554 | BK16: 0.572 | BL16: 0.64 | BM16: 0.492 | BN16: 0.664 | BO16: 0.999 | BP16: 0.592 | BQ16: 0.547 | BR16: 0.876 | BS16: 1.112 | BT16: 0.95 | BU16: 0.525 | BV16: 1.021 | BW16: 1.013 | BX16: =+BX15 -> 0.9944 | BY16: 1.03 | BZ16: =+BZ15 -> 1.0143 | CA16: 0.802 | CB16: 0.606 | CC16: 0.537 | CD16: 0.532 | CE16: 0.394 | CF16: 0.807 | CG16: 0.802 | CH16: 0.734 | CI16: 0.786 | CJ16: 0.879 | CK16: 0.49 | CL16: 0.985 | CM16: 1.026 | CN16: =+CN15 -> 0.845 | CO16: 0.746 | CP16: 0.987 | CQ16: 0.669 | CR16: 1.09 | CS16: 1.114 | CT16: 1.095 | CU16: 0.452 | CV16: 1.362 | CW16: 1.005 | CX16: 1.305 | CY16: 1.015 | CZ16: 0.693 | DA16: 0.499 | DB16: 0.686 | DC16: 0.446 | DD16: 0.952 | DE16: 0.535 | DF16: 1.035 | DG16: =[12]PCR!$J$219 -> 0.527 | DH16: 1.037 | DI16: =[13]PCR!$J$228 -> 1.004 | DJ16: 1.25 | DK16: 1.019 | DL16: =DL15 -> 0.894 | DM16: 0.722 | DN16: =DN15 -> 1.048 | DO16: 1.207 | DP16: =DP15 -> 1.177 | DQ16: 0.848 | DR16: =DR15 -> 1.283 | DS16: 1.334 | DT16: =DT15 -> 1.505 | DU16: =[14]PCR!$J$285 -> 1.821 | DV16: =DV15 -> 1.44 | DW16: =[15]PCR!$J$280 -> 2.021 | DX16: =DX15 -> 0.676 | DY16: =[16]PCR!$J$248 -> 0.491 | DZ16: =DZ15 -> 0.694 | EA16: =[17]PCR!$J$240 -> 0.456 | EB16: =EB15 -> 1.004 | EC16: =[18]PCR!$J$242 -> 1.162 | ED16: =ED15 -> 1.049 | EE16: =[19]PCR!$J$242 -> 1.161 | EF16: =EF15 -> 1.193 | EG16: =[20]PCR!$J$246 -> 0.728 | EH16: =EH15 -> 1.408 | EI16: =[21]PCR!$J$262 -> 0.409 | EJ16: =EJ15 -> 1.05 | EK16: =[22]PCR!$J$270 -> 1.116 | EL16: =EL15 -> 1.23 | EM16: =[23]PCR!$J$293 -> 3.263 | EN16: =EN15 -> 1.439 | EO16: =[24]PCR!$J$314 -> 1.05 | EP16: =EP15 -> 1.766 | EQ16: =[25]PCR!$J$319 -> 1.287 | ER16: =ER15 -> 1.891 | ES16: =[26]PCR!$J$286 -> 0.726 | ET16: =ET15 -> 1.9 | EU16: =[27]PCR!$J$270 -> 1.364 | EV16: =EV15 -> 0.738 | EW16: =[28]PCR!$J$243 -> 0.552 | EX16: =EX15 -> 0.903 | EY16: =[29]PCR!$J$248 -> #REF! | EZ16: =EZ15 -> 1.025 | FA16: =[30]PCR!$J$252 -> 1.178 | FB16: =FB15 -> 1.759 | FC16: 1.878 | FD16: =FD15 -> 2.587 | FE16: =[31]PCR!$J$243 -> 3.772 | FF16: =FF15 -> 2.763 | FG16: =[32]PCR!$J$250 -> 1.944 | FH16: 2.1245953 | FI16: =[33]PCR!$J$261 -> 2.727 | FJ16: 2.144657 | FK16: =[34]PCR!$J$258 -> 2.145 | FL16: 2.0376141 | FM16: =[35]PCR!$J$271 -> 2.556 | FN16: 2.1261572 | FO16: =[36]PCR!$J$264 -> 2.487 | FP16: 2.681 | FQ16: =[37]PCR!$J$263 -> 3.85 | FR16: 2.717 | FS16: =[38]PCR!$J$248 -> 2.613 | FT16: 1.067 | FU16: =[39]PCR!$J$242 -> 2.762 | FV16: 1.683 | FW16: =[40]PCR!$J$236 -> 1.079 | FX16: 1.873 | FY16: =[41]PCR!$J$225 -> 2.166 | FZ16: 2.473 | GA16: =[42]PCR!$J$233 -> 3.036 | GB16: 3.614 | GC16: 2.449 | GD16: 3.762 | GE16: 2.563 | GF16: 2.944 | GG16: 3.891 | GH16: 3.934 | GI16: 4.808 | GJ16: 2.383 | GK16: 2.25 | GL16: 3.658 | GM16: 3.876 | GN16: 2.827 | GO16: 3.211 | GP16: 2.739 | GQ16: 2.635 | GR16: 2.068 | GS16: 2.037 | GT16: 2.67 | GU16: 2.919 | GV16: 1.796 | GW16: 2.694 | GX16: 2.492 | GY16: 3.202 | GZ16: 3.778 | HA16: 3.802 | HB16: 2.493 | HC16: 1.49 | HD16: 3.71 | HE16: 5.09 | HF16: 5.74 | HG16: 3.684 | HH16: =[43]PCR!$I$504 -> 1.568 | HI16: =[44]PCR!$I$504 -> 1.191 | HJ16: 1.565 | HK16: =[45]PCR!$J$503 -> 1.389 | HL16: 2.005 | HM16: 2.226 | HN16: 2.996 | HO16: 1.721 | HP16: 3.08 | HQ16: 3.454 | HR16: 3.531 | HS16: 2.255 | HT16: 1.798 | HU16: 1.118 | HV16: 3.531 | HW16: 1.748 | HX16: 1.982 | HY16: =[46]Cate!J503 -> 6.423 | HZ16: 1.308 | IA16: =[47]Cate!J503 -> 1.941 | IB16: =[48]Cate!J503 -> 1.255 | IC16: 2.775 | ID16: =[49]PCR!$J$503 -> 4.698 | IE16: 3.881 | IF16: 2.674 | IG16: 0.648 | IH16: 1.1 | II16: 1.72 | IJ16: 1.488 | IK16: 2.081 | IL16: 0.79 | IM16: 1.56 | IN16: 1.789 | IO16: 3.843 | IP16: 1.595 | IQ16: 2.185 | IR16: 2.763 | IS16: 1.754 | IT16: 2.255 | IU16: 1.834 | IV16: 0.907 | IW16: 2.927 | IX16: 2.43 | IY16: 3.191 | IZ16: 2.638 | JA16: 3.038 | JB16: 2.394 | JC16: 3.219 | JD16: 1.448 | JE16: 1.498 | JF16: 1.291 | JG16: 2.712 | JH16: 2.72
D17: Inventory | F17: 0.19 | G17: 0.4916 | H17: =F17+H15-H16 -> 0.249 | I17: =G17+I15-I16 -> 0.4336 | J17: =H17+J15-J16 -> 0.249 | K17: =I17+K15-K16 -> 0.4226 | L17: =J17+L15-L16 -> 0.304 | M17: =K17+M15-M16 -> 0.6496 | N17: =L17+N15-N16 -> 0.367 | O17: =M17+O15-O16 -> 0.9386 | ... AK17: =AI17+AK15-AK16 -> 1.1616 | AL17: =N17*1.137 -> 0.417279 | AM17: =AK17+AM15-AM16 -> 1.4156 | AN17: =P17*1.137 -> 0.460485 | AO17: =AM17+AO15-AO16 -> 1.3806 | AP17: =R17*1.137 -> 0.29562 | AQ17: 0.98 | AR17: =T17*1.137 -> 0.35247 | AS17: =AQ17+AS15-AS16 -> 1.778 | AT17: =V17*1.137 -> 0.57987 | AU17: =AS17+AU15-AU16 -> 1.676 | AV17: =X17*1.137 -> 0.69357 | AW17: =AU17+AW15-AW16 -> 2.364 | AX17: =Z17*1.137 -> 0.61398 | AY17: =AW17+AY15-AY16 -> 3.09 | AZ17: 0.36384 | BA17: 2.616 | BB17: 0.176235 | BC17: 1.898 | BD17: 0.176235 | BE17: 1.677 | BF17: =BD17+BF15-BF16 -> 0.176235 | BG17: =BE17+BG15-BG16 -> 1.496 | BH17: =AJ17*1.137 -> 0.176235 | BI17: =BG17+BI15-BI16 -> 1.8 | BJ17: =AL17*1.137 -> 0.47444622 | BK17: =BI17+BK15-BK16 -> 2.341 | BL17: =AN17*1.137 -> 0.52357145 | BM17: =BK17+BM15-BM16 -> 2.357 | BN17: 0.664 | BO17: =BM17+BO15-BO16 -> 2.511 | BP17: 0.664 | BQ17: =BO17+BQ15-BQ16 -> 2.242 | BR17: 0.664 | BS17: =BQ17+BS15-BS16 -> 1.795 | BT17: 0.664 | BU17: =BS17+BU15-BU16 -> 2.014 | BV17: 0.664 | BW17: =BU17+BW15-BW16 -> 1.769 | BX17: 0.664 | BY17: =BW17+BY15-BY16 -> 1.815 | BZ17: 0.664 | CA17: =BY17+CA15-CA16 -> 1.836 | CB17: 0.664 | CC17: =CA17+CC15-CC16 -> 1.894 | CD17: 0.664 | CE17: =CC17+CE15-CE16 -> 2.055 | CF17: 0.664 | CG17: =CE17+CG15-CG16 -> 2.442 | CH17: 0.664 | CI17: =CG17+CI15-CI16 -> 2.378 | CJ17: 0.664 | CK17: =CI17+CK15-CK16 -> 2.395 | CL17: 0.664 | CM17: =CK17+CM15-CM16 -> 2.099 | CN17: 0.664 | CO17: =CM17+CO15-CO16 -> 2.824 | CP17: 0.664 | CQ17: =CO17+CQ15-CQ16 -> 2.392 | CR17: 0.664 | CS17: =CQ17+CS15-CS16 -> 2.2 | CT17: 0.664 | CU17: =CS17+CU15-CU16 -> 2.369 | CV17: 0.664 | CW17: =CU17+CW15-CW16 -> 1.609 | CX17: 0.664 | CY17: 1.809 | CZ17: =CX17+CZ15-CZ16 -> 0.664 | DA17: =CY17+DA15-DA16 -> 1.75 | DB17: =CZ17+DB15-DB16 -> 0.664 | DC17: =DA17+DC15-DC16 -> 1.406 | DD17: =DB17+DD15-DD16 -> 0.664 | DE17: =DC17+DE15-DE16 -> 1.708 | DF17: =DD17+DF15-DF16 -> 0.664 | DG17: =DE17+DG15-DG16 -> 1.279 | DH17: 0.664 | DI17: =DG17+DI15-DI16 -> 1.513 | DJ17: 0.664 | DK17: =DI17+DK15-DK16 -> 1.625 | DL17: 0.664 | DM17: =DK17+DM15-DM16 -> 2.493 | DN17: 0.664 | DO17: =DM17+DO15-DO16 -> 2.614 | DP17: 0.664 | DQ17: =DO17+DQ15-DQ16 -> 2.488 | DR17: 0.664 | DS17: =DQ17+DS15-DS16 -> 2.816 | DT17: 0.664 | DU17: =DS17+DU15-DU16 -> 2.037 | DV17: 0.664 | DW17: =DU17+DW15-DW16 -> 3.104 | DX17: 0.664 | DY17: =DW17+DY15-DY16 -> 2.613 | DZ17: 0.664 | EA17: =DY17+EA15-EA16 -> 5.26 | EB17: 0.664 | EC17: =EA17+EC15-EC16 -> 5.379 | ED17: 0.664 | EE17: =EC17+EE15-EE16 -> 4.63 | EF17: 0.664 | EG17: =EE17+EG15-EG16 -> 5.716 | EH17: 0.664 | EI17: =EG17+EI15-EI16 -> 5.759 | EJ17: 0.664 | EK17: =EI17+EK15-EK16 -> 5.421 | EL17: 0.664 | EM17: =EK17+EM15-EM16 -> 3.719 | EN17: 0.664 | EO17: 4.162 | EP17: 0.664 | EQ17: =EO17+EQ15-EQ16 -> 3.273 | ER17: 0.664 | ES17: =EQ17+ES15-ES16 -> 3.453 | ET17: 0.664 | EU17: =ES17+EU15-EU16 -> 2.735 | EV17: 0.664 | EW17: =EU17+EW15-EW16 -> 2.961 | EX17: 0.664 | EY17: =EW17+EY15-EY16 -> #REF! | EZ17: 0.664 | FA17: =EY17+FA15-FA16 -> #REF! | FB17: 0.664 | FC17: =FA17+FC15-FC16 -> #REF! | FD17: 0.664 | FE17: 6.016 | FF17: 0.664 | FG17: =FE17+FG15-FG16 -> 7.185 | FH17: 0.664 | FI17: =FG17+FI15-FI16 -> 6.566 | FJ17: 0.664 | FK17: =FI17+FK15-FK16 -> 6.397 | FL17: 0.664 | FM17: =FK17+FM15-FM16 -> 6.897 | FN17: 0.664 | FO17: =FM17+FO15-FO16 -> 6.257 | FP17: 0.664 | FQ17: =FO17+FQ15-FQ16 -> 5.27 | FR17: 3.614 | FS17: =FQ17+FS15-FS16 -> 3.748 | FT17: =FR17+FT15-FT16 -> 5.033 | FU17: =FS17+FU15-FU16 -> 4.025 | FV17: =FT17+FV15-FV16 -> 6.114 | FW17: =FU17+FW15-FW16 -> 4.586 | FX17: =FV17+FX15-FX16 -> 6.345 | FY17: =FW17+FY15-FY16 -> 6.445 | FZ17: 8.957 | GA17: 8.252 | GB17: =GA17+GB15-GB16 -> 6.963 | GC17: =GB17+GC15-GC16 -> 8.212 | GD17: 6.791 | GE17: 6.847 | GF17: =GE17+GF15-GF16 -> 8.23 | GG17: =GF17+GG15-GG16 -> 7.084 | GH17: 7.956 | GI17: =GH17+GI15-GI16 -> 6.111 | GJ17: =GI17+GJ15-GJ16 -> 6.855 | GK17: 10.29 | GL17: =GK17+GL15-GL16 -> 9.988 | GM17: =GL17+GM15-GM16 -> 10.086 | GN17: =GM17+GN15-GN16 -> 10.07 | GO17: =GN17+GO15-GO16 -> 9.066 | GP17: =GO17+GP15-GP16 -> 12.226 | GQ17: =GP17+GQ15-GQ16 -> 12.384 | GR17: =GQ17+GR15-GR16 -> 12.409 | GS17: =GR17+GS15-GS16 -> 13.353 | ... HU17: =HT17+HU15-HU16 -> 7.883 | HV17: 7.359 | HW17: =HV17+HW15-HW16 -> 7.353 | HX17: =HW17+HX15-HX16 -> 7.339 | HY17: =HX17+HY15-HY16 -> 8.171 | HZ17: =HY17+HZ15-HZ16 -> 7.482 | IA17: =HZ17+IA15-IA16 -> 9.271 | IB17: =IA17+IB15-IB16 -> 9.083 | IC17: =IB17+IC15-IC16 -> 6.834 | ID17: =IC17+ID15-ID16 -> 6.305 | ... IL17: =IK17+IL15-IL16 -> 5.763 | IM17: 7.405 | IN17: =IM17+IN15-IN16 -> 6.993 | IO17: =IN17+IO15-IO16 -> 6.608 | IP17: =IO17+IP15-IP16 -> 7.498 | IQ17: =IP17+IQ15-IQ16 -> 6.594 | IR17: =IQ17+IR15-IR16 -> 6.369 | IS17: 5.168 | IT17: =IS17+IT15-IT16 -> 4.65 | IU17: =IT17+IU15-IU16 -> 5.221 | IV17: =IU17+IV15-IV16 -> 5.174 | IW17: =IV17+IW15-IW16 -> 6.398 | IX17: =IW17+IX15-IX16 -> 7.614 | IY17: =IX17+IY15-IY16 -> 6.498 | IZ17: =IY17+IZ15-IZ16 -> 7.365 | JA17: =IZ17+JA15-JA16 -> 7.153 | ... JO17: =JN17+JO15-JO16 -> 4.83
D18: month | E18: 1.9 | F18: 0.75949367 | G18: 3.3518182 | H18: =IF(H17<=J16,H17/J16,IF(H17<=J16+L16,1+(H17-J16)/L16,IF(H17<=J16+L16+N16,2+(H17-J16-L16)/N16,H17*3/(J16+L16+N16)))) -> 1.5948718 | I18: =IF(I17<=K16,I17/K16,IF(I17<=K16+M16,1+(I17-K16)/M16,IF(I17<=K16+M16+O16,2+(I17-K16-M16)/O16,I17*3/(K16+M16+O16)))) -> 1.4185118 | J18: =IF(J17<=L16,J17/L16,IF(J17<=L16+N16,1+(J17-L16)/N16,IF(J17<=L16+N16+P16,2+(J17-L16-N16)/P16,J17*3/(L16+N16+P16)))) -> 1.1881533 | K18: =IF(K17<=M16,K17/M16,IF(K17<=M16+O16,1+(K17-M16)/O16,IF(K17<=M16+O16+Q16,2+(K17-M16-O16)/Q16,K17*3/(M16+O16+Q16)))) -> 0.76696915 | L18: =IF(L17<=N16,L17/N16,IF(L17<=N16+P16,1+(L17-N16)/P16,IF(L17<=N16+P16+R16,2+(L17-N16-P16)/R16,L17*3/(N16+P16+R16)))) -> 1.0801887 | M18: =IF(M17<=O16,M17/O16,IF(M17<=O16+Q16,1+(M17-O16)/Q16,IF(M17<=O16+Q16+S16,2+(M17-O16-Q16)/S16,M17*3/(O16+Q16+S16)))) -> 1.5403846 | N18: =IF(N17<=P16,N17/P16,IF(N17<=P16+R16,1+(N17-P16)/R16,IF(N17<=P16+R16+T16,2+(N17-P16-R16)/T16,N17*3/(P16+R16+T16)))) -> 1.4769231 | O18: =IF(O17<=Q16,O17/Q16,IF(O17<=Q16+S16,1+(O17-Q16)/S16,IF(O17<=Q16+S16+U16,2+(O17-Q16-S16)/U16,O17*3/(Q16+S16+U16)))) -> 2.1253086 | ... AK18: =IF(AK17<=AM16,AK17/AM16,IF(AK17<=AM16+AO16,1+(AK17-AM16)/AO16,IF(AK17<=AM16+AO16+AQ16,2+(AK17-AM16-AO16)/AQ16,AK17*3/(AM16+AO16+AQ16)))) -> 2.1865269 | AL18: =N18*1.137 -> 1.6792615 | AM18: =IF(AM17<=AO16,AM17/AO16,IF(AM17<=AO16+AQ16,1+(AM17-AO16)/AQ16,IF(AM17<=AO16+AQ16+AS16,2+(AM17-AO16-AQ16)/AS16,AM17*3/(AO16+AQ16+AS16)))) -> 2.8791086 | AN18: =P18*1.137 -> 1.50084 | AO18: =IF(AO17<=AQ16,AO17/AQ16,IF(AO17<=AQ16+AS16,1+(AO17-AQ16)/AS16,IF(AO17<=AQ16+AS16+AU16,2+(AO17-AQ16-AS16)/AU16,AO17*3/(AQ16+AS16+AU16)))) -> 2.5639553 | AP18: =R18*1.137 -> 1.2128 | AQ18: =IF(AQ17<=AS16,AQ17/AS16,IF(AQ17<=AS16+AU16,1+(AQ17-AS16)/AU16,IF(AQ17<=AS16+AU16+AW16,2+(AQ17-AS16-AU16)/AW16,AQ17*3/(AS16+AU16+AW16)))) -> 1.9904306 | AR18: =T18*1.137 -> 1.7434 | AS18: =IF(AS17<=AU16,AS17/AU16,IF(AS17<=AU16+AW16,1+(AS17-AU16)/AW16,IF(AS17<=AU16+AW16+AY16,2+(AS17-AU16-AW16)/AY16,AS17*3/(AU16+AW16+AY16)))) -> 3.3996176 | AT18: =V18*1.137 -> 1.7823243 | AU18: =IF(AU17<=AW16,AU17/AW16,IF(AU17<=AW16+AY16,1+(AU17-AW16)/AY16,IF(AU17<=AW16+AY16+BA16,2+(AU17-AW16-AY16)/BA16,AU17*3/(AW16+AY16+BA16)))) -> 3.2649351 | AV18: =X18*1.137 -> 1.8192 | AW18: =IF(AW17<=AY16,AW17/AY16,IF(AW17<=AY16+BA16,1+(AW17-AY16)/BA16,IF(AW17<=AY16+BA16+BC16,2+(AW17-AY16-BA16)/BC16,AW17*3/(AY16+BA16+BC16)))) -> 3.918232 | AX18: =Z18*1.137 -> 1.6423333 | AY18: =IF(AY17<=BA16,AY17/BA16,IF(AY17<=BA16+BC16,1+(AY17-BA16)/BC16,IF(AY17<=BA16+BC16+BE16,2+(AY17-BA16-BC16)/BE16,AY17*3/(BA16+BC16+BE16)))) -> 5.8485804 | AZ18: 1.1571596 | BA18: 4.2861824 | BB18: 0.62494681 | BC18: 3.9053498 | BD18: 0.66503774 | BE18: 2.8391608 | BF18: =AH18*1.137 -> 0.45775325 | BG18: =IF(BG17<=BI16,BG17/BI16,IF(BG17<=BI16+BK16,1+(BG17-BI16)/BK16,IF(BG17<=BI16+BK16+BM16,2+(BG17-BI16-BK16)/BM16,BG17*3/(BI16+BK16+BM16)))) -> 3.1672548 | BH18: =AJ18*1.137 -> 0.3641219 | BI18: =IF(BI17<=BK16,BI17/BK16,IF(BI17<=BK16+BM16,1+(BI17-BK16)/BM16,IF(BI17<=BK16+BM16+BO16,2+(BI17-BK16-BM16)/BO16,BI17*3/(BK16+BM16+BO16)))) -> 2.7367367 | BJ18: =AL18*1.137 -> 1.9093204 | BK18: =IF(BK17<=BM16,BK17/BM16,IF(BK17<=BM16+BO16,1+(BK17-BM16)/BO16,IF(BK17<=BM16+BO16+BQ16,2+(BK17-BM16-BO16)/BQ16,BK17*3/(BM16+BO16+BQ16)))) -> 3.4460255 | BL18: =AN18*1.137 -> 1.7064551 | BM18: =IF(BM17<=BO16,BM17/BO16,IF(BM17<=BO16+BQ16,1+(BM17-BO16)/BQ16,IF(BM17<=BO16+BQ16+BS16,2+(BM17-BO16-BQ16)/BS16,BM17*3/(BO16+BQ16+BS16)))) -> 2.7293165 | BN18: =AP18*1.137 -> 1.3789536 | BO18: =IF(BO17<=BQ16,BO17/BQ16,IF(BO17<=BQ16+BS16,1+(BO17-BQ16)/BS16,IF(BO17<=BQ16+BS16+BU16,2+(BO17-BQ16-BS16)/BU16,BO17*3/(BQ16+BS16+BU16)))) -> 3.4491758 | BP18: =AR18*1.137 -> 1.9822458 | BQ18: =IF(BQ17<=BS16,BQ17/BS16,IF(BQ17<=BS16+BU16,1+(BQ17-BS16)/BU16,IF(BQ17<=BS16+BU16+BW16,2+(BQ17-BS16-BU16)/BW16,BQ17*3/(BS16+BU16+BW16)))) -> 2.5972359 | BR18: =AT18*1.137 -> 2.0265028 | BS18: =IF(BS17<=BU16,BS17/BU16,IF(BS17<=BU16+BW16,1+(BS17-BU16)/BW16,IF(BS17<=BU16+BW16+BY16,2+(BS17-BU16-BW16)/BY16,BS17*3/(BU16+BW16+BY16)))) -> 2.2495146 | BT18: =AV18*1.137 -> 2.0684304 | BU18: =IF(BU17<=BW16,BU17/BW16,IF(BU17<=BW16+BY16,1+(BU17-BW16)/BY16,IF(BU17<=BW16+BY16+CA16,2+(BU17-BW16-BY16)/CA16,BU17*3/(BW16+BY16+CA16)))) -> 1.9718447 | BV18: =IF(BV17<=BX16,BV17/BX16,IF(BV17<=BX16+BZ16,1+(BV17-BX16)/BZ16,IF(BV17<=BX16+BZ16+CB16,2+(BV17-BX16-BZ16)/CB16,BV17*3/(BX16+BZ16+CB16)))) -> 0.66773934 | BW18: =IF(BW17<=BY16,BW17/BY16,IF(BW17<=BY16+CA16,1+(BW17-BY16)/CA16,IF(BW17<=BY16+CA16+CC16,2+(BW17-BY16-CA16)/CC16,BW17*3/(BY16+CA16+CC16)))) -> 1.9214464 | BX18: =IF(BX17<=BZ16,BX17/BZ16,IF(BX17<=BZ16+CB16,1+(BX17-BZ16)/CB16,IF(BX17<=BZ16+CB16+CD16,2+(BX17-BZ16-CB16)/CD16,BX17*3/(BZ16+CB16+CD16)))) -> 0.65463867 | BY18: =IF(BY17<=CA16,BY17/CA16,IF(BY17<=CA16+CC16,1+(BY17-CA16)/CC16,IF(BY17<=CA16+CC16+CE16,2+(BY17-CA16-CC16)/CE16,BY17*3/(CA16+CC16+CE16)))) -> 3.1419504 | BZ18: =IF(BZ17<=CB16,BZ17/CB16,IF(BZ17<=CB16+CD16,1+(BZ17-CB16)/CD16,IF(BZ17<=CB16+CD16+CF16,2+(BZ17-CB16-CD16)/CF16,BZ17*3/(CB16+CD16+CF16)))) -> 1.1090226 | CA18: =IF(CA17<=CC16,CA17/CC16,IF(CA17<=CC16+CE16,1+(CA17-CC16)/CE16,IF(CA17<=CC16+CE16+CG16,2+(CA17-CC16-CE16)/CG16,CA17*3/(CC16+CE16+CG16)))) -> 3.1783035 | CB18: =IF(CB17<=CD16,CB17/CD16,IF(CB17<=CD16+CF16,1+(CB17-CD16)/CF16,IF(CB17<=CD16+CF16+CH16,2+(CB17-CD16-CF16)/CH16,CB17*3/(CD16+CF16+CH16)))) -> 1.1635688 | ... CG18: =IF(CG17<=CI16,CG17/CI16,IF(CG17<=CI16+CK16,1+(CG17-CI16)/CK16,IF(CG17<=CI16+CK16+CM16,2+(CG17-CI16-CK16)/CM16,CG17*3/(CI16+CK16+CM16)))) -> 3.18245 | CH18: =BJ18*1.137 -> 2.1708973 | CI18: =IF(CI17<=CK16,CI17/CK16,IF(CI17<=CK16+CM16,1+(CI17-CK16)/CM16,IF(CI17<=CK16+CM16+CO16,2+(CI17-CK16-CM16)/CO16,CI17*3/(CK16+CM16+CO16)))) -> 3.1538462 | CJ18: =BL18*1.137 -> 1.9402394 | CK18: =IF(CK17<=CM16,CK17/CM16,IF(CK17<=CM16+CO16,1+(CK17-CM16)/CO16,IF(CK17<=CM16+CO16+CQ16,2+(CK17-CM16-CO16)/CQ16,CK17*3/(CM16+CO16+CQ16)))) -> 2.9312407 | CL18: =BN18*1.137 -> 1.5678702 | CM18: =IF(CM17<=CO16,CM17/CO16,IF(CM17<=CO16+CQ16,1+(CM17-CO16)/CQ16,IF(CM17<=CO16+CQ16+CS16,2+(CM17-CO16-CQ16)/CS16,CM17*3/(CO16+CQ16+CS16)))) -> 2.6140036 | CN18: =BP18*1.137 -> 2.2538135 | CO18: =IF(CO17<=CQ16,CO17/CQ16,IF(CO17<=CQ16+CS16,1+(CO17-CQ16)/CS16,IF(CO17<=CQ16+CS16+CU16,2+(CO17-CQ16-CS16)/CU16,CO17*3/(CQ16+CS16+CU16)))) -> 3.790604 | CP18: =BR18*1.137 -> 2.3041336 | CQ18: =IF(CQ17<=CS16,CQ17/CS16,IF(CQ17<=CS16+CU16,1+(CQ17-CS16)/CU16,IF(CQ17<=CS16+CU16+CW16,2+(CQ17-CS16-CU16)/CW16,CQ17*3/(CS16+CU16+CW16)))) -> 2.8218905 | CR18: =BT18*1.137 -> 2.3518054 | CS18: =IF(CS17<=CU16,CS17/CU16,IF(CS17<=CU16+CW16,1+(CS17-CU16)/CW16,IF(CS17<=CU16+CW16+CY16,2+(CS17-CU16-CW16)/CY16,CS17*3/(CU16+CW16+CY16)))) -> 2.7320197 | CT18: =BV18*1.137 -> 0.75921963 | CU18: =IF(CU17<=CW16,CU17/CW16,IF(CU17<=CW16+CY16,1+(CU17-CW16)/CY16,IF(CU17<=CW16+CY16+DA16,2+(CU17-CW16-CY16)/DA16,CU17*3/(CW16+CY16+DA16)))) -> 2.6993988 | CV18: =BX18*1.137 -> 0.74432416 | CW18: =IF(CW17<=CY16,CW17/CY16,IF(CW17<=CY16+DA16,1+(CW17-CY16)/DA16,IF(CW17<=CY16+DA16+DC16,2+(CW17-CY16-DA16)/DC16,CW17*3/(CY16+DA16+DC16)))) -> 2.2130045 | CX18: =BZ18*1.137 -> 1.2609586 | CY18: =IF(CY17<=DA16,CY17/DA16,IF(CY17<=DA16+DC16,1+(CY17-DA16)/DC16,IF(CY17<=DA16+DC16+DE16,2+(CY17-DA16-DC16)/DE16,CY17*3/(DA16+DC16+DE16)))) -> 3.6668919 | CZ18: =CB18*1.137 -> 1.3229777 | DA18: =IF(DA17<=DC16,DA17/DC16,IF(DA17<=DC16+DE16,1+(DA17-DC16)/DE16,IF(DA17<=DC16+DE16+DG16,2+(DA17-DC16-DE16)/DG16,DA17*3/(DC16+DE16+DG16)))) -> 3.4814324 | DB18: =CD18*1.137 -> 0.93552416 | DC18: =IF(DC17<=DE16,DC17/DE16,IF(DC17<=DE16+DG16,1+(DC17-DE16)/DG16,IF(DC17<=DE16+DG16+DI16,2+(DC17-DE16-DG16)/DI16,DC17*3/(DE16+DG16+DI16)))) -> 2.3426295 | DD18: =CF18*1.137 -> 1.0285668 | DE18: =IF(DE17<=DG16,DE17/DG16,IF(DE17<=DG16+DI16,1+(DE17-DG16)/DI16,IF(DE17<=DG16+DI16+DK16,2+(DE17-DG16-DI16)/DK16,DE17*3/(DG16+DI16+DK16)))) -> 2.1736997 | DF18: =CF18*1.137 -> 1.0285668 | DG18: =IF(DG17<=DI16,DG17/DI16,IF(DG17<=DI16+DK16,1+(DG17-DI16)/DK16,IF(DG17<=DI16+DK16+DM16,2+(DG17-DI16-DK16)/DM16,DG17*3/(DI16+DK16+DM16)))) -> 1.2698724 | DH18: =CH18*1.137 -> 2.4683102 | DI18: =IF(DI17<=DK16,DI17/DK16,IF(DI17<=DK16+DM16,1+(DI17-DK16)/DM16,IF(DI17<=DK16+DM16+DO16,2+(DI17-DK16-DM16)/DO16,DI17*3/(DK16+DM16+DO16)))) -> 1.6842105 | DJ18: 1.5 | DK18: =IF(DK17<=DM16,DK17/DM16,IF(DK17<=DM16+DO16,1+(DK17-DM16)/DO16,IF(DK17<=DM16+DO16+DQ16,2+(DK17-DM16-DO16)/DQ16,DK17*3/(DM16+DO16+DQ16)))) -> 1.7481359 | DL18: 1.5 | DM18: =IF(DM17<=DO16,DM17/DO16,IF(DM17<=DO16+DQ16,1+(DM17-DO16)/DQ16,IF(DM17<=DO16+DQ16+DS16,2+(DM17-DO16-DQ16)/DS16,DM17*3/(DO16+DQ16+DS16)))) -> 2.3283358 | DN18: 1.5 | DO18: =IF(DO17<=DQ16,DO17/DQ16,IF(DO17<=DQ16+DS16,1+(DO17-DQ16)/DS16,IF(DO17<=DQ16+DS16+DU16,2+(DO17-DQ16-DS16)/DU16,DO17*3/(DQ16+DS16+DU16)))) -> 2.2372323 | DP18: 1.5 | DQ18: =IF(DQ17<=DS16,DQ17/DS16,IF(DQ17<=DS16+DU16,1+(DQ17-DS16)/DU16,IF(DQ17<=DS16+DU16+DW16,2+(DQ17-DS16-DU16)/DW16,DQ17*3/(DS16+DU16+DW16)))) -> 1.6337177 | DR18: 1.5 | DS18: =IF(DS17<=DU16,DS17/DU16,IF(DS17<=DU16+DW16,1+(DS17-DU16)/DW16,IF(DS17<=DU16+DW16+DY16,2+(DS17-DU16-DW16)/DY16,DS17*3/(DU16+DW16+DY16)))) -> 1.4923305 | DT18: 1.5 | DU18: =IF(DU17<=DW16,DU17/DW16,IF(DU17<=DW16+DY16,1+(DU17-DW16)/DY16,IF(DU17<=DW16+DY16+EA16,2+(DU17-DW16-DY16)/EA16,DU17*3/(DW16+DY16+EA16)))) -> 1.0325866 | DV18: 1.5 | DW18: =IF(DW17<=DY16,DW17/DY16,IF(DW17<=DY16+EA16,1+(DW17-DY16)/EA16,IF(DW17<=DY16+EA16+EC16,2+(DW17-DY16-EA16)/EC16,DW17*3/(DY16+EA16+EC16)))) -> 4.4153627 | DX18: 1.5 | DY18: =IF(DY17<=EA16,DY17/EA16,IF(DY17<=EA16+EC16,1+(DY17-EA16)/EC16,IF(DY17<=EA16+EC16+EE16,2+(DY17-EA16-EC16)/EE16,DY17*3/(EA16+EC16+EE16)))) -> 2.8570198 | DZ18: 1.5 | EA18: =IF(EA17<=EC16,EA17/EC16,IF(EA17<=EC16+EE16,1+(EA17-EC16)/EE16,IF(EA17<=EC16+EE16+EG16,2+(EA17-EC16-EE16)/EG16,EA17*3/(EC16+EE16+EG16)))) -> 5.1720747 | EB18: 1.5 | EC18: =IF(EC17<=EE16,EC17/EE16,IF(EC17<=EE16+EG16,1+(EC17-EE16)/EG16,IF(EC17<=EE16+EG16+EI16,2+(EC17-EE16-EG16)/EI16,EC17*3/(EE16+EG16+EI16)))) -> 7.0221932 | ED18: 1.5 | EE18: =IF(EE17<=EG16,EE17/EG16,IF(EE17<=EG16+EI16,1+(EE17-EG16)/EI16,IF(EE17<=EG16+EI16+EK16,2+(EE17-EG16-EI16)/EK16,EE17*3/(EG16+EI16+EK16)))) -> 6.1651132 | EF18: 1.5 | EG18: =IF(EG17<=EI16,EG17/EI16,IF(EG17<=EI16+EK16,1+(EG17-EI16)/EK16,IF(EG17<=EI16+EK16+EM16,2+(EG17-EI16-EK16)/EM16,EG17*3/(EI16+EK16+EM16)))) -> 3.5814536 | EH18: 1.5 | EI18: =IF(EI17<=EK16,EI17/EK16,IF(EI17<=EK16+EM16,1+(EI17-EK16)/EM16,IF(EI17<=EK16+EM16+EO16,2+(EI17-EK16-EM16)/EO16,EI17*3/(EK16+EM16+EO16)))) -> 3.182354 | EJ18: 2.5 | EK18: =IF(EK17<=EM16,EK17/EM16,IF(EK17<=EM16+EO16,1+(EK17-EM16)/EO16,IF(EK17<=EM16+EO16+EQ16,2+(EK17-EM16-EO16)/EQ16,EK17*3/(EM16+EO16+EQ16)))) -> 2.8609169 | EL18: 2.5 | EM18: =IF(EM17<=EO16,EM17/EO16,IF(EM17<=EO16+EQ16,1+(EM17-EO16)/EQ16,IF(EM17<=EO16+EQ16+ES16,2+(EM17-EO16-EQ16)/ES16,EM17*3/(EO16+EQ16+ES16)))) -> 3.6425073 | EN18: 2.5 | EO18: =IF(EO17<=EQ16,EO17/EQ16,IF(EO17<=EQ16+ES16,1+(EO17-EQ16)/ES16,IF(EO17<=EQ16+ES16+EU16,2+(EO17-EQ16-ES16)/EU16,EO17*3/(EQ16+ES16+EU16)))) -> 3.6973645 | EP18: 2.5 | EQ18: =IF(EQ17<=ES16,EQ17/ES16,IF(EQ17<=ES16+EU16,1+(EQ17-ES16)/EU16,IF(EQ17<=ES16+EU16+EW16,2+(EQ17-ES16-EU16)/EW16,EQ17*3/(ES16+EU16+EW16)))) -> 3.7165026 | ER18: 2.5 | ES18: =IF(ES17<=EU16,ES17/EU16,IF(ES17<=EU16+EW16,1+(ES17-EU16)/EW16,IF(ES17<=EU16+EW16+EY16,2+(ES17-EU16-EW16)/EY16,ES17*3/(EU16+EW16+EY16)))) -> #REF! | ET18: 2.5 | EU18: =IF(EU17<=EW16,EU17/EW16,IF(EU17<=EW16+EY16,1+(EU17-EW16)/EY16,IF(EU17<=EW16+EY16+FA16,2+(EU17-EW16-EY16)/FA16,EU17*3/(EW16+EY16+FA16)))) -> #REF! | EV18: 2.5 | EW18: =IF(EW17<=EY16,EW17/EY16,IF(EW17<=EY16+FA16,1+(EW17-EY16)/FA16,IF(EW17<=EY16+FA16+FC16,2+(EW17-EY16-FA16)/FC16,EW17*3/(EY16+FA16+FC16)))) -> #REF! | EX18: 2.5 | EY18: =IF(EY17<=FA16,EY17/FA16,IF(EY17<=FA16+FC16,1+(EY17-FA16)/FC16,IF(EY17<=FA16+FC16+FE16,2+(EY17-FA16-FC16)/FE16,EY17*3/(FA16+FC16+FE16)))) -> #REF! | EZ18: 2.5 | FA18: =IF(FA17<=FC16,FA17/FC16,IF(FA17<=FC16+FE16,1+(FA17-FC16)/FE16,IF(FA17<=FC16+FE16+FG16,2+(FA17-FC16-FE16)/FG16,FA17*3/(FC16+FE16+FG16)))) -> #REF! | FB18: 2.5 | FC18: =IF(FC17<=FE16,FC17/FE16,IF(FC17<=FE16+FG16,1+(FC17-FE16)/FG16,IF(FC17<=FE16+FG16+FI16,2+(FC17-FE16-FG16)/FI16,FC17*3/(FE16+FG16+FI16)))) -> #REF! | FD18: 2 | FE18: =IF(FE17<=FG16,FE17/FG16,IF(FE17<=FG16+FI16,1+(FE17-FG16)/FI16,IF(FE17<=FG16+FI16+FK16,2+(FE17-FG16-FI16)/FK16,FE17*3/(FG16+FI16+FK16)))) -> 2.6270396 | FF18: 2 | FG18: =IF(FG17<=FI16,FG17/FI16,IF(FG17<=FI16+FK16,1+(FG17-FI16)/FK16,IF(FG17<=FI16+FK16+FM16,2+(FG17-FI16-FK16)/FM16,FG17*3/(FI16+FK16+FM16)))) -> 2.9049296 | FH18: 2 | FI18: =IF(FI17<=FK16,FI17/FK16,IF(FI17<=FK16+FM16,1+(FI17-FK16)/FM16,IF(FI17<=FK16+FM16+FO16,2+(FI17-FK16-FM16)/FO16,FI17*3/(FK16+FM16+FO16)))) -> 2.7498995 | FJ18: 2 | FK18: =IF(FK17<=FM16,FK17/FM16,IF(FK17<=FM16+FO16,1+(FK17-FM16)/FO16,IF(FK17<=FM16+FO16+FQ16,2+(FK17-FM16-FO16)/FQ16,FK17*3/(FM16+FO16+FQ16)))) -> 2.3516883 | FL18: 2 | FM18: =IF(FM17<=FO16,FM17/FO16,IF(FM17<=FO16+FQ16,1+(FM17-FO16)/FQ16,IF(FM17<=FO16+FQ16+FS16,2+(FM17-FO16-FQ16)/FS16,FM17*3/(FO16+FQ16+FS16)))) -> 2.2143131 | FN18: 2 | FO18: =IF(FO17<=FQ16,FO17/FQ16,IF(FO17<=FQ16+FS16,1+(FO17-FQ16)/FS16,IF(FO17<=FQ16+FS16+FU16,2+(FO17-FQ16-FS16)/FU16,FO17*3/(FQ16+FS16+FU16)))) -> 1.9211634 | FP18: 2 | FQ18: =IF(FQ17<=FS16,FQ17/FS16,IF(FQ17<=FS16+FU16,1+(FQ17-FS16)/FU16,IF(FQ17<=FS16+FU16+FW16,2+(FQ17-FS16-FU16)/FW16,FQ17*3/(FS16+FU16+FW16)))) -> 1.9619841 | FR18: 2 | FS18: =IF(FS17<=FU16,FS17/FU16,IF(FS17<=FU16+FW16,1+(FS17-FU16)/FW16,IF(FS17<=FU16+FW16+FY16,2+(FS17-FU16-FW16)/FY16,FS17*3/(FU16+FW16+FY16)))) -> 1.9138091 | FT18: =IF(FT17<=FV16,FT17/FV16,IF(FT17<=FV16+FX16,1+(FT17-FV16)/FX16,IF(FT17<=FV16+FX16+FZ16,2+(FT17-FV16-FX16)/FZ16,FT17*3/(FV16+FX16+FZ16)))) -> 2.5972503 | FU18: =IF(FU17<=FW16,FU17/FW16,IF(FU17<=FW16+FY16,1+(FU17-FW16)/FY16,IF(FU17<=FW16+FY16+GA16,2+(FU17-FW16-FY16)/GA16,FU17*3/(FW16+FY16+GA16)))) -> 2.256917 | FV18: =IF(FV17<=FX16,FV17/FX16,IF(FV17<=FX16+FZ16,1+(FV17-FX16)/FZ16,IF(FV17<=FX16+FZ16+#REF!,2+(FV17-FX16-FZ16)/#REF!,FV17*3/(FX16+FZ16+#REF!)))) -> #REF! | FW18: =IF(FW17<=FY16,FW17/FY16,IF(FW17<=FY16+GA16,1+(FW17-FY16)/GA16,IF(FW17<=FY16+GA16+GB16,2+(FW17-FY16-GA16)/GB16,FW17*3/(FY16+GA16+GB16)))) -> 1.7971014 | FX18: =IF(FX17<=FZ16,FX17/FZ16,IF(FX17<=FZ16+#REF!,1+(FX17-FZ16)/#REF!,IF(FX17<=FZ16+#REF!+#REF!,2+(FX17-FZ16-#REF!)/#REF!,FX17*3/(FZ16+#REF!+#REF!)))) -> #REF! | FY18: =IF(FY17<=GA16,FY17/GA16,IF(FY17<=GA16+GB16,1+(FY17-GA16)/GB16,IF(FY17<=GA16+GB16+GC16,2+(FY17-GA16-GB16)/GC16,FY17*3/(GA16+GB16+GC16)))) -> 1.9432761 | FZ18: =IF(FZ17<=#REF!,FZ17/#REF!,IF(FZ17<=#REF!+#REF!,1+(FZ17-#REF!)/#REF!,IF(FZ17<=#REF!+#REF!+#REF!,2+(FZ17-#REF!-#REF!)/#REF!,FZ17*3/(#REF!+#REF!+#REF!)))) -> #REF! | GA18: =IF(GA17<=GB16,GA17/GB16,IF(GA17<=GB16+GC16,1+(GA17-GB16)/GC16,IF(GA17<=GB16+GC16+GD16,2+(GA17-GB16-GC16)/GD16,GA17*3/(GB16+GC16+GD16)))) -> 2.5818713 | GB18: =IF(GB17<=GC16,GB17/GC16,IF(GB17<=GC16+GD16,1+(GB17-GC16)/GD16,IF(GB17<=GC16+GD16+GE16,2+(GB17-GC16-GD16)/GE16,GB17*3/(GC16+GD16+GE16)))) -> 2.2934062 | GC18: =IF(GC17<=GD16,GC17/GD16,IF(GC17<=GD16+GE16,1+(GC17-GD16)/GE16,IF(GC17<=GD16+GE16+GF16,2+(GC17-GD16-GE16)/GF16,GC17*3/(GD16+GE16+GF16)))) -> 2.6409647 | GD18: =IF(GD17<=GE16,GD17/GE16,IF(GD17<=GE16+GF16,1+(GD17-GE16)/GF16,IF(GD17<=GE16+GF16+GG16,2+(GD17-GE16-GF16)/GG16,GD17*3/(GE16+GF16+GG16)))) -> 2.3299923 | GE18: =IF(GE17<=GF16,GE17/GF16,IF(GE17<=GF16+GG16,1+(GE17-GF16)/GG16,IF(GE17<=GF16+GG16+GH16,2+(GE17-GF16-GG16)/GH16,GE17*3/(GF16+GG16+GH16)))) -> 2.0030503 | GF18: =IF(GF17<=GG16,GF17/GG16,IF(GF17<=GG16+GH16,1+(GF17-GG16)/GH16,IF(GF17<=GG16+GH16+GI16,2+(GF17-GG16-GH16)/GI16,GF17*3/(GG16+GH16+GI16)))) -> 2.0842346 | GG18: =IF(GG17<=GH16,GG17/GH16,IF(GG17<=GH16+GI16,1+(GG17-GH16)/GI16,IF(GG17<=GH16+GI16+GJ16,2+(GG17-GH16-GI16)/GJ16,GG17*3/(GH16+GI16+GJ16)))) -> 1.6551581 | GH18: =IF(GH17<=GI16,GH17/GI16,IF(GH17<=GI16+GJ16,1+(GH17-GI16)/GJ16,IF(GH17<=GI16+GJ16+GK16,2+(GH17-GI16-GJ16)/GK16,GH17*3/(GI16+GJ16+GK16)))) -> 2.34 | ... JO18: =IF(JO17<=JP16,JO17/JP16,IF(JO17<=JP16+JQ16,1+(JO17-JP16)/JQ16,IF(JO17<=JP16+JQ16+JR16,2+(JO17-JP16-JQ16)/JR16,JO17*3/(JP16+JQ16+JR16)))) -> #DIV/0!
